Workbook
Name BIP_date: 'Paramètres'!$C$6
Name BIP_facteur: 'Paramètres'!$C$7
Name BIP_inclus: 'Paramètres'!$C$8
Name INFR_debut: 'Paramètres'!$C$9
Name Seuil_aberrant: 'Paramètres'!$C$10
Name Fenetre: 'Paramètres'!$C$11
Name Wc_C1: 'Paramètres'!$D$37
Name Wc_C2: 'Paramètres'!$E$37
Name Wc_C3: 'Paramètres'!$F$37
Name Wc_C4: 'Paramètres'!$G$37

Sheet Synthèse
B2: COURS DES PROXIES COTÉS - OPENSTONE INFRAWORLD
B3: Source : Yahoo Finance, extraction du 06/10/2026 (séance américaine en cours). Cours en devise de cotation, LSE converti de pence en livres. Colonnes de cours et performances à un an : valeurs extraites. Colonnes de statistiques mensuelles : formules sur l'onglet Rendements (devise locale, dividendes réinvestis, paramètres de l'onglet Paramètres).
B5: Ticker | C5: Yahoo | D5: Nom | E5: Stratégie / usage proxy | F5: Composite | G5: Devise | H5: Date | I5: Dernier cours | J5: Veille | K5: Var. jour | L5: Plus haut 1 an | M5: Plus bas 1 an | N5: Perf. 1 mois | O5: Perf. 3 mois | P5: Perf. 1 an (prix) | Q5: Perf. 1 an (dividendes réinvestis) | R5: Vol. quotidienne 1 an | S5: Vol. mensuelle annualisée | T5: Rendement annualisé | U5: Pire fenêtre glissante | V5: Perte maximale | W5: Mois disponibles | X5: Inclus
B6: NasdaqGM:IGF | C6: IGF | D6: iShares Global Infrastructure ETF | E6: Infrastructure cotée monde | F6: C1 | G6: USD | H6: 46301 | I6: 62.759998 | J6: 62.009998 | K6: 0.012094824 | L6: 69.370003 | M6: 60.720001 | N6: -0.035648486 | O6: -0.065654309 | P6: 0.018170002 | Q6: 0.049282315 | R6: 0.1089084 | S6: {=IF(COUNT(Rendements!C$7:C$184)<24,"",STDEVP(IF(ISNUMBER(Rendements!C$7:C$184),LN(1+Rendements!C$7:C$184)))*SQRT(12))} | T6: {=IF(COUNT(Rendements!C$7:C$184)<24,"",EXP(SUMPRODUCT(ISNUMBER(Rendements!C$7:C$184)*N(+IF(ISNUMBER(Rendements!C$7:C$184),LN(1+Rendements!C$7:C$184),0)))*12/COUNT(Rendements!C$7:C$184))-1)} | U6: =IF(COUNT('Aide calcul'!C$6:C$184)=0,"",MIN('Aide calcul'!C$6:C$184)) | V6: =IF(COUNT('Aide calcul'!V$6:V$184)=0,"",MIN('Aide calcul'!V$6:V$184)) | W6: =COUNT(Rendements!C$7:C$184) | X6: =SUM(Paramètres!D15:G15)
B7: LSE:INFR | C7: INFR.L | D7: iShares Global Infrastructure UCITS ETF | E7: Infrastructure cotée monde (UCITS) | F7: C1 | G7: GBP | H7: 46301 | I7: 27.705 | J7: 27.525 | K7: 0.0065395095 | L7: 30.37 | M7: 26.055 | N7: -0.026528461 | O7: -0.068582955 | P7: 0.039197299 | Q7: 0.039411941 | R7: 0.11812197 | S7: {=IF(COUNT(Rendements!D$7:D$184)<24,"",STDEVP(IF(ISNUMBER(Rendements!D$7:D$184),LN(1+Rendements!D$7:D$184)))*SQRT(12))} | T7: {=IF(COUNT(Rendements!D$7:D$184)<24,"",EXP(SUMPRODUCT(ISNUMBER(Rendements!D$7:D$184)*N(+IF(ISNUMBER(Rendements!D$7:D$184),LN(1+Rendements!D$7:D$184),0)))*12/COUNT(Rendements!D$7:D$184))-1)} | U7: =IF(COUNT('Aide calcul'!D$6:D$184)=0,"",MIN('Aide calcul'!D$6:D$184)) | V7: =IF(COUNT('Aide calcul'!W$6:W$184)=0,"",MIN('Aide calcul'!W$6:W$184)) | W7: =COUNT(Rendements!D$7:D$184) | X7: =SUM(Paramètres!D16:G16)
B8: LSE:3IN | C8: 3IN.L | D8: 3i Infrastructure plc | E8: Infrastructure core-plus, trust coté | F8: C1 | G8: GBP | H8: 46301 | I8: 3.865 | J8: 3.87 | K8: -0.0012919897 | L8: 3.96 | M8: 3.26 | N8: -0.010243278 | O8: 0.017105263 | P8: 0.075104312 | Q8: 0.075498993 | R8: 0.15117187 | S8: {=IF(COUNT(Rendements!E$7:E$184)<24,"",STDEVP(IF(ISNUMBER(Rendements!E$7:E$184),LN(1+Rendements!E$7:E$184)))*SQRT(12))} | T8: {=IF(COUNT(Rendements!E$7:E$184)<24,"",EXP(SUMPRODUCT(ISNUMBER(Rendements!E$7:E$184)*N(+IF(ISNUMBER(Rendements!E$7:E$184),LN(1+Rendements!E$7:E$184),0)))*12/COUNT(Rendements!E$7:E$184))-1)} | U8: =IF(COUNT('Aide calcul'!E$6:E$184)=0,"",MIN('Aide calcul'!E$6:E$184)) | V8: =IF(COUNT('Aide calcul'!X$6:X$184)=0,"",MIN('Aide calcul'!X$6:X$184)) | W8: =COUNT(Rendements!E$7:E$184) | X8: =SUM(Paramètres!D17:G17)
B9: LSE:HICL | C9: HICL.L | D9: HICL Infrastructure plc | E9: Infrastructure core (PPP, régulé), trust coté | F9: C1 | G9: GBP | H9: 46301 | I9: 1.318 | J9: 1.3139999 | K9: 0.0030442098 | L9: 1.4039999 | M9: 1.09 | N9: -0.025147884 | O9: -0.023703681 | P9: 0.085667227 | Q9: 0.086390867 | R9: 0.16789832 | S9: {=IF(COUNT(Rendements!F$7:F$184)<24,"",STDEVP(IF(ISNUMBER(Rendements!F$7:F$184),LN(1+Rendements!F$7:F$184)))*SQRT(12))} | T9: {=IF(COUNT(Rendements!F$7:F$184)<24,"",EXP(SUMPRODUCT(ISNUMBER(Rendements!F$7:F$184)*N(+IF(ISNUMBER(Rendements!F$7:F$184),LN(1+Rendements!F$7:F$184),0)))*12/COUNT(Rendements!F$7:F$184))-1)} | U9: =IF(COUNT('Aide calcul'!F$6:F$184)=0,"",MIN('Aide calcul'!F$6:F$184)) | V9: =IF(COUNT('Aide calcul'!Y$6:Y$184)=0,"",MIN('Aide calcul'!Y$6:Y$184)) | W9: =COUNT(Rendements!F$7:F$184) | X9: =SUM(Paramètres!D18:G18)
B10: LSE:INPP | C10: INPP.L | D10: International Public Partnerships Ltd | E10: Infrastructure core (PPP, régulé), trust coté | F10: C1 | G10: GBP | H10: 46301 | I10: 1.3660001 | J10: 1.348 | K10: 0.013353138 | L10: 1.4460001 | M10: 1.172 | N10: -0.018678096 | O10: -0.025677539 | P10: 0.10876631 | Q10: 0.10948863 | R10: 0.1412787 | S10: {=IF(COUNT(Rendements!G$7:G$184)<24,"",STDEVP(IF(ISNUMBER(Rendements!G$7:G$184),LN(1+Rendements!G$7:G$184)))*SQRT(12))} | T10: {=IF(COUNT(Rendements!G$7:G$184)<24,"",EXP(SUMPRODUCT(ISNUMBER(Rendements!G$7:G$184)*N(+IF(ISNUMBER(Rendements!G$7:G$184),LN(1+Rendements!G$7:G$184),0)))*12/COUNT(Rendements!G$7:G$184))-1)} | U10: =IF(COUNT('Aide calcul'!G$6:G$184)=0,"",MIN('Aide calcul'!G$6:G$184)) | V10: =IF(COUNT('Aide calcul'!Z$6:Z$184)=0,"",MIN('Aide calcul'!Z$6:Z$184)) | W10: =COUNT(Rendements!G$7:G$184) | X10: =SUM(Paramètres!D19:G19)
B11: LSE:SEQI | C11: SEQI.L | D11: Sequoia Economic Infrastructure Income Fund | E11: Dette d'infrastructure, trust coté | F11: C2 | G11: GBP | H11: 46301 | I11: 0.83599998 | J11: 0.83099998 | K11: 0.0060168473 | L11: 0.875 | M11: 0.75800003 | N11: -0.014150997 | O11: 0.0023980449 | P11: 0.085714266 | Q11: 0.086628677 | R11: 0.13860033 | S11: {=IF(COUNT(Rendements!H$7:H$184)<24,"",STDEVP(IF(ISNUMBER(Rendements!H$7:H$184),LN(1+Rendements!H$7:H$184)))*SQRT(12))} | T11: {=IF(COUNT(Rendements!H$7:H$184)<24,"",EXP(SUMPRODUCT(ISNUMBER(Rendements!H$7:H$184)*N(+IF(ISNUMBER(Rendements!H$7:H$184),LN(1+Rendements!H$7:H$184),0)))*12/COUNT(Rendements!H$7:H$184))-1)} | U11: =IF(COUNT('Aide calcul'!H$6:H$184)=0,"",MIN('Aide calcul'!H$6:H$184)) | V11: =IF(COUNT('Aide calcul'!AA$6:AA$184)=0,"",MIN('Aide calcul'!AA$6:AA$184)) | W11: =COUNT(Rendements!H$7:H$184) | X11: =SUM(Paramètres!D20:G20)
B12: LSE:GCP | C12: GCP.L | D12: GCP Infrastructure Investments Ltd | E12: Dette d'infrastructure (UK), trust coté | F12: C2 | G12: GBP | H12: 46301 | I12: 0.81900002 | J12: 0.81599998 | K12: 0.0036765081 | L12: 0.85599998 | M12: 0.7 | N12: -0.023837902 | O12: -0.0060679611 | P12: 0.11732603 | Q12: 0.11834444 | R12: 0.14519648 | S12: {=IF(COUNT(Rendements!I$7:I$184)<24,"",STDEVP(IF(ISNUMBER(Rendements!I$7:I$184),LN(1+Rendements!I$7:I$184)))*SQRT(12))} | T12: {=IF(COUNT(Rendements!I$7:I$184)<24,"",EXP(SUMPRODUCT(ISNUMBER(Rendements!I$7:I$184)*N(+IF(ISNUMBER(Rendements!I$7:I$184),LN(1+Rendements!I$7:I$184),0)))*12/COUNT(Rendements!I$7:I$184))-1)} | U12: =IF(COUNT('Aide calcul'!I$6:I$184)=0,"",MIN('Aide calcul'!I$6:I$184)) | V12: =IF(COUNT('Aide calcul'!AB$6:AB$184)=0,"",MIN('Aide calcul'!AB$6:AB$184)) | W12: =COUNT(Rendements!I$7:I$184) | X12: =SUM(Paramètres!D21:G21)
B13: NYSE:BIP | C13: BIP | D13: Brookfield Infrastructure Partners L.P. | E13: Infrastructure value add, gérant coté | F13: C1 | G13: USD | H13: 46301 | I13: 37.419998 | J13: 36.169998 | K13: 0.034559029 | L13: 42.619999 | M13: 33.41 | N13: 0.0078103176 | O13: 0.015192554 | P13: 0.089374085 | Q13: 0.12817675 | R13: 0.21674548 | S13: {=IF(COUNT(Rendements!J$7:J$184)<24,"",STDEVP(IF(ISNUMBER(Rendements!J$7:J$184),LN(1+Rendements!J$7:J$184)))*SQRT(12))} | T13: {=IF(COUNT(Rendements!J$7:J$184)<24,"",EXP(SUMPRODUCT(ISNUMBER(Rendements!J$7:J$184)*N(+IF(ISNUMBER(Rendements!J$7:J$184),LN(1+Rendements!J$7:J$184),0)))*12/COUNT(Rendements!J$7:J$184))-1)} | U13: =IF(COUNT('Aide calcul'!J$6:J$184)=0,"",MIN('Aide calcul'!J$6:J$184)) | V13: =IF(COUNT('Aide calcul'!AC$6:AC$184)=0,"",MIN('Aide calcul'!AC$6:AC$184)) | W13: =COUNT(Rendements!J$7:J$184) | X13: =SUM(Paramètres!D22:G22)
B14: KOSE:A088980 | C14: 088980.KS | D14: Macquarie Korea Infrastructure Fund | E14: Infrastructure core Corée, fonds Macquarie coté | F14: C1 | G14: KRW | H14: 46301 | I14: 9730 | J14: 9790 | K14: -0.0061287028 | L14: 11830 | M14: 9430 | N14: -0.019153226 | O14: -0.03567889 | P14: -0.14723926 | Q14: -0.087900709 | R14: 0.12930414 | S14: {=IF(COUNT(Rendements!K$7:K$184)<24,"",STDEVP(IF(ISNUMBER(Rendements!K$7:K$184),LN(1+Rendements!K$7:K$184)))*SQRT(12))} | T14: {=IF(COUNT(Rendements!K$7:K$184)<24,"",EXP(SUMPRODUCT(ISNUMBER(Rendements!K$7:K$184)*N(+IF(ISNUMBER(Rendements!K$7:K$184),LN(1+Rendements!K$7:K$184),0)))*12/COUNT(Rendements!K$7:K$184))-1)} | U14: =IF(COUNT('Aide calcul'!K$6:K$184)=0,"",MIN('Aide calcul'!K$6:K$184)) | V14: =IF(COUNT('Aide calcul'!AD$6:AD$184)=0,"",MIN('Aide calcul'!AD$6:AD$184)) | W14: =COUNT(Rendements!K$7:K$184) | X14: =SUM(Paramètres!D23:G23)
B15: ARCA:BKLN | C15: BKLN | D15: Invesco Senior Loan ETF | E15: Prêts seniors à taux variable (leveraged loans) | F15: C4 | G15: USD | H15: 46301 | I15: 20.504999 | J15: 20.49 | K15: 0.00073203464 | L15: 21.059999 | M15: 20.209999 | N15: -0.0050946844 | O15: 0.0041625408 | P15: -0.020773704 | Q15: 0.04345876 | R15: 0.028393948 | S15: {=IF(COUNT(Rendements!L$7:L$184)<24,"",STDEVP(IF(ISNUMBER(Rendements!L$7:L$184),LN(1+Rendements!L$7:L$184)))*SQRT(12))} | T15: {=IF(COUNT(Rendements!L$7:L$184)<24,"",EXP(SUMPRODUCT(ISNUMBER(Rendements!L$7:L$184)*N(+IF(ISNUMBER(Rendements!L$7:L$184),LN(1+Rendements!L$7:L$184),0)))*12/COUNT(Rendements!L$7:L$184))-1)} | U15: =IF(COUNT('Aide calcul'!L$6:L$184)=0,"",MIN('Aide calcul'!L$6:L$184)) | V15: =IF(COUNT('Aide calcul'!AE$6:AE$184)=0,"",MIN('Aide calcul'!AE$6:AE$184)) | W15: =COUNT(Rendements!L$7:L$184) | X15: =SUM(Paramètres!D24:G24)
B16: ARCA:HYG | C16: HYG | D16: iShares iBoxx $ High Yield Corporate Bond ETF | E16: Haut rendement USD | F16: C4 | G16: USD | H16: 46301 | I16: 77.254997 | J16: 76.980003 | K16: 0.003572277 | L16: 81.279999 | M16: 76.900002 | N16: -0.024065264 | O16: -0.031406781 | P16: -0.044583271 | Q16: 0.013302668 | R16: 0.039150509 | S16: {=IF(COUNT(Rendements!M$7:M$184)<24,"",STDEVP(IF(ISNUMBER(Rendements!M$7:M$184),LN(1+Rendements!M$7:M$184)))*SQRT(12))} | T16: {=IF(COUNT(Rendements!M$7:M$184)<24,"",EXP(SUMPRODUCT(ISNUMBER(Rendements!M$7:M$184)*N(+IF(ISNUMBER(Rendements!M$7:M$184),LN(1+Rendements!M$7:M$184),0)))*12/COUNT(Rendements!M$7:M$184))-1)} | U16: =IF(COUNT('Aide calcul'!M$6:M$184)=0,"",MIN('Aide calcul'!M$6:M$184)) | V16: =IF(COUNT('Aide calcul'!AF$6:AF$184)=0,"",MIN('Aide calcul'!AF$6:AF$184)) | W16: =COUNT(Rendements!M$7:M$184) | X16: =SUM(Paramètres!D25:G25)
B17: LSE:IHYG | C17: IHYG.L | D17: iShares € High Yield Corp Bond UCITS ETF | E17: Haut rendement EUR | F17: C4 | G17: EUR | H17: 46301 | I17: 88.800003 | J17: 88.269997 | K17: 0.0060043778 | L17: 93.760002 | M17: 88.150002 | N17: -0.024443817 | O17: -0.026635977 | P17: -0.040311205 | Q17: 0.010680436 | R17: 0.038503106 | S17: {=IF(COUNT(Rendements!N$7:N$184)<24,"",STDEVP(IF(ISNUMBER(Rendements!N$7:N$184),LN(1+Rendements!N$7:N$184)))*SQRT(12))} | T17: {=IF(COUNT(Rendements!N$7:N$184)<24,"",EXP(SUMPRODUCT(ISNUMBER(Rendements!N$7:N$184)*N(+IF(ISNUMBER(Rendements!N$7:N$184),LN(1+Rendements!N$7:N$184),0)))*12/COUNT(Rendements!N$7:N$184))-1)} | U17: =IF(COUNT('Aide calcul'!N$6:N$184)=0,"",MIN('Aide calcul'!N$6:N$184)) | V17: =IF(COUNT('Aide calcul'!AG$6:AG$184)=0,"",MIN('Aide calcul'!AG$6:AG$184)) | W17: =COUNT(Rendements!N$7:N$184) | X17: =SUM(Paramètres!D26:G26)
B18: NasdaqGS:ARCC | C18: ARCC | D18: Ares Capital Corporation | E18: Direct lending, BDC cotée (Ares) | F18: C3 | G18: USD | H18: 46301 | I18: 18.625 | J18: 18.82 | K18: -0.010361302 | L18: 21.030001 | M18: 17.450001 | N18: -0.070608825 | O18: 0.0083920245 | P18: -0.074304214 | Q18: 0.023044115 | R18: 0.1916091 | S18: {=IF(COUNT(Rendements!O$7:O$184)<24,"",STDEVP(IF(ISNUMBER(Rendements!O$7:O$184),LN(1+Rendements!O$7:O$184)))*SQRT(12))} | T18: {=IF(COUNT(Rendements!O$7:O$184)<24,"",EXP(SUMPRODUCT(ISNUMBER(Rendements!O$7:O$184)*N(+IF(ISNUMBER(Rendements!O$7:O$184),LN(1+Rendements!O$7:O$184),0)))*12/COUNT(Rendements!O$7:O$184))-1)} | U18: =IF(COUNT('Aide calcul'!O$6:O$184)=0,"",MIN('Aide calcul'!O$6:O$184)) | V18: =IF(COUNT('Aide calcul'!AH$6:AH$184)=0,"",MIN('Aide calcul'!AH$6:AH$184)) | W18: =COUNT(Rendements!O$7:O$184) | X18: =SUM(Paramètres!D27:G27)
B19: ARCA:BIZD | C19: BIZD | D19: VanEck BDC Income ETF | E19: Direct lending, panier de BDC | F19: C3 | G19: USD | H19: 46301 | I19: 12.1333 | J19: 12.25 | K19: -0.0095265447 | L19: 15.05 | M19: 12.11 | N19: -0.089774951 | O19: -0.019135009 | P19: -0.15270251 | Q19: -0.044666166 | R19: 0.19457148 | S19: {=IF(COUNT(Rendements!P$7:P$184)<24,"",STDEVP(IF(ISNUMBER(Rendements!P$7:P$184),LN(1+Rendements!P$7:P$184)))*SQRT(12))} | T19: {=IF(COUNT(Rendements!P$7:P$184)<24,"",EXP(SUMPRODUCT(ISNUMBER(Rendements!P$7:P$184)*N(+IF(ISNUMBER(Rendements!P$7:P$184),LN(1+Rendements!P$7:P$184),0)))*12/COUNT(Rendements!P$7:P$184))-1)} | U19: =IF(COUNT('Aide calcul'!P$6:P$184)=0,"",MIN('Aide calcul'!P$6:P$184)) | V19: =IF(COUNT('Aide calcul'!AI$6:AI$184)=0,"",MIN('Aide calcul'!AI$6:AI$184)) | W19: =COUNT(Rendements!P$7:P$184) | X19: =SUM(Paramètres!D28:G28)
B21: COMPOSITES COTÉS équipondérés, devise locale, dividendes réinvestis ; contrôle coté du portefeuille pondéré par l'allocation cible
B22: Composite | C22: Titres inclus | D22: Poids dans le contrôle coté | E22: Vol. mensuelle annualisée | F22: Rendement annualisé | G22: Pire fenêtre glissante | H22: Perte maximale | I22: Mois | J22: Perf. 12 derniers mois | K22: Référence DIC
B23: Infrastructure cotée, capital | C23: IGF, INFR, 3IN, HICL, INPP, A088980 ; BIP exclu | D23: =Wc_C1 | E23: {=IF(COUNT(Composites!C$7:C$184)<24,"",STDEVP(IF(ISNUMBER(Composites!C$7:C$184),LN(1+Composites!C$7:C$184)))*SQRT(12))} | F23: {=IF(COUNT(Composites!C$7:C$184)<24,"",EXP(SUMPRODUCT(ISNUMBER(Composites!C$7:C$184)*N(+IF(ISNUMBER(Composites!C$7:C$184),LN(1+Composites!C$7:C$184),0)))*12/COUNT(Composites!C$7:C$184))-1)} | G23: =IF(COUNT('Aide calcul'!Q$6:Q$184)=0,"",MIN('Aide calcul'!Q$6:Q$184)) | H23: =IF(COUNT('Aide calcul'!AJ$6:AJ$184)=0,"",MIN('Aide calcul'!AJ$6:AJ$184)) | I23: =COUNT(Composites!C$7:C$184) | J23: {=IF(COUNT(Composites!C173:C184)<12,"",PRODUCT(1+Composites!C173:C184)-1)} | K23: Preqin Infrastructure désmoothé : vol. 3,34 % ; value add 4,27 %
B24: Dette d'infrastructure cotée | C24: SEQI, GCP | D24: =Wc_C2 | E24: {=IF(COUNT(Composites!D$7:D$184)<24,"",STDEVP(IF(ISNUMBER(Composites!D$7:D$184),LN(1+Composites!D$7:D$184)))*SQRT(12))} | F24: {=IF(COUNT(Composites!D$7:D$184)<24,"",EXP(SUMPRODUCT(ISNUMBER(Composites!D$7:D$184)*N(+IF(ISNUMBER(Composites!D$7:D$184),LN(1+Composites!D$7:D$184),0)))*12/COUNT(Composites!D$7:D$184))-1)} | G24: =IF(COUNT('Aide calcul'!R$6:R$184)=0,"",MIN('Aide calcul'!R$6:R$184)) | H24: =IF(COUNT('Aide calcul'!AK$6:AK$184)=0,"",MIN('Aide calcul'!AK$6:AK$184)) | I24: =COUNT(Composites!D$7:D$184) | J24: {=IF(COUNT(Composites!D173:D184)<12,"",PRODUCT(1+Composites!D173:D184)-1)} | K24: Pas d'indice Preqin dédié ; dette d'infra traitée en direct lending (6,09 %)
B25: Direct lending coté | C25: ARCC, BIZD | D25: =Wc_C3 | E25: {=IF(COUNT(Composites!E$7:E$184)<24,"",STDEVP(IF(ISNUMBER(Composites!E$7:E$184),LN(1+Composites!E$7:E$184)))*SQRT(12))} | F25: {=IF(COUNT(Composites!E$7:E$184)<24,"",EXP(SUMPRODUCT(ISNUMBER(Composites!E$7:E$184)*N(+IF(ISNUMBER(Composites!E$7:E$184),LN(1+Composites!E$7:E$184),0)))*12/COUNT(Composites!E$7:E$184))-1)} | G25: =IF(COUNT('Aide calcul'!S$6:S$184)=0,"",MIN('Aide calcul'!S$6:S$184)) | H25: =IF(COUNT('Aide calcul'!AL$6:AL$184)=0,"",MIN('Aide calcul'!AL$6:AL$184)) | I25: =COUNT(Composites!E$7:E$184) | J25: {=IF(COUNT(Composites!E173:E184)<12,"",PRODUCT(1+Composites!E173:E184)-1)} | K25: Preqin Private Debt Direct Lending désmoothé : vol. 6,09 %
B26: Poche liquide : haut rendement et prêts seniors | C26: BKLN, HYG, IHYG | D26: =Wc_C4 | E26: {=IF(COUNT(Composites!F$7:F$184)<24,"",STDEVP(IF(ISNUMBER(Composites!F$7:F$184),LN(1+Composites!F$7:F$184)))*SQRT(12))} | F26: {=IF(COUNT(Composites!F$7:F$184)<24,"",EXP(SUMPRODUCT(ISNUMBER(Composites!F$7:F$184)*N(+IF(ISNUMBER(Composites!F$7:F$184),LN(1+Composites!F$7:F$184),0)))*12/COUNT(Composites!F$7:F$184))-1)} | G26: =IF(COUNT('Aide calcul'!T$6:T$184)=0,"",MIN('Aide calcul'!T$6:T$184)) | H26: =IF(COUNT('Aide calcul'!AM$6:AM$184)=0,"",MIN('Aide calcul'!AM$6:AM$184)) | I26: =COUNT(Composites!F$7:F$184) | J26: {=IF(COUNT(Composites!F173:F184)<12,"",PRODUCT(1+Composites!F173:F184)-1)} | K26: Morningstar LSTA : vol. 5,68 % (coté)
B27: Portefeuille (contrôle coté) | C27: Pondération de l'onglet Paramètres | D27: =Wc_C1+Wc_C2+Wc_C3+Wc_C4 | E27: {=IF(COUNT(Composites!G$7:G$184)<24,"",STDEVP(IF(ISNUMBER(Composites!G$7:G$184),LN(1+Composites!G$7:G$184)))*SQRT(12))} | F27: {=IF(COUNT(Composites!G$7:G$184)<24,"",EXP(SUMPRODUCT(ISNUMBER(Composites!G$7:G$184)*N(+IF(ISNUMBER(Composites!G$7:G$184),LN(1+Composites!G$7:G$184),0)))*12/COUNT(Composites!G$7:G$184))-1)} | G27: =IF(COUNT('Aide calcul'!U$6:U$184)=0,"",MIN('Aide calcul'!U$6:U$184)) | H27: =IF(COUNT('Aide calcul'!AN$6:AN$184)=0,"",MIN('Aide calcul'!AN$6:AN$184)) | I27: =COUNT(Composites!G$7:G$184) | J27: {=IF(COUNT(Composites!G173:G184)<12,"",PRODUCT(1+Composites!G173:G184)-1)} | K27: VEV de contrôle coté retenue au DIC : 10,88 %
B29: CONTRÔLE BROOKFIELD rapport des cours de fin de mois septembre / août 2016 dans la série brute
B30: Rapport septembre 2016 / août 2016, série Brut ajusté | D30: =INDEX('Brut ajusté'!J$6:J$184,MATCH(DATE(2016,9,1),'Brut ajusté'!$B$6:$B$184,0))/INDEX('Brut ajusté'!J$6:J$184,MATCH(DATE(2016,8,1),'Brut ajusté'!$B$6:$B$184,0)) | E30: ="Facteur appliqué : "&SUBSTITUTE(ROUND(BIP_facteur,2)&"",".",",")&" - un rapport proche de 1 signifie que la source a déjà ajusté le regroupement 3 pour 2 ; un rapport proche de 1,5 appelle le facteur 1,5."
B32: Lecture risque : les trusts d'infrastructure cotés à Londres (3IN, HICL, INPP, SEQI, GCP) traitent avec une décote sur l'actif net ; leur cours intègre un risque de taux et de liquidité que les VL des fonds cibles ne montrent pas. Ils constituent le contrôle coté le plus proche des fonds non cotés du portefeuille.
B33: Brookfield (BIP) est conservé en information mais exclu des composites : les distributions d'actions BIPC de mars 2020 et de juin 2022 ne sont pas reflétées dans la série de cours, dont le rendement total est donc sous-estimé. Le facteur de regroupement de septembre 2016 est paramétré (onglet Paramètres).
B34: Les composites sont équipondérés en devise locale : ils mesurent le risque de marché des actifs, non le risque de change du Fonds (51 % de l'actif en dollars non couverts). Les volatilités mensuelles sont comparables aux volatilités désmoothées Preqin du DIC et à la VEV de contrôle coté de 10,88 %.

Sheet Paramètres
B2: PARAMÈTRES - PROXIES COTÉS
B3: Cellules crème : saisies. Les onglets Historique ajusté, Rendements, Composites et Synthèse sont en formules et se recalculent à partir de cet onglet.
B5: Paramètre | C5: Valeur | D5: Unité | E5: Commentaire
B6: Brookfield (NYSE:BIP) - date du regroupement 3 pour 2 | C6: 42627 | D6: date | E6: Les cours de fin de mois antérieurs à cette date sont divisés par le facteur ci-dessous.
B7: Brookfield (NYSE:BIP) - facteur appliqué avant cette date | C7: 1 | D7: x | E7: 1,5 pour une source brute (CapIQ). Mis à 1,0 ici : la série Yahoo est déjà ajustée du regroupement (contrôle en Synthèse : rapport septembre / août 2016).
B8: Brookfield (NYSE:BIP) - inclusion dans les composites | C8: 0 | D8: 1/0 | E8: Exclu : les distributions d'actions BIPC de mars 2020 et juin 2022 ne sont probablement pas ajustées dans la série de cours (rendement total sous-estimé).
B9: INFR (LSE) - début des statistiques | C9: 42370 | D9: date | E9: Quatre points aberrants de la source (pence et livres mélangés) avant cette date ; mois antérieurs ignorés dans les rendements.
B10: Seuil d'exclusion d'un rendement mensuel aberrant | C10: 0.6 | D10: log | E10: Un rendement mensuel dont la valeur absolue en logarithme dépasse ce seuil est ignoré (erreur de source). Mars 2020 reste en deçà pour toutes les séries.
B11: Fenêtre glissante des pires performances | C11: 12 | D11: mois
B13: INCLUSION DANS LES COMPOSITES 1 = inclus, 0 = exclu
B14: Ticker | C14: Composite | D14: C1 Infrastructure capital | E14: C2 Dette d'infrastructure | F14: C3 Direct lending | G14: C4 Poche liquide | H14: Commentaire
B15: NasdaqGM:IGF | C15: C1 | D15: 1 | E15: 0 | F15: 0 | G15: 0
B16: LSE:INFR | C16: C1 | D16: 1 | E16: 0 | F16: 0 | G16: 0
B17: LSE:3IN | C17: C1 | D17: 1 | E17: 0 | F17: 0 | G17: 0
B18: LSE:HICL | C18: C1 | D18: 1 | E18: 0 | F18: 0 | G18: 0
B19: LSE:INPP | C19: C1 | D19: 1 | E19: 0 | F19: 0 | G19: 0
B20: LSE:SEQI | C20: C2 | D20: 0 | E20: 1 | F20: 0 | G20: 0
B21: LSE:GCP | C21: C2 | D21: 0 | E21: 1 | F21: 0 | G21: 0
B22: NYSE:BIP | C22: C1 | D22: =BIP_inclus | E22: 0 | F22: 0 | G22: 0 | H22: Exclu par défaut (voir paramètre BIP)
B23: KOSE:A088980 | C23: C1 | D23: 1 | E23: 0 | F23: 0 | G23: 0
B24: ARCA:BKLN | C24: C4 | D24: 0 | E24: 0 | F24: 0 | G24: 1
B25: ARCA:HYG | C25: C4 | D25: 0 | E25: 0 | F25: 0 | G25: 1
B26: LSE:IHYG | C26: C4 | D26: 0 | E26: 0 | F26: 0 | G26: 1
B27: NasdaqGS:ARCC | C27: C3 | D27: 0 | E27: 0 | F27: 1 | G27: 0
B28: ARCA:BIZD | C28: C3 | D28: 0 | E28: 0 | F28: 1 | G28: 0
B30: PONDÉRATION DU CONTRÔLE COTÉ DU PORTEFEUILLE allocation cible du Fonds projetée sur les composites
B31: Ligne du Fonds | C31: Poids | D31: C1 | E31: C2 | F31: C3 | G31: C4 | H31: Commentaire
B32: MAPIF II | C32: 0.34 | D32: 1 | E32: 0 | F32: 0 | G32: 0 | H32: Secondaires d'infrastructure : capital
B33: MSIG 3 | C33: 0.17 | D33: 0 | E33: 0 | F33: 1 | G33: 0 | H33: Dette privée d'infrastructure : direct lending
B34: PG NGI | C34: 0.17 | D34: 1 | E34: 0 | F34: 0 | G34: 0 | H34: Value add : capital (BIP serait le proxy le plus proche, exclu)
B35: Ares AGI | C35: 0.17 | D35: 0.6 | E35: 0 | F35: 0.2 | G35: 0.2 | H35: 60 % infrastructure, 20 % dette privée, 20 % liquide et HY
B36: Actifs liquides | C36: 0.15 | D36: 0 | E36: 0 | F36: 0 | G36: 1 | H36: Monétaire et haut rendement
B37: Poids des composites dans le contrôle coté | C37: =SUM(C32:C36) | D37: =SUMPRODUCT($C$32:$C$36,D32:D36) | E37: =SUMPRODUCT($C$32:$C$36,E32:E36) | F37: =SUMPRODUCT($C$32:$C$36,F32:F36) | G37: =SUMPRODUCT($C$32:$C$36,G32:G36)

Sheet Historique cours
B2: HISTORIQUE COURS - clôture de fin de mois, devise de cotation (LSE en livres)
B3: Clôture non ajustée, telle que publiée par la source. Mois en cours exclu. Information seulement : les calculs utilisent l'onglet Brut ajusté puis Historique ajusté.
B5: Mois | C5: NasdaqGM:IGF | D5: LSE:INFR | E5: LSE:3IN | F5: LSE:HICL | G5: LSE:INPP | H5: LSE:SEQI | I5: LSE:GCP | J5: NYSE:BIP | K5: KOSE:A088980 | L5: ARCA:BKLN | M5: ARCA:HYG | N5: LSE:IHYG | O5: NasdaqGS:ARCC | P5: ARCA:BIZD
B6: 40848 | C6: 34.16 | D6: 13.65 | E6: 1.702962 | F6: 1.173 | G6: 1.184348 | I6: 1.003344 | J6: 10.178571 | K6: 5050 | L6: 23.91 | M6: 86.599998 | N6: 93.540001 | O6: 15.56
B7: 40878 | C7: 33.200001 | D7: 14.0125 | E7: 1.6888879 | F7: 1.178 | G7: 1.209 | I7: 1.04125 | J7: 10.992063 | K7: 5000 | L7: 23.809999 | M7: 89.43 | N7: 95.724998 | O7: 15.45
B8: 40909 | C8: 34.130001 | D8: 13.455 | E8: 1.690295 | F8: 1.177 | G8: 1.205337 | I8: 1.07625 | J8: 11.575397 | K8: 5080 | L8: 24.42 | M8: 90.739998 | N8: 101.6 | O8: 15.85
B9: 40940 | C9: 35.34 | D9: 13.665 | E9: 1.708591 | F9: 1.19 | G9: 1.178351 | I9: 1.0575 | J9: 11.789683 | K9: 5380 | L9: 24.459999 | M9: 92.129997 | N9: 101.34 | O9: 16.67
B10: 40969 | C10: 35.41 | D10: 13.8125 | E10: 1.7522211 | F10: 1.204 | G10: 1.196 | I10: 1.05625 | J10: 12.539683 | K10: 5580 | L10: 24.58 | M10: 90.720001 | N10: 102.63 | O10: 16.35
B11: 41000 | C11: 35.52 | D11: 13.45 | E11: 1.776147 | F11: 1.2 | G11: 1.176353 | I11: 1.05375 | J11: 12.515873 | K11: 5540 | L11: 24.59 | M11: 91.199997 | N11: 101.66 | O11: 16.040001
B12: 41030 | C12: 32.740002 | D12: 13.39 | E12: 1.745184 | F12: 1.207 | G12: 1.165 | I12: 1.04125 | J12: 12.420635 | K12: 5880 | L12: 24.139999 | M12: 87.769997 | N12: 99.32 | O12: 15.09
B13: 41061 | C13: 33.959999 | D13: 13.9325 | E13: 1.708591 | F13: 1.185 | G13: 1.184 | I13: 1.045 | J13: 13.321429 | K13: 6040 | L13: 24.379999 | M13: 91.290001 | N13: 102.74 | O13: 15.96
B14: 41091 | C14: 34.27 | D14: 13.7875 | E14: 1.735332 | F14: 1.213 | G14: 1.217 | I14: 1.0675 | J14: 13.202381 | K14: 6160 | L14: 24.57 | M14: 91.699997 | N14: 104.385 | O14: 16.629999
B15: 41122 | C15: 34.450001 | D15: 13.575 | E15: 1.770517 | F15: 1.23 | G15: 1.243 | I15: 1.06625 | J15: 13.563492 | K15: 6690 | L15: 24.77 | M15: 92.330002 | N15: 102.63 | O15: 17.27
B16: 41153 | C16: 35.25 | D16: 13.5375 | E16: 1.780369 | F16: 1.214 | G16: 1.217 | I16: 1.06625 | J16: 14.107143 | K16: 6500 | L16: 24.950001 | M16: 92.300003 | N16: 103.795 | O16: 17.139999
B17: 41183 | C17: 35.810001 | D17: 13.5575 | E17: 1.767702 | F17: 1.249 | G17: 1.242 | I17: 1.1075 | J17: 13.630952 | K17: 6700 | L17: 24.84 | M17: 92.589996 | N17: 106.385 | O17: 17.440001
... B21: 41306 | C21: 36.349998 | D21: 14.55 | E21: 1.823999 | F21: 1.231 | G21: 1.263 | I21: 1.1175 | J21: 15.734127 | K21: 6730 | L21: 25 | M21: 94.040001 | N21: 106.28 | O21: 18.52
B22: 41334 | C22: 37.169998 | D22: 22.873579 | E22: 1.866221 | F22: 1.164 | G22: 1.292 | I22: 1.1425 | J22: 15.103175 | K22: 6740 | L22: 25.1 | M22: 94.349998 | N22: 106.72 | O22: 18.1 | P22: 20.440001
B23: 41365 | C23: 38.880001 | D23: 15.4675 | E23: 1.864814 | F23: 1.3039999 | G23: 1.285 | I23: 1.1225 | J23: 15.337302 | K23: 6980 | L23: 25.190001 | M23: 95.849998 | N23: 109.06 | O23: 18.16 | P23: 20.76
B24: 41395 | C24: 36.610001 | D24: 15.075 | E24: 1.84511 | F24: 1.2810001 | G24: 1.2910001 | I24: 1.0675 | J24: 14.412698 | K24: 7400 | L24: 25.08 | M24: 92.919998 | N24: 108.385 | O24: 17.15 | P24: 19.98
B25: 41426 | C25: 35.189999 | D25: 14.7525 | E25: 1.8901469 | F25: 1.327 | G25: 1.287 | I25: 1.085 | J25: 14.492063 | K25: 6840 | L25: 24.75 | M25: 90.879997 | N25: 106.29 | O25: 17.200001 | P25: 19.93
B26: 41456 | C26: 36.650002 | D26: 15.1825 | E26: 1.914073 | F26: 1.3039999 | G26: 1.315 | I26: 1.1 | J26: 14.793651 | K26: 6810 | L26: 24.950001 | M26: 92.980003 | N26: 108.62 | O26: 17.780001 | P26: 20.42
B27: 41487 | C27: 35.400002 | D27: 14.2375 | E27: 1.887332 | F27: 1.3210001 | G27: 1.328 | I27: 1.1075 | J27: 14.043651 | K27: 6840 | L27: 24.719999 | M27: 91.349998 | N27: 104.98 | O27: 17.58 | P27: 19.790001
B28: 41518 | C28: 37.77 | D28: 14.205 | E28: 1.8746651 | F28: 1.2989999 | G28: 1.24 | I28: 1.0925 | J28: 15.087302 | K28: 6610 | L28: 24.68 | M28: 91.580002 | N28: 106.57 | O28: 17.290001 | P28: 20.549999
B29: 41548 | C29: 39.189999 | D29: 14.625 | E29: 1.914073 | F29: 1.3289999 | G29: 1.256 | I29: 1.1075 | J29: 15.623016 | K29: 6600 | L29: 24.83 | M29: 93.43 | N29: 108.395 | O29: 17.370001 | P29: 20.540001
B30: 41579 | C30: 38.77 | D30: 14.15 | E30: 1.787406 | F30: 1.293 | G30: 1.245 | I30: 1.085 | J30: 15.190476 | K30: 6610 | L30: 24.82 | M30: 93.419998 | N30: 109.135 | O30: 18.379999 | P30: 21.57
B31: 41609 | C31: 38.939999 | D31: 14.125 | E31: 1.8788879 | F31: 1.345 | G31: 1.276 | I31: 1.1275 | J31: 15.563492 | K31: 6110 | L31: 24.879999 | M31: 92.879997 | N31: 110.085 | O31: 17.77 | P31: 20.98
B32: 41640 | C32: 38.43 | D32: 14.1075 | E32: 1.908443 | F32: 1.348 | G32: 1.282 | I32: 1.0875 | J32: 14.599206 | K32: 6010 | L32: 24.91 | M32: 93.25 | N32: 109.95 | O32: 17.709999 | P32: 20.860001
B33: 41671 | C33: 40.200001 | D33: 14.51 | E33: 1.904221 | F33: 1.382 | G33: 1.303 | I33: 1.1075 | J33: 14.84127 | K33: 6210 | L33: 24.870001 | M33: 94.93 | N33: 108.64 | O33: 18.030001 | P33: 21.209999
... B46: 42064 | C46: 41.84 | D46: 16.625 | E46: 2.2546651 | F46: 1.565 | G46: 1.378 | I46: 1.175 | J46: 18.071428 | K46: 7830 | L46: 24.09 | M46: 90.610001 | N46: 108.38 | O46: 17.17 | P46: 18.700001
B47: 42095 | C47: 43.709999 | D47: 16.345 | E47: 2.2434061 | F47: 1.532 | G47: 1.3660001 | H47: 1.0465 | I47: 1.15 | J47: 17.432541 | K47: 7910 | L47: 24.18 | M47: 90.989998 | N47: 108.58 | O47: 17.02 | P47: 18.559999
B48: 42125 | C48: 43.119999 | D48: 16.345 | E48: 2.3644431 | F48: 1.53 | G48: 1.373 | H48: 1.055128 | I48: 1.1825 | J48: 17.162699 | K48: 7850 | L48: 24.139999 | M48: 90.910004 | N48: 109.01 | O48: 16.75 | P48: 18.34
B49: 42156 | C49: 40.619999 | D49: 15.13 | E49: 2.3644431 | F49: 1.54 | G49: 1.357 | H49: 1.050198 | I49: 1.145 | J49: 17.710318 | K49: 8050 | L49: 23.790001 | M49: 88.800003 | N49: 106.79 | O49: 16.459999 | P49: 17.889999
B50: 42186 | C50: 40.810001 | D50: 15.545 | E50: 2.140665 | F50: 1.5239999 | G50: 1.37 | H50: 1.020615 | I50: 1.174 | J50: 16.611111 | K50: 7900 | L50: 23.690001 | M50: 87.970001 | N50: 107.86 | O50: 16.09 | P50: 17.01
B51: 42217 | C51: 38.650002 | D51: 22.9229 | E51: 2.0849319 | F51: 1.5139999 | G51: 1.358 | H51: 1.02801 | I51: 1.187 | J51: 15.674603 | K51: 7930 | L51: 23.379999 | M51: 86.239998 | N51: 104.358 | O51: 15.77 | P51: 17.139999
B52: 42248 | C52: 37.73 | D52: 14.735 | E52: 2.1191319 | F52: 1.523 | G52: 1.3089999 | H52: 1.02801 | I52: 1.213 | J52: 14.59127 | K52: 7940 | L52: 23.040001 | M52: 83.290001 | N52: 101.89 | O52: 14.48 | P52: 15.71
B53: 42278 | C53: 39.349998 | D53: 15.0925 | E53: 2.183732 | F53: 1.547 | G53: 1.318 | H53: 1.015684 | I53: 1.213 | J53: 16.690475 | K53: 8000 | L53: 23 | M53: 85.57 | N53: 105.39 | O53: 15.23 | P53: 16.040001
B54: 42309 | C54: 37.720001 | D54: 14.7675 | E54: 2.186265 | F54: 1.525 | G54: 1.38 | H54: 1.025545 | I54: 1.185 | J54: 16.484127 | K54: 7940 | L54: 22.690001 | M54: 83.050003 | N54: 105.58 | O54: 15.82 | P54: 17.32
B55: 42339 | C55: 35.939999 | D55: 14.83 | E55: 2.176132 | F55: 1.507 | G55: 1.393 | H55: 1.018149 | I55: 1.201 | J55: 15.043651 | K55: 8030 | L55: 22.4 | M55: 80.580002 | N55: 102.705 | O55: 14.25 | P55: 15.77
B56: 42370 | C56: 35.889999 | D56: 15.655 | E56: 2.165999 | F56: 1.513 | G56: 1.405 | H56: 0.99596199 | I56: 1.15 | J56: 14.265873 | K56: 8170 | L56: 22.18 | M56: 79.290001 | N56: 101.9 | O56: 13.9 | P56: 14.8
B57: 42401 | C57: 35.990002 | D57: 15.9975 | E57: 2.1938651 | F57: 1.557 | G57: 1.423 | H57: 1.020615 | I57: 1.192 | J57: 14.940476 | K57: 8470 | L57: 22.120001 | M57: 80.080002 | N57: 101.9 | O57: 13.66 | P57: 15.11
...

Sheet Brut ajusté
B2: BRUT AJUSTÉ - clôture de fin de mois, devise de cotation (LSE en livres)
B3: Clôture ajustée des dividendes telle que téléchargée (Yahoo Finance). Aucune correction : les corrections paramétrées sont appliquées dans l'onglet Historique ajusté.
B5: Mois | C5: NasdaqGM:IGF | D5: LSE:INFR | E5: LSE:3IN | F5: LSE:HICL | G5: LSE:INPP | H5: LSE:SEQI | I5: LSE:GCP | J5: NYSE:BIP | K5: KOSE:A088980 | L5: ARCA:BKLN | M5: ARCA:HYG | N5: LSE:IHYG | O5: NasdaqGS:ARCC | P5: ARCA:BIZD
B6: 40848 | C6: 21.164545 | D6: 13.60832 | E6: 1.6888113 | F6: 1.1637467 | G6: 1.1756075 | I6: 0.9928949 | J6: 5.2103019 | K6: 1939.7854 | L6: 11.245183 | M6: 38.252228 | N6: 49.066017 | O6: 3.7332234
B7: 40878 | C7: 21.105621 | D7: 13.969712 | E7: 1.6752696 | F7: 1.1687073 | G7: 1.2000774 | I7: 1.0304063 | J7: 5.62672 | K7: 1985.0553 | L7: 11.252995 | M7: 39.993488 | N7: 50.212158 | O7: 3.7956185
B8: 40909 | C8: 21.696833 | D8: 13.41391 | E8: 1.6766656 | F8: 1.1677155 | G8: 1.1964413 | I8: 1.0650417 | J8: 5.925323 | K8: 2016.8163 | L8: 11.589306 | M8: 40.579342 | N8: 53.293846 | O8: 3.8938861
B9: 40940 | C9: 22.466036 | D9: 13.623278 | E9: 1.6948141 | F9: 1.1806126 | G9: 1.1696544 | I9: 1.0464867 | J9: 6.1113544 | K9: 2135.9192 | L9: 11.656215 | M9: 41.432453 | N9: 53.157478 | O9: 4.0953383
B10: 40969 | C10: 22.510542 | D10: 13.770322 | E10: 1.7380922 | F10: 1.1945021 | G10: 1.1871732 | I10: 1.0452502 | J10: 6.5001297 | K10: 2215.3213 | L10: 11.761751 | M10: 41.037544 | N10: 53.834137 | O10: 4.109148
B11: 41000 | C11: 22.580469 | D11: 13.408928 | E11: 1.7618256 | F11: 1.1908711 | G11: 1.1679524 | I11: 1.042776 | J11: 6.4877863 | K11: 2199.4414 | L11: 11.81807 | M11: 41.504005 | N11: 53.325344 | O11: 4.0312362
B12: 41030 | C12: 20.81319 | D12: 13.349116 | E12: 1.7311121 | F12: 1.1978178 | G12: 1.1566808 | I12: 1.0307664 | J12: 6.5164909 | K12: 2334.4248 | L12: 11.651369 | M12: 40.167244 | N12: 52.097885 | O12: 3.7924786
B13: 41061 | C13: 22.032398 | D13: 13.88996 | E13: 1.6952214 | F13: 1.175985 | G13: 1.175545 | I13: 1.0344787 | J13: 6.9890947 | K13: 2489.2175 | L13: 11.815828 | M13: 42.037735 | N13: 53.89185 | O13: 4.1090293
B14: 41091 | C14: 22.233521 | D14: 13.745403 | E14: 1.7217535 | F14: 1.2037721 | G14: 1.2083092 | I14: 1.0567519 | J14: 6.9266334 | K14: 2538.6729 | L14: 11.958699 | M14: 42.467503 | N14: 54.754723 | O14: 4.2815242
B15: 41122 | C15: 22.350304 | D15: 13.53355 | E15: 1.7566629 | F15: 1.2206428 | G15: 1.2341235 | I15: 1.0555145 | J15: 7.1920877 | K15: 2757.0972 | L15: 12.100555 | M15: 42.996078 | N15: 53.834137 | O15: 4.4462972
B16: 41153 | C16: 22.869322 | D16: 13.496162 | E16: 1.7664377 | F16: 1.2047646 | G16: 1.2086036 | I16: 1.0555145 | J16: 7.48036 | K16: 2678.7947 | L16: 12.23293 | M16: 43.219898 | N16: 54.445236 | O16: 4.5228271
B17: 41183 | C17: 23.232632 | D17: 13.516101 | E17: 1.7538698 | F17: 1.2394982 | G17: 1.2334309 | I17: 1.0963495 | J17: 7.2278557 | K17: 2761.2185 | L17: 12.229397 | M17: 43.584679 | N17: 55.803806 | O17: 4.6019912
... B21: 41306 | C21: 24.111961 | D21: 14.505574 | E21: 1.8101523 | F21: 1.2223178 | G21: 1.254286 | I21: 1.1066268 | J21: 8.52981 | K21: 2879.6316 | L21: 12.509544 | M21: 44.982922 | N21: 57.697121 | O21: 5.0100093
B22: 41334 | C22: 24.65589 | D22: 22.803733 | E22: 1.8520537 | F22: 1.1557902 | G22: 1.2830861 | I22: 1.1313837 | J22: 8.1877565 | K22: 2883.9097 | L22: 12.607686 | M22: 45.375381 | N22: 57.93597 | O22: 4.9993043 | P22: 5.4540987
B23: 41365 | C23: 25.790184 | D23: 15.42027 | E23: 1.8506575 | F23: 1.2948029 | G23: 1.2764242 | I23: 1.111578 | J23: 8.3146858 | K23: 2986.6008 | L23: 12.700808 | M23: 46.336414 | N23: 59.206299 | O23: 5.0158763 | P23: 5.596159
B24: 41395 | C24: 24.284426 | D24: 15.028967 | E24: 1.8311031 | F24: 1.2719652 | G24: 1.2823842 | I24: 1.0574793 | J24: 7.9016905 | K24: 3166.3105 | L24: 12.691501 | M24: 45.140404 | N24: 58.83987 | O24: 4.7369108 | P24: 5.3858995
B25: 41426 | C25: 23.92012 | D25: 14.707456 | E25: 1.8762833 | F25: 1.3176411 | G25: 1.2784113 | I25: 1.0748151 | J25: 7.9451981 | K25: 3021.9856 | L25: 12.569842 | M25: 44.378147 | N25: 57.702538 | O25: 4.8603945 | P25: 5.3724203
B26: 41456 | C26: 24.912546 | D26: 15.136136 | E26: 1.900034 | F26: 1.2948029 | G26: 1.3062247 | I26: 1.0896743 | J26: 8.1105442 | K26: 3008.7312 | L26: 12.717335 | M26: 45.644665 | N26: 58.967453 | O26: 5.0242934 | P26: 5.5744328
B27: 41487 | C27: 24.062864 | D27: 14.194022 | E27: 1.8734894 | F27: 1.3116826 | G27: 1.3191373 | I27: 1.097104 | J27: 7.7942758 | K27: 3021.9856 | L27: 12.64585 | M27: 45.064026 | N27: 58.911861 | O27: 4.9677768 | P27: 5.4024491
B28: 41518 | C28: 25.673853 | D28: 14.161622 | E28: 1.8609154 | F28: 1.2898384 | G28: 1.2320219 | I28: 1.0822447 | J28: 8.3735085 | K28: 2920.3691 | L28: 12.667779 | M28: 45.416157 | N28: 59.804123 | O28: 4.9922242 | P28: 5.6099205
B29: 41548 | C29: 26.639084 | D29: 14.580341 | E29: 1.900034 | F29: 1.3196263 | G29: 1.2479191 | I29: 1.097104 | J29: 8.6708336 | K29: 2915.9512 | L29: 12.787707 | M29: 46.559853 | N29: 60.828262 | O29: 5.0153232 | P29: 5.6987023
B30: 41579 | C30: 26.353592 | D30: 14.106792 | E30: 1.7747528 | F30: 1.2842155 | G30: 1.2369897 | I30: 1.0751832 | J30: 8.5240593 | K30: 2920.3691 | L30: 12.825866 | M30: 46.780182 | N30: 61.243538 | O30: 5.3069458 | P30: 5.9844718
B31: 41609 | C31: 26.821722 | D31: 14.081871 | E31: 1.8655873 | F31: 1.3358615 | G31: 1.2677905 | I31: 1.1172986 | J31: 8.7333746 | K31: 2830.8171 | L31: 12.900496 | M31: 46.970409 | N31: 61.776634 | O31: 5.2584929 | P31: 5.919764
B32: 41640 | C32: 26.470432 | D32: 14.065253 | E32: 1.894933 | F32: 1.3388412 | G32: 1.2737518 | I32: 1.0778445 | J32: 8.1922731 | K32: 2784.4861 | L32: 12.959589 | M32: 47.157513 | N32: 61.700886 | O32: 5.2407365 | P32: 5.8859062
B33: 41671 | C33: 27.6896 | D33: 14.466552 | E33: 1.8907408 | F33: 1.3726096 | G33: 1.2946169 | I33: 1.097667 | J33: 8.4369135 | K33: 2877.1482 | L33: 12.982058 | M33: 48.246159 | N33: 62.627285 | O33: 5.3354335 | P33: 5.9846649
... B46: 42064 | C46: 29.673439 | D46: 16.579808 | E46: 2.2397528 | F46: 1.5553278 | G46: 1.3697806 | I46: 1.1653316 | J46: 10.756918 | K46: 3862.3062 | L46: 13.123964 | M46: 48.805016 | N46: 65.415527 | O46: 5.7185688 | P46: 5.7032542
B47: 42095 | C47: 30.99966 | D47: 16.301447 | E47: 2.2285684 | F47: 1.5225316 | G47: 1.3581596 | H47: 1.0388469 | I47: 1.1407185 | J47: 10.376625 | K47: 3901.7683 | L47: 13.212755 | M47: 49.230274 | N47: 65.536255 | O47: 5.6686125 | P47: 5.7622437
B48: 42125 | C48: 30.581224 | D48: 16.301447 | E48: 2.3488043 | F48: 1.5207288 | G48: 1.3651193 | H48: 1.0474117 | I48: 1.1729557 | J48: 10.339703 | K48: 3872.1721 | L48: 13.23135 | M48: 49.405273 | N48: 65.795799 | O48: 5.5786853 | P48: 5.6939411
B49: 42156 | C49: 29.170858 | D49: 15.089689 | E49: 2.3493091 | F49: 1.5306679 | G49: 1.3492114 | H49: 1.0425178 | I49: 1.1357586 | J49: 10.66962 | K49: 4076.6479 | L49: 13.080473 | M49: 48.472912 | N49: 64.455872 | O49: 5.6119738 | P49: 5.5542307
B50: 42186 | C50: 29.307306 | D50: 15.505314 | E50: 2.1289137 | F50: 1.5147652 | G50: 1.362137 | H50: 1.0132468 | I50: 1.1647125 | J50: 10.007397 | K50: 4000.6855 | L50: 13.066955 | M50: 48.234421 | N50: 65.101685 | O50: 5.4858241 | P50: 5.3956299
B51: 42217 | C51: 27.756123 | D51: 22.86438 | E51: 2.0734869 | F51: 1.5050085 | G51: 1.3502054 | H51: 1.0205884 | I51: 1.1776098 | J51: 9.5733948 | K51: 4015.8772 | L51: 12.938985 | M51: 47.499657 | N51: 64.429916 | O51: 5.3767223 | P51: 5.4368653
B52: 42248 | C52: 27.095438 | D52: 14.697383 | E52: 2.1074992 | F52: 1.5139554 | G52: 1.3018004 | H52: 1.0205884 | I52: 1.203404 | J52: 8.9117403 | K52: 4020.9412 | L52: 12.793956 | M52: 46.079498 | N52: 62.906189 | O52: 5.0621367 | P52: 4.9832659
B53: 42278 | C53: 28.258818 | D53: 15.053967 | E53: 2.1717447 | F53: 1.5378131 | G53: 1.3107507 | H53: 1.0083515 | I53: 1.2035915 | J53: 10.193851 | K53: 4051.3271 | L53: 12.816054 | M53: 47.568195 | N53: 65.06707 | O53: 5.3243332 | P53: 5.1971111
B54: 42309 | C54: 27.088253 | D54: 14.730857 | E54: 2.1747092 | F54: 1.5161275 | G54: 1.3724094 | H54: 1.0182401 | I54: 1.1758086 | J54: 10.1952 | K54: 4020.9412 | L54: 12.688275 | M54: 46.38089 | N54: 65.18438 | O54: 5.5305939 | P54: 5.6118422
B55: 42339 | C55: 26.27713 | D55: 14.793206 | E55: 2.16463 | F55: 1.498232 | G55: 1.3853384 | H55: 1.0108968 | I55: 1.1916845 | J55: 9.304286 | K55: 4196.3447 | L55: 12.573391 | M55: 45.456821 | N55: 63.40937 | O55: 5.1092954 | P55: 5.2379169
B56: 42370 | C56: 26.240574 | D56: 15.616156 | E56: 2.1545505 | F56: 1.5041966 | G56: 1.3972722 | H56: 0.98901405 | I56: 1.1412649 | J56: 8.8232412 | K56: 4269.5059 | L56: 12.496996 | M56: 44.72913 | N56: 62.912365 | O56: 4.9838023 | P56: 4.9157376
B57: 42401 | C57: 26.31369 | D57: 15.958739 | E57: 2.1822685 | F57: 1.5481232 | G57: 1.4151735 | H57: 1.0134954 | I57: 1.1829455 | J57: 9.3863754 | K57: 4426.2812 | L57: 12.511206 | M57: 45.398663 | N57: 62.912365 | O57: 4.8977528 | P57: 5.018702
...

Sheet Historique ajusté
B2: HISTORIQUE AJUSTÉ - base des rendements
B3: Formules : Brut ajusté corrigé des paramètres (facteur Brookfield avant la date de regroupement, début des statistiques INFR). Une cellule vide signifie : pas de donnée.
B5: Mois | C5: NasdaqGM:IGF | D5: LSE:INFR | E5: LSE:3IN | F5: LSE:HICL | G5: LSE:INPP | H5: LSE:SEQI | I5: LSE:GCP | J5: NYSE:BIP | K5: KOSE:A088980 | L5: ARCA:BKLN | M5: ARCA:HYG | N5: LSE:IHYG | O5: NasdaqGS:ARCC | P5: ARCA:BIZD
B6: ='Brut ajusté'!B6 | C6: =IF('Brut ajusté'!C6="","",'Brut ajusté'!C6) | D6: =IF(OR('Brut ajusté'!D6="",$B6<INFR_debut),"",'Brut ajusté'!D6) | E6: =IF('Brut ajusté'!E6="","",'Brut ajusté'!E6) | F6: =IF('Brut ajusté'!F6="","",'Brut ajusté'!F6) | G6: =IF('Brut ajusté'!G6="","",'Brut ajusté'!G6) | H6: =IF('Brut ajusté'!H6="","",'Brut ajusté'!H6) | I6: =IF('Brut ajusté'!I6="","",'Brut ajusté'!I6) | J6: =IF('Brut ajusté'!J6="","",IF($B6<BIP_date,'Brut ajusté'!J6/BIP_facteur,'Brut ajusté'!J6)) | K6: =IF('Brut ajusté'!K6="","",'Brut ajusté'!K6) | L6: =IF('Brut ajusté'!L6="","",'Brut ajusté'!L6) | M6: =IF('Brut ajusté'!M6="","",'Brut ajusté'!M6) | N6: =IF('Brut ajusté'!N6="","",'Brut ajusté'!N6) | O6: =IF('Brut ajusté'!O6="","",'Brut ajusté'!O6) | P6: =IF('Brut ajusté'!P6="","",'Brut ajusté'!P6)
B7: ='Brut ajusté'!B7 | C7: =IF('Brut ajusté'!C7="","",'Brut ajusté'!C7) | D7: =IF(OR('Brut ajusté'!D7="",$B7<INFR_debut),"",'Brut ajusté'!D7) | E7: =IF('Brut ajusté'!E7="","",'Brut ajusté'!E7) | F7: =IF('Brut ajusté'!F7="","",'Brut ajusté'!F7) | G7: =IF('Brut ajusté'!G7="","",'Brut ajusté'!G7) | H7: =IF('Brut ajusté'!H7="","",'Brut ajusté'!H7) | I7: =IF('Brut ajusté'!I7="","",'Brut ajusté'!I7) | J7: =IF('Brut ajusté'!J7="","",IF($B7<BIP_date,'Brut ajusté'!J7/BIP_facteur,'Brut ajusté'!J7)) | K7: =IF('Brut ajusté'!K7="","",'Brut ajusté'!K7) | L7: =IF('Brut ajusté'!L7="","",'Brut ajusté'!L7) | M7: =IF('Brut ajusté'!M7="","",'Brut ajusté'!M7) | N7: =IF('Brut ajusté'!N7="","",'Brut ajusté'!N7) | O7: =IF('Brut ajusté'!O7="","",'Brut ajusté'!O7) | P7: =IF('Brut ajusté'!P7="","",'Brut ajusté'!P7)
B8: ='Brut ajusté'!B8 | C8: =IF('Brut ajusté'!C8="","",'Brut ajusté'!C8) | D8: =IF(OR('Brut ajusté'!D8="",$B8<INFR_debut),"",'Brut ajusté'!D8) | E8: =IF('Brut ajusté'!E8="","",'Brut ajusté'!E8) | F8: =IF('Brut ajusté'!F8="","",'Brut ajusté'!F8) | G8: =IF('Brut ajusté'!G8="","",'Brut ajusté'!G8) | H8: =IF('Brut ajusté'!H8="","",'Brut ajusté'!H8) | I8: =IF('Brut ajusté'!I8="","",'Brut ajusté'!I8) | J8: =IF('Brut ajusté'!J8="","",IF($B8<BIP_date,'Brut ajusté'!J8/BIP_facteur,'Brut ajusté'!J8)) | K8: =IF('Brut ajusté'!K8="","",'Brut ajusté'!K8) | L8: =IF('Brut ajusté'!L8="","",'Brut ajusté'!L8) | M8: =IF('Brut ajusté'!M8="","",'Brut ajusté'!M8) | N8: =IF('Brut ajusté'!N8="","",'Brut ajusté'!N8) | O8: =IF('Brut ajusté'!O8="","",'Brut ajusté'!O8) | P8: =IF('Brut ajusté'!P8="","",'Brut ajusté'!P8)
B9: ='Brut ajusté'!B9 | C9: =IF('Brut ajusté'!C9="","",'Brut ajusté'!C9) | D9: =IF(OR('Brut ajusté'!D9="",$B9<INFR_debut),"",'Brut ajusté'!D9) | E9: =IF('Brut ajusté'!E9="","",'Brut ajusté'!E9) | F9: =IF('Brut ajusté'!F9="","",'Brut ajusté'!F9) | G9: =IF('Brut ajusté'!G9="","",'Brut ajusté'!G9) | H9: =IF('Brut ajusté'!H9="","",'Brut ajusté'!H9) | I9: =IF('Brut ajusté'!I9="","",'Brut ajusté'!I9) | J9: =IF('Brut ajusté'!J9="","",IF($B9<BIP_date,'Brut ajusté'!J9/BIP_facteur,'Brut ajusté'!J9)) | K9: =IF('Brut ajusté'!K9="","",'Brut ajusté'!K9) | L9: =IF('Brut ajusté'!L9="","",'Brut ajusté'!L9) | M9: =IF('Brut ajusté'!M9="","",'Brut ajusté'!M9) | N9: =IF('Brut ajusté'!N9="","",'Brut ajusté'!N9) | O9: =IF('Brut ajusté'!O9="","",'Brut ajusté'!O9) | P9: =IF('Brut ajusté'!P9="","",'Brut ajusté'!P9)
B10: ='Brut ajusté'!B10 | C10: =IF('Brut ajusté'!C10="","",'Brut ajusté'!C10) | D10: =IF(OR('Brut ajusté'!D10="",$B10<INFR_debut),"",'Brut ajusté'!D10) | E10: =IF('Brut ajusté'!E10="","",'Brut ajusté'!E10) | F10: =IF('Brut ajusté'!F10="","",'Brut ajusté'!F10) | G10: =IF('Brut ajusté'!G10="","",'Brut ajusté'!G10) | H10: =IF('Brut ajusté'!H10="","",'Brut ajusté'!H10) | I10: =IF('Brut ajusté'!I10="","",'Brut ajusté'!I10) | J10: =IF('Brut ajusté'!J10="","",IF($B10<BIP_date,'Brut ajusté'!J10/BIP_facteur,'Brut ajusté'!J10)) | K10: =IF('Brut ajusté'!K10="","",'Brut ajusté'!K10) | L10: =IF('Brut ajusté'!L10="","",'Brut ajusté'!L10) | M10: =IF('Brut ajusté'!M10="","",'Brut ajusté'!M10) | N10: =IF('Brut ajusté'!N10="","",'Brut ajusté'!N10) | O10: =IF('Brut ajusté'!O10="","",'Brut ajusté'!O10) | P10: =IF('Brut ajusté'!P10="","",'Brut ajusté'!P10)
B11: ='Brut ajusté'!B11 | C11: =IF('Brut ajusté'!C11="","",'Brut ajusté'!C11) | D11: =IF(OR('Brut ajusté'!D11="",$B11<INFR_debut),"",'Brut ajusté'!D11) | E11: =IF('Brut ajusté'!E11="","",'Brut ajusté'!E11) | F11: =IF('Brut ajusté'!F11="","",'Brut ajusté'!F11) | G11: =IF('Brut ajusté'!G11="","",'Brut ajusté'!G11) | H11: =IF('Brut ajusté'!H11="","",'Brut ajusté'!H11) | I11: =IF('Brut ajusté'!I11="","",'Brut ajusté'!I11) | J11: =IF('Brut ajusté'!J11="","",IF($B11<BIP_date,'Brut ajusté'!J11/BIP_facteur,'Brut ajusté'!J11)) | K11: =IF('Brut ajusté'!K11="","",'Brut ajusté'!K11) | L11: =IF('Brut ajusté'!L11="","",'Brut ajusté'!L11) | M11: =IF('Brut ajusté'!M11="","",'Brut ajusté'!M11) | N11: =IF('Brut ajusté'!N11="","",'Brut ajusté'!N11) | O11: =IF('Brut ajusté'!O11="","",'Brut ajusté'!O11) | P11: =IF('Brut ajusté'!P11="","",'Brut ajusté'!P11)
B12: ='Brut ajusté'!B12 | C12: =IF('Brut ajusté'!C12="","",'Brut ajusté'!C12) | D12: =IF(OR('Brut ajusté'!D12="",$B12<INFR_debut),"",'Brut ajusté'!D12) | E12: =IF('Brut ajusté'!E12="","",'Brut ajusté'!E12) | F12: =IF('Brut ajusté'!F12="","",'Brut ajusté'!F12) | G12: =IF('Brut ajusté'!G12="","",'Brut ajusté'!G12) | H12: =IF('Brut ajusté'!H12="","",'Brut ajusté'!H12) | I12: =IF('Brut ajusté'!I12="","",'Brut ajusté'!I12) | J12: =IF('Brut ajusté'!J12="","",IF($B12<BIP_date,'Brut ajusté'!J12/BIP_facteur,'Brut ajusté'!J12)) | K12: =IF('Brut ajusté'!K12="","",'Brut ajusté'!K12) | L12: =IF('Brut ajusté'!L12="","",'Brut ajusté'!L12) | M12: =IF('Brut ajusté'!M12="","",'Brut ajusté'!M12) | N12: =IF('Brut ajusté'!N12="","",'Brut ajusté'!N12) | O12: =IF('Brut ajusté'!O12="","",'Brut ajusté'!O12) | P12: =IF('Brut ajusté'!P12="","",'Brut ajusté'!P12)
B13: ='Brut ajusté'!B13 | C13: =IF('Brut ajusté'!C13="","",'Brut ajusté'!C13) | D13: =IF(OR('Brut ajusté'!D13="",$B13<INFR_debut),"",'Brut ajusté'!D13) | E13: =IF('Brut ajusté'!E13="","",'Brut ajusté'!E13) | F13: =IF('Brut ajusté'!F13="","",'Brut ajusté'!F13) | G13: =IF('Brut ajusté'!G13="","",'Brut ajusté'!G13) | H13: =IF('Brut ajusté'!H13="","",'Brut ajusté'!H13) | I13: =IF('Brut ajusté'!I13="","",'Brut ajusté'!I13) | J13: =IF('Brut ajusté'!J13="","",IF($B13<BIP_date,'Brut ajusté'!J13/BIP_facteur,'Brut ajusté'!J13)) | K13: =IF('Brut ajusté'!K13="","",'Brut ajusté'!K13) | L13: =IF('Brut ajusté'!L13="","",'Brut ajusté'!L13) | M13: =IF('Brut ajusté'!M13="","",'Brut ajusté'!M13) | N13: =IF('Brut ajusté'!N13="","",'Brut ajusté'!N13) | O13: =IF('Brut ajusté'!O13="","",'Brut ajusté'!O13) | P13: =IF('Brut ajusté'!P13="","",'Brut ajusté'!P13)
B14: ='Brut ajusté'!B14 | C14: =IF('Brut ajusté'!C14="","",'Brut ajusté'!C14) | D14: =IF(OR('Brut ajusté'!D14="",$B14<INFR_debut),"",'Brut ajusté'!D14) | E14: =IF('Brut ajusté'!E14="","",'Brut ajusté'!E14) | F14: =IF('Brut ajusté'!F14="","",'Brut ajusté'!F14) | G14: =IF('Brut ajusté'!G14="","",'Brut ajusté'!G14) | H14: =IF('Brut ajusté'!H14="","",'Brut ajusté'!H14) | I14: =IF('Brut ajusté'!I14="","",'Brut ajusté'!I14) | J14: =IF('Brut ajusté'!J14="","",IF($B14<BIP_date,'Brut ajusté'!J14/BIP_facteur,'Brut ajusté'!J14)) | K14: =IF('Brut ajusté'!K14="","",'Brut ajusté'!K14) | L14: =IF('Brut ajusté'!L14="","",'Brut ajusté'!L14) | M14: =IF('Brut ajusté'!M14="","",'Brut ajusté'!M14) | N14: =IF('Brut ajusté'!N14="","",'Brut ajusté'!N14) | O14: =IF('Brut ajusté'!O14="","",'Brut ajusté'!O14) | P14: =IF('Brut ajusté'!P14="","",'Brut ajusté'!P14)
B15: ='Brut ajusté'!B15 | C15: =IF('Brut ajusté'!C15="","",'Brut ajusté'!C15) | D15: =IF(OR('Brut ajusté'!D15="",$B15<INFR_debut),"",'Brut ajusté'!D15) | E15: =IF('Brut ajusté'!E15="","",'Brut ajusté'!E15) | F15: =IF('Brut ajusté'!F15="","",'Brut ajusté'!F15) | G15: =IF('Brut ajusté'!G15="","",'Brut ajusté'!G15) | H15: =IF('Brut ajusté'!H15="","",'Brut ajusté'!H15) | I15: =IF('Brut ajusté'!I15="","",'Brut ajusté'!I15) | J15: =IF('Brut ajusté'!J15="","",IF($B15<BIP_date,'Brut ajusté'!J15/BIP_facteur,'Brut ajusté'!J15)) | K15: =IF('Brut ajusté'!K15="","",'Brut ajusté'!K15) | L15: =IF('Brut ajusté'!L15="","",'Brut ajusté'!L15) | M15: =IF('Brut ajusté'!M15="","",'Brut ajusté'!M15) | N15: =IF('Brut ajusté'!N15="","",'Brut ajusté'!N15) | O15: =IF('Brut ajusté'!O15="","",'Brut ajusté'!O15) | P15: =IF('Brut ajusté'!P15="","",'Brut ajusté'!P15)
B16: ='Brut ajusté'!B16 | C16: =IF('Brut ajusté'!C16="","",'Brut ajusté'!C16) | D16: =IF(OR('Brut ajusté'!D16="",$B16<INFR_debut),"",'Brut ajusté'!D16) | E16: =IF('Brut ajusté'!E16="","",'Brut ajusté'!E16) | F16: =IF('Brut ajusté'!F16="","",'Brut ajusté'!F16) | G16: =IF('Brut ajusté'!G16="","",'Brut ajusté'!G16) | H16: =IF('Brut ajusté'!H16="","",'Brut ajusté'!H16) | I16: =IF('Brut ajusté'!I16="","",'Brut ajusté'!I16) | J16: =IF('Brut ajusté'!J16="","",IF($B16<BIP_date,'Brut ajusté'!J16/BIP_facteur,'Brut ajusté'!J16)) | K16: =IF('Brut ajusté'!K16="","",'Brut ajusté'!K16) | L16: =IF('Brut ajusté'!L16="","",'Brut ajusté'!L16) | M16: =IF('Brut ajusté'!M16="","",'Brut ajusté'!M16) | N16: =IF('Brut ajusté'!N16="","",'Brut ajusté'!N16) | O16: =IF('Brut ajusté'!O16="","",'Brut ajusté'!O16) | P16: =IF('Brut ajusté'!P16="","",'Brut ajusté'!P16)
B17: ='Brut ajusté'!B17 | C17: =IF('Brut ajusté'!C17="","",'Brut ajusté'!C17) | D17: =IF(OR('Brut ajusté'!D17="",$B17<INFR_debut),"",'Brut ajusté'!D17) | E17: =IF('Brut ajusté'!E17="","",'Brut ajusté'!E17) | F17: =IF('Brut ajusté'!F17="","",'Brut ajusté'!F17) | G17: =IF('Brut ajusté'!G17="","",'Brut ajusté'!G17) | H17: =IF('Brut ajusté'!H17="","",'Brut ajusté'!H17) | I17: =IF('Brut ajusté'!I17="","",'Brut ajusté'!I17) | J17: =IF('Brut ajusté'!J17="","",IF($B17<BIP_date,'Brut ajusté'!J17/BIP_facteur,'Brut ajusté'!J17)) | K17: =IF('Brut ajusté'!K17="","",'Brut ajusté'!K17) | L17: =IF('Brut ajusté'!L17="","",'Brut ajusté'!L17) | M17: =IF('Brut ajusté'!M17="","",'Brut ajusté'!M17) | N17: =IF('Brut ajusté'!N17="","",'Brut ajusté'!N17) | O17: =IF('Brut ajusté'!O17="","",'Brut ajusté'!O17) | P17: =IF('Brut ajusté'!P17="","",'Brut ajusté'!P17)
... B184: ='Brut ajusté'!B184 | C184: =IF('Brut ajusté'!C184="","",'Brut ajusté'!C184) | D184: =IF(OR('Brut ajusté'!D184="",$B184<INFR_debut),"",'Brut ajusté'!D184) | E184: =IF('Brut ajusté'!E184="","",'Brut ajusté'!E184) | F184: =IF('Brut ajusté'!F184="","",'Brut ajusté'!F184) | G184: =IF('Brut ajusté'!G184="","",'Brut ajusté'!G184) | H184: =IF('Brut ajusté'!H184="","",'Brut ajusté'!H184) | I184: =IF('Brut ajusté'!I184="","",'Brut ajusté'!I184) | J184: =IF('Brut ajusté'!J184="","",IF($B184<BIP_date,'Brut ajusté'!J184/BIP_facteur,'Brut ajusté'!J184)) | K184: =IF('Brut ajusté'!K184="","",'Brut ajusté'!K184) | L184: =IF('Brut ajusté'!L184="","",'Brut ajusté'!L184) | M184: =IF('Brut ajusté'!M184="","",'Brut ajusté'!M184) | N184: =IF('Brut ajusté'!N184="","",'Brut ajusté'!N184) | O184: =IF('Brut ajusté'!O184="","",'Brut ajusté'!O184) | P184: =IF('Brut ajusté'!P184="","",'Brut ajusté'!P184)

Sheet Rendements
B2: RENDEMENTS MENSUELS - devise de cotation, dividendes réinvestis
B3: Formules : rendement simple d'un mois sur l'autre à partir de l'Historique ajusté ; vide si donnée manquante ou rendement aberrant au sens du seuil paramétré.
B5: Mois | C5: NasdaqGM:IGF | D5: LSE:INFR | E5: LSE:3IN | F5: LSE:HICL | G5: LSE:INPP | H5: LSE:SEQI | I5: LSE:GCP | J5: NYSE:BIP | K5: KOSE:A088980 | L5: ARCA:BKLN | M5: ARCA:HYG | N5: LSE:IHYG | O5: NasdaqGS:ARCC | P5: ARCA:BIZD
B7: ='Historique ajusté'!B7 | C7: =IF(OR('Historique ajusté'!C7="",'Historique ajusté'!C6=""),"",IF(ABS(LN('Historique ajusté'!C7/'Historique ajusté'!C6))>Seuil_aberrant,"",'Historique ajusté'!C7/'Historique ajusté'!C6-1)) | D7: =IF(OR('Historique ajusté'!D7="",'Historique ajusté'!D6=""),"",IF(ABS(LN('Historique ajusté'!D7/'Historique ajusté'!D6))>Seuil_aberrant,"",'Historique ajusté'!D7/'Historique ajusté'!D6-1)) | E7: =IF(OR('Historique ajusté'!E7="",'Historique ajusté'!E6=""),"",IF(ABS(LN('Historique ajusté'!E7/'Historique ajusté'!E6))>Seuil_aberrant,"",'Historique ajusté'!E7/'Historique ajusté'!E6-1)) | F7: =IF(OR('Historique ajusté'!F7="",'Historique ajusté'!F6=""),"",IF(ABS(LN('Historique ajusté'!F7/'Historique ajusté'!F6))>Seuil_aberrant,"",'Historique ajusté'!F7/'Historique ajusté'!F6-1)) | G7: =IF(OR('Historique ajusté'!G7="",'Historique ajusté'!G6=""),"",IF(ABS(LN('Historique ajusté'!G7/'Historique ajusté'!G6))>Seuil_aberrant,"",'Historique ajusté'!G7/'Historique ajusté'!G6-1)) | H7: =IF(OR('Historique ajusté'!H7="",'Historique ajusté'!H6=""),"",IF(ABS(LN('Historique ajusté'!H7/'Historique ajusté'!H6))>Seuil_aberrant,"",'Historique ajusté'!H7/'Historique ajusté'!H6-1)) | I7: =IF(OR('Historique ajusté'!I7="",'Historique ajusté'!I6=""),"",IF(ABS(LN('Historique ajusté'!I7/'Historique ajusté'!I6))>Seuil_aberrant,"",'Historique ajusté'!I7/'Historique ajusté'!I6-1)) | J7: =IF(OR('Historique ajusté'!J7="",'Historique ajusté'!J6=""),"",IF(ABS(LN('Historique ajusté'!J7/'Historique ajusté'!J6))>Seuil_aberrant,"",'Historique ajusté'!J7/'Historique ajusté'!J6-1)) | ... P7: =IF(OR('Historique ajusté'!P7="",'Historique ajusté'!P6=""),"",IF(ABS(LN('Historique ajusté'!P7/'Historique ajusté'!P6))>Seuil_aberrant,"",'Historique ajusté'!P7/'Historique ajusté'!P6-1))
B8: ='Historique ajusté'!B8 | C8: =IF(OR('Historique ajusté'!C8="",'Historique ajusté'!C7=""),"",IF(ABS(LN('Historique ajusté'!C8/'Historique ajusté'!C7))>Seuil_aberrant,"",'Historique ajusté'!C8/'Historique ajusté'!C7-1)) | D8: =IF(OR('Historique ajusté'!D8="",'Historique ajusté'!D7=""),"",IF(ABS(LN('Historique ajusté'!D8/'Historique ajusté'!D7))>Seuil_aberrant,"",'Historique ajusté'!D8/'Historique ajusté'!D7-1)) | E8: =IF(OR('Historique ajusté'!E8="",'Historique ajusté'!E7=""),"",IF(ABS(LN('Historique ajusté'!E8/'Historique ajusté'!E7))>Seuil_aberrant,"",'Historique ajusté'!E8/'Historique ajusté'!E7-1)) | F8: =IF(OR('Historique ajusté'!F8="",'Historique ajusté'!F7=""),"",IF(ABS(LN('Historique ajusté'!F8/'Historique ajusté'!F7))>Seuil_aberrant,"",'Historique ajusté'!F8/'Historique ajusté'!F7-1)) | G8: =IF(OR('Historique ajusté'!G8="",'Historique ajusté'!G7=""),"",IF(ABS(LN('Historique ajusté'!G8/'Historique ajusté'!G7))>Seuil_aberrant,"",'Historique ajusté'!G8/'Historique ajusté'!G7-1)) | H8: =IF(OR('Historique ajusté'!H8="",'Historique ajusté'!H7=""),"",IF(ABS(LN('Historique ajusté'!H8/'Historique ajusté'!H7))>Seuil_aberrant,"",'Historique ajusté'!H8/'Historique ajusté'!H7-1)) | I8: =IF(OR('Historique ajusté'!I8="",'Historique ajusté'!I7=""),"",IF(ABS(LN('Historique ajusté'!I8/'Historique ajusté'!I7))>Seuil_aberrant,"",'Historique ajusté'!I8/'Historique ajusté'!I7-1)) | J8: =IF(OR('Historique ajusté'!J8="",'Historique ajusté'!J7=""),"",IF(ABS(LN('Historique ajusté'!J8/'Historique ajusté'!J7))>Seuil_aberrant,"",'Historique ajusté'!J8/'Historique ajusté'!J7-1)) | ... P8: =IF(OR('Historique ajusté'!P8="",'Historique ajusté'!P7=""),"",IF(ABS(LN('Historique ajusté'!P8/'Historique ajusté'!P7))>Seuil_aberrant,"",'Historique ajusté'!P8/'Historique ajusté'!P7-1))
B9: ='Historique ajusté'!B9 | C9: =IF(OR('Historique ajusté'!C9="",'Historique ajusté'!C8=""),"",IF(ABS(LN('Historique ajusté'!C9/'Historique ajusté'!C8))>Seuil_aberrant,"",'Historique ajusté'!C9/'Historique ajusté'!C8-1)) | D9: =IF(OR('Historique ajusté'!D9="",'Historique ajusté'!D8=""),"",IF(ABS(LN('Historique ajusté'!D9/'Historique ajusté'!D8))>Seuil_aberrant,"",'Historique ajusté'!D9/'Historique ajusté'!D8-1)) | E9: =IF(OR('Historique ajusté'!E9="",'Historique ajusté'!E8=""),"",IF(ABS(LN('Historique ajusté'!E9/'Historique ajusté'!E8))>Seuil_aberrant,"",'Historique ajusté'!E9/'Historique ajusté'!E8-1)) | F9: =IF(OR('Historique ajusté'!F9="",'Historique ajusté'!F8=""),"",IF(ABS(LN('Historique ajusté'!F9/'Historique ajusté'!F8))>Seuil_aberrant,"",'Historique ajusté'!F9/'Historique ajusté'!F8-1)) | G9: =IF(OR('Historique ajusté'!G9="",'Historique ajusté'!G8=""),"",IF(ABS(LN('Historique ajusté'!G9/'Historique ajusté'!G8))>Seuil_aberrant,"",'Historique ajusté'!G9/'Historique ajusté'!G8-1)) | H9: =IF(OR('Historique ajusté'!H9="",'Historique ajusté'!H8=""),"",IF(ABS(LN('Historique ajusté'!H9/'Historique ajusté'!H8))>Seuil_aberrant,"",'Historique ajusté'!H9/'Historique ajusté'!H8-1)) | I9: =IF(OR('Historique ajusté'!I9="",'Historique ajusté'!I8=""),"",IF(ABS(LN('Historique ajusté'!I9/'Historique ajusté'!I8))>Seuil_aberrant,"",'Historique ajusté'!I9/'Historique ajusté'!I8-1)) | J9: =IF(OR('Historique ajusté'!J9="",'Historique ajusté'!J8=""),"",IF(ABS(LN('Historique ajusté'!J9/'Historique ajusté'!J8))>Seuil_aberrant,"",'Historique ajusté'!J9/'Historique ajusté'!J8-1)) | ... P9: =IF(OR('Historique ajusté'!P9="",'Historique ajusté'!P8=""),"",IF(ABS(LN('Historique ajusté'!P9/'Historique ajusté'!P8))>Seuil_aberrant,"",'Historique ajusté'!P9/'Historique ajusté'!P8-1))
B10: ='Historique ajusté'!B10 | C10: =IF(OR('Historique ajusté'!C10="",'Historique ajusté'!C9=""),"",IF(ABS(LN('Historique ajusté'!C10/'Historique ajusté'!C9))>Seuil_aberrant,"",'Historique ajusté'!C10/'Historique ajusté'!C9-1)) | D10: =IF(OR('Historique ajusté'!D10="",'Historique ajusté'!D9=""),"",IF(ABS(LN('Historique ajusté'!D10/'Historique ajusté'!D9))>Seuil_aberrant,"",'Historique ajusté'!D10/'Historique ajusté'!D9-1)) | E10: =IF(OR('Historique ajusté'!E10="",'Historique ajusté'!E9=""),"",IF(ABS(LN('Historique ajusté'!E10/'Historique ajusté'!E9))>Seuil_aberrant,"",'Historique ajusté'!E10/'Historique ajusté'!E9-1)) | F10: =IF(OR('Historique ajusté'!F10="",'Historique ajusté'!F9=""),"",IF(ABS(LN('Historique ajusté'!F10/'Historique ajusté'!F9))>Seuil_aberrant,"",'Historique ajusté'!F10/'Historique ajusté'!F9-1)) | G10: =IF(OR('Historique ajusté'!G10="",'Historique ajusté'!G9=""),"",IF(ABS(LN('Historique ajusté'!G10/'Historique ajusté'!G9))>Seuil_aberrant,"",'Historique ajusté'!G10/'Historique ajusté'!G9-1)) | H10: =IF(OR('Historique ajusté'!H10="",'Historique ajusté'!H9=""),"",IF(ABS(LN('Historique ajusté'!H10/'Historique ajusté'!H9))>Seuil_aberrant,"",'Historique ajusté'!H10/'Historique ajusté'!H9-1)) | I10: =IF(OR('Historique ajusté'!I10="",'Historique ajusté'!I9=""),"",IF(ABS(LN('Historique ajusté'!I10/'Historique ajusté'!I9))>Seuil_aberrant,"",'Historique ajusté'!I10/'Historique ajusté'!I9-1)) | J10: =IF(OR('Historique ajusté'!J10="",'Historique ajusté'!J9=""),"",IF(ABS(LN('Historique ajusté'!J10/'Historique ajusté'!J9))>Seuil_aberrant,"",'Historique ajusté'!J10/'Historique ajusté'!J9-1)) | ... P10: =IF(OR('Historique ajusté'!P10="",'Historique ajusté'!P9=""),"",IF(ABS(LN('Historique ajusté'!P10/'Historique ajusté'!P9))>Seuil_aberrant,"",'Historique ajusté'!P10/'Historique ajusté'!P9-1))
