Workbook

Sheet Tableau de bord
B2: TABLEAU DE BORD LST ET MST - OPENSTONE INFRAWORLD, COMPARTIMENT I
B3: ="Projection à partir de la fin du blocage ("&DAY(Date_depart)&"/"&RIGHT("0"&MONTH(Date_depart),2)&"/"&YEAR(Date_depart)&"), huit dates de rachat semestrielles, actif net de départ "&ROUND(AN_depart/1000000,0)&" M€. Phase : "&Phase&". Les cellules sont des formules vers les onglets de calcul." -> Projection à partir de la fin du blocage (31/12/2028), huit dates de rachat semestrielles, actif net de départ 8 M€. Phase : Montée en charge. Les cellules sont des formules vers les onglets de calcul.
B5: A. INDICATEURS DE TÊTE
B6: Indicateur | C6: Valeur | G6: Lecture
B7: Taille de lancement retenue (sélecteur de l'onglet Paramètres) | C7: =AN_depart -> 8000000 | G7: Comparatif des cinq tailles dans l'onglet dédié
B8: Écart actif - passif en régime normal (jours) | C8: =Ecart_TTL_N -> -28.93 | G8: WATTL actif moins LTTL moyen ; porté par la poche liquide et le plafonnement
B9: Écart actif - passif en S3 (jours) | C9: =Ecart_TTL_S3 -> 206.7 | G9: Justification structurelle du gate de 5 %
B10: Actifs liquides à 30 jours, normal / S3 | C10: =HQLA_N -> 0.16 | D10: =HQLA_S3 -> 0.1567 | G10: Trésorerie et fonds HY après haircut
B11: Capacité maximale de sortie sur douze mois (2 × gate) | C11: =2*Gate -> 0.1 | G11: Prospectus art. 7.2.6
B12: Part du premier porteur et dates de gate consommées | C12: =Top1 -> 0.15 | D12: =Top1_dates -> 3 | G12: Choc porteur 1
B13: Point de rupture avec plafonnement (taux par date) | C13: =Rupture_gated -> 0.05 | D13: =Rupture_suspension -> 0.075 | G13: Premier taux imposant des cessions décotées malgré le gate ; suspension dès le premier taux supérieur au gate
B14: Point de rupture sans plafonnement (taux par date) | C14: =Rupture_ungated -> 0.05 | D14: =Rupture_impossible -> 0.075 | G14: Premier taux imposant des cessions décotées ; cession impossible au-delà de la valeur en colonne D
B15: Point de rupture des appels de fonds (non-appelé, % AN) | C15: =Rupture_appels -> 0.125 | G15: Non-appelé au-delà duquel une cession s'impose en douze mois
B16: Cessions à la date 8 pour 10 % de rachats par date : avec puis sans plafonnement | C16: =Cession_gate_10 -> 0.027968824 | D16: =Cession_nogate_10 -> 0.59223059 | G16: Valeur du plafonnement : la file remplace la vente forcée
B17: Première date de triple gel en S3 | C17: =LST_S3_gel -> 47118 | G17: Collecte, distributions et capacité evergreen gelées ensemble
B19: B. VERDICTS PAR SCÉNARIO
B20: Scénario | C20: MST (creux de VL) | D20: LST (file à la date 8) | E20: Suspension | F20: Verdict conjoint | G20: Lecture
B21: S1 Base | C21: =MST_S1_creux -> 0.044637287 | D21: =LST_S1_file8 -> 0 | E21: =LST_S1_susp -> - | F21: =Joint_S1 -> Vert | G21: Rachats courants, collecte normale, marchés stables
B22: S2 Plausible | C22: =MST_S2_creux -> -0.014988138 | D22: =LST_S2_file8 -> 0 | E22: =LST_S2_susp -> - | F22: =Joint_S2 -> Rouge | G22: Correction de marché à 1,5 écart-type, rachats de 7,5 % sur deux dates, collecte divisée par deux
B23: S3 Sévère | C23: =MST_S3_creux -> -0.087196361 | D23: =LST_S3_file8 -> 0.4666904 | E23: =LST_S3_susp -> 47848 | F23: =Joint_S3 -> Rouge | G23: Réplique 2008 : pire semestre historique des proxies, rachats de 15 % sur deux dates, collecte nulle, sortie du premier porteur
B24: S4 Extrême | C24: =MST_S4_creux -> -0.17282085 | D24: =LST_S4_file8 -> 0.92475927 | E24: =LST_S4_susp -> 47848 | F24: =Joint_S4 -> Rouge | G24: Queue de distribution à 3,5 écarts-types, rachats de 25 % puis 20 %, gel des distributions, pairs saturant les fonds evergreen
B26: C. ACTIONS RECOMMANDÉES déduites des seuils de l'onglet Intégré
B27: =IF(Phase="Montée en charge","Phase de montée en charge : le risque dominant est la concentration des porteurs, pas la cascade de plafonnement ; LST mensuel jusqu'à la troisième année.","Régime de croisière : LST trimestriel avant chaque date de centralisation.") -> Phase de montée en charge : le risque dominant est la concentration des porteurs, pas la cascade de plafonnement ; LST mensuel jusqu'à la troisième année.
B28: =IF(Top1>0.1,"Premier porteur au-dessus de 10 % : convenir d'un protocole de préavis renforcé et simuler sa sortie avant chaque date.","Concentration des porteurs sous contrôle.") -> Premier porteur au-dessus de 10 % : convenir d'un protocole de préavis renforcé et simuler sa sortie avant chaque date.
B29: =IF(LST_S3_file8>0.3,"S3 : file résiduelle au-dessus de 30 % à la date 8 ; préparer la suspension et l'information de l'AMF.",IF(LST_S3_file8>0.15,"S3 : file résiduelle élevée ; pré-positionner la Prolongation du Délai de Préavis (art. 7.2.7) et la communication aux distributeurs.","S3 : file résorbable sous les outils du prospectus.")) -> S3 : file résiduelle au-dessus de 30 % à la date 8 ; préparer la suspension et l'information de l'AMF.
B30: =IF(LST_S2_poche<S_poche_orange,"S2 : poche liquide sous 15 % ; relever la trésorerie cible ou ralentir les engagements fermés.","S2 : poche liquide conforme à l'article 3.") -> S2 : poche liquide sous 15 % ; relever la trésorerie cible ou ralentir les engagements fermés.
B31: =IF(-MST_S3_creux>S_mst_rouge,"MST S3 : creux de VL au-delà de 25 % ; revoir la transmission des chocs et l'exposition dollar non couverte (51 %).","MST S3 : creux de VL contenu ; surveiller le dollar (aucune couverture possible, art. 22).") -> MST S3 : creux de VL contenu ; surveiller le dollar (aucune couverture possible, art. 22).
B32: =IF(Rupture_appels<=NA_total/AN_depart+0.0001,"Appels : le non-appelé de départ dépasse le point de rupture ; séquencer les engagements fermés.","Appels : le non-appelé de départ reste sous le point de rupture ("&ROUND(Rupture_appels*100,0)&" % de l'AN).") -> Appels : le non-appelé de départ dépasse le point de rupture ; séquencer les engagements fermés.
B33: ="Reporting : les profils ALP et LLP alimentent les questions 178 et 186 de l'Annex IV ; la concentration la question 118." -> Reporting : les profils ALP et LLP alimentent les questions 178 et 186 de l'Annex IV ; la concentration la question 118.
B35: D. HYPOTHÈSES CLÉS À VALIDER EN COMITÉ
B36: Taux de rachat par scénario et collecte (Paramètres G) : aucun historique, hypothèses de la Fonction Risques.
B37: Transmission des chocs cotés aux VL privées : 0,5 par défaut, cohérente avec le rapport VEV privée / VEV cotée du DIC (MST Données).
B38: Pression des pairs sur les gates de PG NGI et d'Ares AGI : 1 en S3 et S4 aux deux premières dates (aucun rachat récupérable).
B39: Décotes de cession secondaire : 15 % (S2), 25 % (S3), 35 % (S4) sur les fonds fermés ; 1 à 5 % sur le fonds HY.
B40: Registre des porteurs hypothétique : à remplacer avant la première VL.

Sheet Paramètres
B2: PARAMÈTRES - ANCRES DU PROSPECTUS, ALLOCATION, HYPOTHÈSES ET CALIBRATION
B3: Source unique de tous les calculs. Cellules cyan : saisies modifiables. Les autres onglets ne contiennent que des formules. Les ancres citent l'article du prospectus du 30/09/2026 (colonne Source).
B5: A. IDENTIFICATION ET DATES
B6: Paramètre | C6: Valeur | D6: Unité | E6: Source | L6: Commentaire
B7: Fonds | C7: Openstone Infraworld, Compartiment I | D7: - | E7: Prospectus, p. 1
B8: Société de Gestion | C8: Fundcraft France SAS, GP-20260008 | D8: - | E8: Prospectus, p. 1
B9: Structure | C9: Fonds de fonds evergreen investissant en direct dans deux fonds fermés, deux fonds evergreen, un fonds obligataire HY quotidien et de la trésorerie | D9: - | E9: Prospectus art. 3
B10: Date d'arrêté | C10: 46301 | D10: date | E10: -
B11: Date de première VL (lancement) | C11: 46387 | D11: date | E11: Hypothèse : constitution au T4 2026 | L11: Pilote la fin du blocage et la phase du Fonds.
B12: Fin de la Période de Blocage = première date de rachat | C12: =EDATE(Date_lancement,Blocage_mois) -> 47118 | D12: date | E12: Prospectus art. 7.2.2 : deux ans à compter de la souscription
B13: Actif net au départ de la projection | C13: =INDEX(Tailles_AN,Taille_sel) -> 8000000 | D13: EUR | E13: Taille retenue dans le bloc C
B14: Phase du Fonds | C14: =IF(YEARFRAC(Date_lancement,Date_depart)<3,"Montée en charge","Régime de croisière") -> Montée en charge | D14: - | E14: Dérivé | L14: En montée en charge, la concentration des porteurs domine le risque de plafonnement.
B15: Années depuis le lancement à la date de départ | C15: =YEARFRAC(Date_lancement,Date_depart) -> 2 | D15: ans | E15: Dérivé
B17: B. ANCRES DU PROSPECTUS (aucune valeur de passif codée ailleurs)
B18: Ancre | C18: Valeur | D18: Unité | E18: Source | L18: Commentaire
B19: Fréquence de la VL | C19: Mensuelle | D19: - | E19: Prospectus art. 6 : dernier jour calendaire de chaque mois
B20: Fréquence des souscriptions | C20: Mensuelle, centralisation 25 JO avant la VL | D20: - | E20: Prospectus art. 7.1.2
B21: Fréquence des rachats | C21: Semestrielle : VL du 30/06 et du 31/12 | D21: - | E21: Prospectus art. 7.2.1
B22: Dates de rachat par an | C22: 2 | D22: dates | E22: Prospectus art. 7.2.1
B23: Préavis : centralisation le 31/03 ou le 30/09 | C23: 91 | D23: jours cal. | E23: Prospectus art. 7.2.3 | L23: Jours entre la Date de Centralisation et la VL de rachat.
B24: Publication de la VL après la date de VL | C24: 30 | D24: JO | E24: Prospectus art. 6 et 7.1.5
B25: Règlement après publication de la VL | C25: 5 | D25: JO | E25: Prospectus art. 7.2.4 : cinq Jours Ouvrés au plus
B26: Délai VL à cash (publication + règlement) | C26: =ROUND((Publication_JO+Reglement_JO)*7/5,0) -> 49 | D26: jours cal. | E26: Dérivé
B27: Plafond de Rachats (gate) par date | C27: 0.05 | D27: % AN | E27: Prospectus art. 7.2.6 : 5 % de l'Actif Net à la VL de rachat | L27: Assiette : demandes centralisées nettes des souscriptions versées.
B28: Base du plafond | C28: AN à la VL du 30/06 ou du 31/12, demandes nettes des souscriptions | D28: - | E28: Prospectus art. 7.2.6
B29: Reports successifs avant examen d'une suspension | C29: 4 | D29: dates | E29: Prospectus art. 7.2.6 ; note de liquidité § 5 | L29: Les demandes reportées perdent la priorité ; Demandes Prioritaires après deux reports.
B30: Période de Blocage | C30: 24 | D30: mois | E30: Prospectus art. 7.2.2
B31: Déduction de sortie anticipée | C31: 0 | D31: % | E31: DIC du 29/09/2026 : aucune commission de rachat
B32: Prolongation du Délai de Préavis : préavis maximal | C32: 180 | D32: jours cal. | E32: Prospectus art. 7.2.7
B33: Prolongation du Délai de Préavis : durée maximale | C33: 12 | D33: mois | E33: Prospectus art. 7.2.7
B34: Suspension des Rachats | C34: Oui, circonstances exceptionnelles, sans plafonnement préalable | D34: - | E34: Prospectus art. 7.2.8
B35: Actifs liquides minimum | C35: 0.15 | D35: % AN | E35: Prospectus art. 3 et DIC : 15 % au moins en actifs liquides
B36: Sur-engagement maximal | C36: 1.3 | D36: % AN | E36: Prospectus art. 23
B37: Emprunts et instruments dérivés | C37: Interdits | D37: - | E37: Prospectus art. 22 ; aucune couverture de change possible
B38: Entreprises Cibles (co-investissements) au plus | C38: 0.3 | D38: % AN | E38: Prospectus art. 3
B40: C. TAILLE DU FONDS AU LANCEMENT ET ALLOCATION EN EUROS
B41: Le Fonds n'est pas lancé sous 8 M€. Les fonds Macquarie exigent 10 M$ d'engagement, dérogation écrite possible à 4 M. Règle d'allocation : trésorerie 5 %, fonds HY 10 %, fonds fermés selon les engagements négociés, solde réparti à parts égales entre PG NGI et Ares AGI. Les engagements fermés sont appelés progressivement : la part appelée à la fin du blocage est un paramètre.
B42: Taille de lancement (M€) | C42: 8 M€ | D42: 15 M€ | E42: 20 M€ | F42: 25 M€ | G42: 50 M€ | H42: Unité | L42: Commentaire
B43: Taille retenue pour les onglets de calcul (1 = 8 M€ … 5 = 50 M€) | C43: 1 | H43: 1-5 | L43: Sélecteur : toute la projection se recalcule
B44: Actif net au lancement | C44: 8000000 | D44: 15000000 | E44: 20000000 | F44: 25000000 | G44: 50000000 | H44: EUR | L44: Hypothèse de collecte
...

Sheet Comparatif tailles
B2: COMPARATIF DES TAILLES DE LANCEMENT : 8, 15, 20, 25 ET 50 M€
B3: Bloc A : allocation en formules (onglet Paramètres C). Bloc B : résultats du moteur pour chaque taille, obtenus par recalcul complet du classeur taille par taille (script tools/lst_mst_infraworld), valeurs figées à la date indiquée ; le sélecteur de l'onglet Paramètres permet de rejouer une taille en direct.
B5: A. ALLOCATION PAR TAILLE (formules)
B6: Ligne | C6: 8 M€ | D6: 15 M€ | E6: 20 M€ | F6: 25 M€ | G6: 50 M€ | H6: Lecture
B7: Actif net au lancement | C7: =Paramètres!C44 -> 8000000 | D7: =Paramètres!D44 -> 15000000 | E7: =Paramètres!E44 -> 20000000 | F7: =Paramètres!F44 -> 25000000 | G7: =Paramètres!G44 -> 50000000
B8: Engagement MAPIF II | C8: =Paramètres!C45 -> 4000000 | D8: =Paramètres!D45 -> 4000000 | E8: =Paramètres!E45 -> 5000000 | F8: =Paramètres!F45 -> 5000000 | G8: =Paramètres!G45 -> 17000000 | H8: 4 M sous dérogation jusqu'à 15 M€ ; 5 M à 20 et 25 M€
B9: Engagement MSIG 3 | C9: =Paramètres!C46 -> 0 | D9: =Paramètres!D46 -> 0 | E9: =Paramètres!E46 -> 5000000 | F9: =Paramètres!F46 -> 5000000 | G9: =Paramètres!G46 -> 8500000 | H9: Aucun sous 20 M€
B10: MAPIF II appelé à la fin du blocage | C10: =Paramètres!C48 -> 2800000 | D10: =Paramètres!D48 -> 2800000 | E10: =Paramètres!E48 -> 3500000 | F10: =Paramètres!F48 -> 3500000 | G10: =Paramètres!G48 -> 11900000
B11: MSIG 3 appelé à la fin du blocage | C11: =Paramètres!C49 -> 0 | D11: =Paramètres!D49 -> 0 | E11: =Paramètres!E49 -> 3500000 | F11: =Paramètres!F49 -> 3500000 | G11: =Paramètres!G49 -> 5950000
B12: Non-appelé | C12: =Paramètres!C50 -> 1200000 | D12: =Paramètres!D50 -> 1200000 | E12: =Paramètres!E50 -> 3000000 | F12: =Paramètres!F50 -> 3000000 | G12: =Paramètres!G50 -> 7650000
B13: Trésorerie | C13: =Paramètres!C51 -> 400000 | D13: =Paramètres!D51 -> 750000 | E13: =Paramètres!E51 -> 1000000 | F13: =Paramètres!F51 -> 1250000 | G13: =Paramètres!G51 -> 2500000 | H13: 5 % de l'actif net
B14: Fonds HY UCITS | C14: =Paramètres!C52 -> 880000 | D14: =Paramètres!D52 -> 1650000 | E14: =Paramètres!E52 -> 2200000 | F14: =Paramètres!F52 -> 2750000 | G14: =Paramètres!G52 -> 5500000 | H14: 10 % de l'actif net
B15: PG NGI | C15: =Paramètres!C54 -> 1960000 | D15: =Paramètres!D54 -> 4900000 | E15: =Paramètres!E54 -> 4900000 | F15: =Paramètres!F54 -> 7000000 | G15: =Paramètres!G54 -> 12075000 | H15: Moitié du solde
B16: Ares AGI | C16: =Paramètres!C55 -> 1960000 | D16: =Paramètres!D55 -> 4900000 | E16: =Paramètres!E55 -> 4900000 | F16: =Paramètres!F55 -> 7000000 | G16: =Paramètres!G55 -> 12075000 | H16: Moitié du solde
B17: Poids en % de l'actif net | C17: 8 M€ | D17: 15 M€ | E17: 20 M€ | F17: 25 M€ | G17: 50 M€
B18: MAPIF II (appelé) | C18: =Paramètres!C48/Paramètres!C44 -> 0.35 | D18: =Paramètres!D48/Paramètres!D44 -> 0.18666667 | E18: =Paramètres!E48/Paramètres!E44 -> 0.175 | F18: =Paramètres!F48/Paramètres!F44 -> 0.14 | G18: =Paramètres!G48/Paramètres!G44 -> 0.238
B19: MSIG 3 (appelé) | C19: =Paramètres!C49/Paramètres!C44 -> 0 | D19: =Paramètres!D49/Paramètres!D44 -> 0 | E19: =Paramètres!E49/Paramètres!E44 -> 0.175 | F19: =Paramètres!F49/Paramètres!F44 -> 0.14 | G19: =Paramètres!G49/Paramètres!G44 -> 0.119
B20: PG NGI | C20: =Paramètres!C54/Paramètres!C44 -> 0.245 | D20: =Paramètres!D54/Paramètres!D44 -> 0.32666667 | E20: =Paramètres!E54/Paramètres!E44 -> 0.245 | F20: =Paramètres!F54/Paramètres!F44 -> 0.28 | G20: =Paramètres!G54/Paramètres!G44 -> 0.2415
B21: Ares AGI | C21: =Paramètres!C55/Paramètres!C44 -> 0.245 | D21: =Paramètres!D55/Paramètres!D44 -> 0.32666667 | E21: =Paramètres!E55/Paramètres!E44 -> 0.245 | F21: =Paramètres!F55/Paramètres!F44 -> 0.28 | G21: =Paramètres!G55/Paramètres!G44 -> 0.2415
B22: Fonds HY UCITS | C22: =Paramètres!C52/Paramètres!C44 -> 0.11 | D22: =Paramètres!D52/Paramètres!D44 -> 0.11 | E22: =Paramètres!E52/Paramètres!E44 -> 0.11 | F22: =Paramètres!F52/Paramètres!F44 -> 0.11 | G22: =Paramètres!G52/Paramètres!G44 -> 0.11
B23: Trésorerie | C23: =Paramètres!C51/Paramètres!C44 -> 0.05 | D23: =Paramètres!D51/Paramètres!D44 -> 0.05 | E23: =Paramètres!E51/Paramètres!E44 -> 0.05 | F23: =Paramètres!F51/Paramètres!F44 -> 0.05 | G23: =Paramètres!G51/Paramètres!G44 -> 0.05
B24: Non-appelé | C24: =Paramètres!C50/Paramètres!C44 -> 0.15 | D24: =Paramètres!D50/Paramètres!D44 -> 0.08 | E24: =Paramètres!E50/Paramètres!E44 -> 0.15 | F24: =Paramètres!F50/Paramètres!F44 -> 0.12 | G24: =Paramètres!G50/Paramètres!G44 -> 0.153
B25: Engagement MAPIF II en % de l'actif net | C25: =Paramètres!C45/Paramètres!C44 -> 0.5 | D25: =Paramètres!D45/Paramètres!D44 -> 0.26666667 | E25: =Paramètres!E45/Paramètres!E44 -> 0.25 | F25: =Paramètres!F45/Paramètres!F44 -> 0.2 | G25: =Paramètres!G45/Paramètres!G44 -> 0.34 | H25: Concentration : 50 % à 8 M€
B26: Sur-engagement | C26: =(Paramètres!C44+Paramètres!C50)/Paramètres!C44 -> 1.15 | D26: =(Paramètres!D44+Paramètres!D50)/Paramètres!D44 -> 1.08 | E26: =(Paramètres!E44+Paramètres!E50)/Paramètres!E44 -> 1.15 | F26: =(Paramètres!F44+Paramètres!F50)/Paramètres!F44 -> 1.12 | G26: =(Paramètres!G44+Paramètres!G50)/Paramètres!G44 -> 1.153 | H26: Plafond 130 %
B27: Frais totaux (part A1) | C27: =Frais_var+MAX(Fee_SGP,SGP_min/Paramètres!C44)-Fee_SGP+Frais_fixes/Paramètres!C44 -> 0.032599 | D27: =Frais_var+MAX(Fee_SGP,SGP_min/Paramètres!D44)-Fee_SGP+Frais_fixes/Paramètres!D44 -> 0.025879467 | E27: =Frais_var+MAX(Fee_SGP,SGP_min/Paramètres!E44)-Fee_SGP+Frais_fixes/Paramètres!E44 -> 0.0239596 | F27: =Frais_var+MAX(Fee_SGP,SGP_min/Paramètres!F44)-Fee_SGP+Frais_fixes/Paramètres!F44 -> 0.02280768 | G27: =Frais_var+MAX(Fee_SGP,SGP_min/Paramètres!G44)-Fee_SGP+Frais_fixes/Paramètres!G44 -> 0.02110384 | H27: Frais fixes rapportés à l'encours
B29: B. RÉSULTATS DU MOTEUR PAR TAILLE (valeurs figées) recalcul du 06/10/2026
B30: S1 Base | C30: 8 M€ | D30: 15 M€ | E30: 20 M€ | F30: 25 M€ | G30: 50 M€ | H30: Lecture
B31: Creux de VL (MST) | C31: 0.044637287 | D31: 0.042085543 | E31: 0.040916919 | F31: 0.040567388 | G31: 0.042216797
B32: Dates plafonnées ou suspendues | C32: 0 | D32: 0 | E32: 0 | F32: 0 | G32: 0
B33: File résiduelle à la date 8 (% AN) | C33: 0 | D33: 0 | E33: 0 | F33: 0 | G33: 0
B34: Première suspension | C34: - | D34: - | E34: - | F34: - | G34: -
B35: Poche liquide minimale (% AN) | C35: 0.15469325 | D35: 0.15455742 | E35: 0.15439528 | F35: 0.15439616 | G35: 0.15409055
B36: Couverture à douze mois minimale | C36: 1.9163833 | D36: 2.2431677 | E36: 1.9311284 | F36: 2.0682252 | G36: 1.9073194
B37: Cessions secondaires cumulées (EUR) | C37: 0 | D37: 0 | E37: 0 | F37: 0 | G37: 0
B38: Décotes réalisées (EUR) | C38: 0 | D38: 0 | E38: 0 | F38: 0 | G38: 0
B39: Actif net à la date 8 / départ | C39: 1.3881741 | D39: 1.4063944 | E39: 1.4202084 | F39: 1.4216804 | G39: 1.4601912
B40: Verdict conjoint | C40: Vert | D40: Vert | E40: Vert | F40: Vert | G40: Vert
B42: S2 Plausible | C42: 8 M€ | D42: 15 M€ | E42: 20 M€ | F42: 25 M€ | G42: 50 M€ | H42: Lecture
B43: Creux de VL (MST) | C43: -0.014988138 | D43: -0.0038600377 | E43: -0.013024242 | F43: -0.0086478355 | G43: -0.014129608
B44: Dates plafonnées ou suspendues | C44: 0 | D44: 0 | E44: 0 | F44: 0 | G44: 0
...

Sheet ALP
B2: ALP - PROFIL DE LIQUIDITÉ DE L'ACTIF (look-through, date de départ)
B3: Valeur de chaque ligne à la fin du blocage, délai de conversion en cash (TTL) par scénario et classement par tranche Annex IV. Les fonds evergreen ne sont pas liquides à 90 jours : préavis, gate trimestriel de 5 % et pression des pairs portent le délai de récupération complète au-delà de 180 jours. Le non-appelé des fonds fermés est une sortie, pas une ressource.
B5: A. VALEURS ET DÉLAIS DE CONVERSION
B6: Ligne | C6: Valeur (EUR) | D6: % AN | E6: TTL normal | F6: TTL S2 | G6: TTL S3 | H6: TTL S4 | I6: Non-appelé (EUR) | J6: Capacité de rachat par semestre, normal (EUR) | K6: Haircut S2 | L6: Haircut S3 | M6: Haircut S4
B7: MAPIF II | C7: =Paramètres!$D$68*AN_depart -> 2800000 | D7: =C7/AN_depart -> 0.35 | E7: =Paramètres!$H$68 -> 365 | F7: =Paramètres!$I$68 -> 540 | G7: =Paramètres!$J$68 -> 730 | H7: =Paramètres!$K$68 -> 1095 | I7: =C7*Paramètres!$E$68 -> 1200000 | J7: =0 -> 0 | K7: =Paramètres!$J$79 -> 0.15 | L7: =Paramètres!$K$79 -> 0.25 | M7: =Paramètres!$L$79 -> 0.35
B8: MSIG 3 | C8: =Paramètres!$D$69*AN_depart -> 0 | D8: =C8/AN_depart -> 0 | E8: =Paramètres!$H$69 -> 365 | F8: =Paramètres!$I$69 -> 540 | G8: =Paramètres!$J$69 -> 730 | H8: =Paramètres!$K$69 -> 1095 | I8: =C8*Paramètres!$E$69 -> 0 | J8: =0 -> 0 | K8: =Paramètres!$J$80 -> 0.15 | L8: =Paramètres!$K$80 -> 0.25 | M8: =Paramètres!$L$80 -> 0.35
B9: PG NGI | C9: =Paramètres!$D$70*AN_depart -> 1960000 | D9: =C9/AN_depart -> 0.245 | E9: =Paramètres!$H$70 -> 180 | F9: =Paramètres!$I$70 -> 270 | G9: =Paramètres!$J$70 -> 365 | H9: =Paramètres!$K$70 -> 540 | I9: =C9*Paramètres!$E$70 -> 0 | J9: =C9*Paramètres!$F$70*2*(1-Paramètres!$C$148) -> 137200 | K9: =Paramètres!$J$81 -> 0.05 | L9: =Paramètres!$K$81 -> 0.15 | M9: =Paramètres!$L$81 -> 0.25
B10: Ares AGI | C10: =Paramètres!$D$71*AN_depart -> 1960000 | D10: =C10/AN_depart -> 0.245 | E10: =Paramètres!$H$71 -> 120 | F10: =Paramètres!$I$71 -> 180 | G10: =Paramètres!$J$71 -> 365 | H10: =Paramètres!$K$71 -> 540 | I10: =C10*Paramètres!$E$71 -> 0 | J10: =C10*Paramètres!$F$71*2*(1-Paramètres!$C$148) -> 137200 | K10: =Paramètres!$J$82 -> 0.05 | L10: =Paramètres!$K$82 -> 0.15 | M10: =Paramètres!$L$82 -> 0.25
B11: Fonds HY UCITS | C11: =Paramètres!$D$72*AN_depart -> 880000 | D11: =C11/AN_depart -> 0.11 | E11: =Paramètres!$H$72 -> 7 | F11: =Paramètres!$I$72 -> 14 | G11: =Paramètres!$J$72 -> 30 | H11: =Paramètres!$K$72 -> 30 | I11: =C11*Paramètres!$E$72 -> 0 | J11: =C11 -> 880000 | K11: =Paramètres!$J$83 -> 0.01 | L11: =Paramètres!$K$83 -> 0.03 | M11: =Paramètres!$L$83 -> 0.05
B12: Trésorerie | C12: =Paramètres!$D$73*AN_depart -> 400000 | D12: =C12/AN_depart -> 0.05 | E12: =Paramètres!$H$73 -> 1 | F12: =Paramètres!$I$73 -> 1 | G12: =Paramètres!$J$73 -> 1 | H12: =Paramètres!$K$73 -> 1 | I12: =C12*Paramètres!$E$73 -> 0 | J12: =C12 -> 400000 | K12: =Paramètres!$J$84 -> 0 | L12: =Paramètres!$K$84 -> 0 | M12: =Paramètres!$L$84 -> 0
B13: Total | C13: =SUM(C7:C12) -> 8000000 | D13: =SUM(D7:D12) -> 1 | I13: =SUM(I7:I12) -> 1200000 | J13: =SUM(J7:J12) -> 1554400
B14: Sur-engagement au départ (AN + non-appelé) / AN | C14: =(C13+I13)/C13 -> 1.15 | J14: =IF((C13+I13)/C13>Surengagement_max,"Rouge : plafond de l'art. 23 dépassé","Vert : sous le plafond de l'art. 23") -> Vert : sous le plafond de l'art. 23
B16: B. DÉLAI MOYEN PONDÉRÉ DE CONVERSION (WATTL) ET T90
B17: WATTL = Σ valeur × TTL / actif net. T90 = TTL de la ligne où le cumul des valeurs triées par TTL atteint 90 % de l'actif net.
B18: Mesure | C18: Normal | D18: S2 | E18: S3 | F18: S4
B19: WATTL (jours) | C19: =SUMPRODUCT(C7:C12,E7:E12)/C13 -> 202.07 | D19: =SUMPRODUCT(C7:C12,F7:F12)/C13 -> 300.84 | E19: =SUMPRODUCT(C7:C12,G7:G12)/C13 -> 437.7 | F19: =SUMPRODUCT(C7:C12,H7:H12)/C13 -> 651.2
B20: T90 (jours pour liquider 90 % de l'actif) | C20: {=MIN(IF(SUMIF(E7:E12,"<="&E7:E12,C7:C12)>=0.9*C13,E7:E12,100000))} -> 365 | D20: {=MIN(IF(SUMIF(F7:F12,"<="&F7:F12,C7:C12)>=0.9*C13,F7:F12,100000))} -> 540 | E20: {=MIN(IF(SUMIF(G7:G12,"<="&G7:G12,C7:C12)>=0.9*C13,G7:G12,100000))} -> 730 | F20: {=MIN(IF(SUMIF(H7:H12,"<="&H7:H12,C7:C12)>=0.9*C13,H7:H12,100000))} -> 1095
B21: Actifs liquides à 30 jours (HQLA), % AN | C21: =SUMIF(E7:E12,"<=30",C7:C12)/C13 -> 0.16 | D21: =SUMIF(F7:F12,"<=30",C7:C12)/C13 -> 0.16 | E21: =SUMIF(G7:G12,"<=30",C7:C12)/C13 -> 0.16 | F21: =SUMIF(H7:H12,"<=30",C7:C12)/C13 -> 0.16
B22: HQLA après haircut, % AN | C22: =SUMIF(E7:E12,"<=30",C7:C12)/C13 -> 0.16 | D22: =SUMPRODUCT((F7:F12<=30)*C7:C12*(1-K7:K12))/C13 -> 0.1589 | E22: =SUMPRODUCT((G7:G12<=30)*C7:C12*(1-L7:L12))/C13 -> 0.1567 | F22: =SUMPRODUCT((H7:H12<=30)*C7:C12*(1-M7:M12))/C13 -> 0.1545
B23: Capacité de rachat des fonds evergreen sur douze mois, % AN | C23: =Cap_normal*2/AN_depart -> 0.3886 | D23: =Cap_normal*2*(1-Paramètres!$C$149)/(1-Paramètres!$C$148)/AN_depart -> 0.27757143 | E23: =Cap_normal*2*(1-Paramètres!$C$150)/(1-Paramètres!$C$148)/AN_depart -> 0 | F23: =Cap_normal*2*(1-Paramètres!$C$151)/(1-Paramètres!$C$148)/AN_depart -> 0
B25: C. PROFIL ANNEX IV, CÔTÉ ACTIF % de l'actif net liquidable par tranche (AIFMD Annex IV, section 2, question 178)
B26: Tranche | C26: Normal | D26: S2 | E26: S3 | F26: S4 | G26: Champ Annex IV
B27: 1 jour | C27: =SUMPRODUCT((E7:E12>0)*(E7:E12<=1)*C7:C12)/C13 -> 0.05 | D27: =SUMPRODUCT((F7:F12>0)*(F7:F12<=1)*C7:C12)/C13 -> 0.05 | E27: =SUMPRODUCT((G7:G12>0)*(G7:G12<=1)*C7:C12)/C13 -> 0.05 | F27: =SUMPRODUCT((H7:H12>0)*(H7:H12<=1)*C7:C12)/C13 -> 0.05 | G27: 1 day
B28: 2 à 7 jours | C28: =SUMPRODUCT((E7:E12>1)*(E7:E12<=7)*C7:C12)/C13 -> 0.11 | D28: =SUMPRODUCT((F7:F12>1)*(F7:F12<=7)*C7:C12)/C13 -> 0 | E28: =SUMPRODUCT((G7:G12>1)*(G7:G12<=7)*C7:C12)/C13 -> 0 | F28: =SUMPRODUCT((H7:H12>1)*(H7:H12<=7)*C7:C12)/C13 -> 0 | G28: 2-7 days
B29: 8 à 30 jours | C29: =SUMPRODUCT((E7:E12>7)*(E7:E12<=30)*C7:C12)/C13 -> 0 | D29: =SUMPRODUCT((F7:F12>7)*(F7:F12<=30)*C7:C12)/C13 -> 0.11 | E29: =SUMPRODUCT((G7:G12>7)*(G7:G12<=30)*C7:C12)/C13 -> 0.11 | F29: =SUMPRODUCT((H7:H12>7)*(H7:H12<=30)*C7:C12)/C13 -> 0.11 | G29: 8-30 days
B30: 31 à 90 jours | C30: =SUMPRODUCT((E7:E12>30)*(E7:E12<=90)*C7:C12)/C13 -> 0 | D30: =SUMPRODUCT((F7:F12>30)*(F7:F12<=90)*C7:C12)/C13 -> 0 | E30: =SUMPRODUCT((G7:G12>30)*(G7:G12<=90)*C7:C12)/C13 -> 0 | F30: =SUMPRODUCT((H7:H12>30)*(H7:H12<=90)*C7:C12)/C13 -> 0 | G30: 31-90 days
B31: 91 à 180 jours | C31: =SUMPRODUCT((E7:E12>90)*(E7:E12<=180)*C7:C12)/C13 -> 0.49 | D31: =SUMPRODUCT((F7:F12>90)*(F7:F12<=180)*C7:C12)/C13 -> 0.245 | E31: =SUMPRODUCT((G7:G12>90)*(G7:G12<=180)*C7:C12)/C13 -> 0 | F31: =SUMPRODUCT((H7:H12>90)*(H7:H12<=180)*C7:C12)/C13 -> 0 | G31: 91-180 days
B32: 181 à 365 jours | C32: =SUMPRODUCT((E7:E12>180)*(E7:E12<=365)*C7:C12)/C13 -> 0.35 | D32: =SUMPRODUCT((F7:F12>180)*(F7:F12<=365)*C7:C12)/C13 -> 0.245 | E32: =SUMPRODUCT((G7:G12>180)*(G7:G12<=365)*C7:C12)/C13 -> 0.49 | F32: =SUMPRODUCT((H7:H12>180)*(H7:H12<=365)*C7:C12)/C13 -> 0 | G32: 181-365 days
B33: Plus de 365 jours | C33: =SUMPRODUCT((E7:E12>365)*(E7:E12<=100000)*C7:C12)/C13 -> 0 | D33: =SUMPRODUCT((F7:F12>365)*(F7:F12<=100000)*C7:C12)/C13 -> 0.35 | E33: =SUMPRODUCT((G7:G12>365)*(G7:G12<=100000)*C7:C12)/C13 -> 0.35 | F33: =SUMPRODUCT((H7:H12>365)*(H7:H12<=100000)*C7:C12)/C13 -> 0.84 | G33: more than 365 days
B34: Total | C34: =SUM(C27:C33) -> 1 | D34: =SUM(D27:D33) -> 1 | E34: =SUM(E27:E33) -> 1 | F34: =SUM(F27:F33) -> 1 | G34: Doit être égal à 100 %
B36: Convention TTL : trésorerie 1 jour ; OPCVM HY 7 jours (30 en S3) ; fonds evergreen 180 jours en régime normal (préavis 45 JO ou 30 jours, gate trimestriel, règlement), 365 jours et plus en S3 lorsque les pairs saturent le gate ; fonds fermés 365 jours (cession secondaire agréée) à 1 095 jours en S4 (marché secondaire fermé). Les haircuts de cession s'appliquent aux ventes forcées dans le moteur LST.

Sheet LLP
B2: LLP - PROFIL DE LIQUIDITÉ DU PASSIF ET ADÉQUATION ACTIF-PASSIF
B3: Délai de liquidité du passif (LTTL) du point de vue du porteur : préavis, attente de la prochaine date de rachat, publication et règlement. Comparaison au WATTL de l'actif par scénario. Profil Annex IV côté passif.
B5: A. DÉLAI DE LIQUIDITÉ DU PASSIF (LTTL), EN JOURS CALENDAIRES
B6: Composante | C6: Minimum | D6: Moyen | E6: Maximum | F6: Préavis prolongé | G6: Source
B7: Préavis (centralisation à VL) | C7: =Preavis_j -> 91 | D7: =Preavis_j -> 91 | E7: =Preavis_j -> 91 | F7: =Preavis_max_j -> 180 | G7: Prospectus art. 7.2.3 et 7.2.7
B8: Attente de la prochaine date de centralisation | C8: 0 | D8: =ROUND(365/Rachats_par_an/2,0) -> 91 | E8: =ROUND(365/Rachats_par_an,0) -> 183 | F8: =ROUND(365/Rachats_par_an/2,0) -> 91 | G8: Deux dates par an : 0 à 182 jours, 91 en moyenne
B9: Publication de la VL et règlement | C9: =Reglement_cal -> 49 | D9: =Reglement_cal -> 49 | E9: =Reglement_cal -> 49 | F9: =Reglement_cal -> 49 | G9: Prospectus art. 6 et 7.2.4
B10: LTTL hors blocage | C10: =SUM(C7:C9) -> 140 | D10: =SUM(D7:D9) -> 231 | E10: =SUM(E7:E9) -> 323 | F10: =SUM(F7:F9) -> 320 | G10: Délai entre la décision de sortir et le cash
B11: Porteurs encore sous blocage à la date de départ | C11: =Part_bloquee -> 0.5 | G11: Paramètres D : part de l'actif net souscrite depuis moins de 24 mois
B12: LTTL moyen pondéré du passif (blocage résiduel moyen de 12 mois pour la part bloquée) | C12: =(1-Part_bloquee)*LTTL_moy+Part_bloquee*(365+LTTL_moy) -> 413.5 | G12: Dérivé
B14: B. ADÉQUATION ACTIF-PASSIF écart = WATTL actif - LTTL moyen (jours). Positif : l'actif se convertit plus lentement que le passif ne sort ; l'écart est porté par la poche liquide, les flux entrants et le plafonnement.
B15: Mesure | C15: Normal | D15: S2 | E15: S3 | F15: S4 | G15: Lecture
B16: WATTL actif (jours) | C16: =WATTL_N -> 202.07 | D16: =WATTL_S2 -> 300.84 | E16: =WATTL_S3 -> 437.7 | F16: =WATTL_S4 -> 651.2 | G16: Onglet ALP
B17: LTTL moyen du passif (jours) | C17: =LTTL_moy -> 231 | D17: =LTTL_moy -> 231 | E17: =LTTL_moy -> 231 | F17: =LTTL_prol -> 320 | G17: S4 : préavis prolongé à 180 jours (art. 7.2.7)
B18: Écart actif - passif (jours) | C18: =C16-C17 -> -28.93 | D18: =D16-D17 -> 69.84 | E18: =E16-E17 -> 206.7 | F18: =F16-F17 -> 331.2 | G18: Vert < 100 ; Orange 100 à 250 ; Rouge > 250
B19: Verdict | C19: =IF(C18>250,"Rouge",IF(C18>100,"Orange","Vert")) -> Vert | D19: =IF(D18>250,"Rouge",IF(D18>100,"Orange","Vert")) -> Vert | E19: =IF(E18>250,"Rouge",IF(E18>100,"Orange","Vert")) -> Orange | F19: =IF(F18>250,"Rouge",IF(F18>100,"Orange","Vert")) -> Rouge | G19: Le plafonnement de 5 % est la réponse structurelle à cet écart
B20: Couverture de la sortie maximale sur douze mois (2 × gate) par l'actif convertible dans le LTTL maximal, S3 | C20: =SUMPRODUCT((ALP!G7:G12<=LTTL_max)*ALP!C7:C12*(1-ALP!L7:L12))/(2*Gate*AN_depart) -> 1.567 | G20: Doit dépasser 1 : la poche liquide couvre deux dates plafonnées
B22: C. PROFIL ANNEX IV, CÔTÉ PASSIF % de l'actif net rachetable par tranche (question 186), hypothèse de porteurs répartis uniformément
B23: Tranche | C23: Normal | D23: S2 (gate actif) | E23: S3 (gate et suspension) | F23: Préavis prolongé | G23: Champ Annex IV
B24: 1 jour | C24: 0 | D24: 0 | E24: 0 | F24: 0 | G24: 1 day
B25: 2 à 7 jours | C25: 0 | D25: 0 | E25: 0 | F25: 0 | G25: 2-7 days
B26: 8 à 30 jours | C26: 0 | D26: 0 | E26: 0 | F26: 0 | G26: 8-30 days
B27: 31 à 90 jours | C27: 0 | D27: 0 | E27: 0 | F27: 0 | G27: 31-90 days
B28: 91 à 180 jours | C28: =(1-Part_bloquee)*0.5 -> 0.25 | D28: =MIN(Gate,(1-Part_bloquee)*0.5) -> 0.05 | E28: 0 | F28: 0 | G28: 91-180 days ; une date de rachat au plus dans la fenêtre
B29: 181 à 365 jours | C29: =(1-Part_bloquee)*0.5 -> 0.25 | D29: =MIN(Gate,(1-Part_bloquee)*0.5) -> 0.05 | E29: =MIN(Gate,(1-Part_bloquee)) -> 0.05 | F29: =MIN(2*Gate,(1-Part_bloquee)) -> 0.1 | G29: 181-365 days ; deuxième date, LTTL max 322 jours
B30: Plus de 365 jours | C30: =1-SUM(C24:C29) -> 0.5 | D30: =1-SUM(D24:D29) -> 0.9 | E30: =1-SUM(E24:E29) -> 0.95 | F30: =1-SUM(F24:F29) -> 0.9 | G30: more than 365 days ; porteurs bloqués et demandes reportées
B31: Total | C31: =SUM(C24:C30) -> 1 | D31: =SUM(D24:D30) -> 1 | E31: =SUM(E24:E30) -> 1 | F31: =SUM(F24:F30) -> 1
B32: Hypothèses : les porteurs hors blocage demandent au plus le plafond par date ; en S3 la première date est plafonnée puis suspendue ; en préavis prolongé la première date glisse de 89 jours. Ce profil alimente la question 186 du reporting Annex IV ; le profil d'actif (ALP) la question 178.

Sheet LST Moteur
B2: LST - MOTEUR DE PROJECTION PAR SCÉNARIO : HUIT DATES DE RACHAT SEMESTRIELLES
B3: Pour chaque scénario : passif (demandes, report, plafond, suspension), flux des lignes (appels, distributions, chocs de marché du MST), cascade de ressources (trésorerie au-dessus du plancher, vente du fonds HY, rachats evergreen sous gate et pression des pairs, cession secondaire décotée), puis indicateurs et verdict par date. Tous les paramètres viennent de l'onglet Paramètres.
B5: S1 - BASE Rachats courants, collecte normale, marchés stables
B6: Date de rachat | C6: 1 | D6: 2 | E6: 3 | F6: 4 | G6: 5 | H6: 6 | I6: 7 | J6: 8 | K6: Formule et lecture
B7: Date de VL de rachat | C7: =EDATE(Date_depart,0) -> 47118 | D7: =EDATE(Date_depart,6) -> 47299 | E7: =EDATE(Date_depart,12) -> 47483 | F7: =EDATE(Date_depart,18) -> 47664 | G7: =EDATE(Date_depart,24) -> 47848 | H7: =EDATE(Date_depart,30) -> 48029 | I7: =EDATE(Date_depart,36) -> 48213 | J7: =EDATE(Date_depart,42) -> 48395
B8: Actif net de début de période | C8: =AN_depart -> 8000000 | D8: =C59 -> 8866702.3 | E8: =D59 -> 9846937.1 | F8: =E59 -> 10999515 | G8: =F59 -> 12286513 | H8: =G59 -> 13722954 | I8: =H59 -> 15325805 | J8: =I59 -> 17113948 | K8: t = 1 : AN de départ ; ensuite AN de fin précédent
B9: Souscriptions versées sur la période | C9: =Collecte_norm*Paramètres!$C$133*C8 -> 800000 | D9: =Collecte_norm*Paramètres!$D$133*D8 -> 886670.23 | E9: =Collecte_norm*Paramètres!$E$133*E8 -> 984693.71 | F9: =Collecte_norm*Paramètres!$F$133*F8 -> 1099951.5 | G9: =Collecte_norm*Paramètres!$G$133*G8 -> 1228651.3 | H9: =Collecte_norm*Paramètres!$H$133*H8 -> 1372295.4 | I9: =Collecte_norm*Paramètres!$I$133*I8 -> 1532580.5 | J9: =Collecte_norm*Paramètres!$J$133*J8 -> 1711394.8 | K9: Collecte normale × multiplicateur du scénario
B10: Demandes de rachat nouvelles | C10: =(Paramètres!$C$128+Paramètres!$C$153*Top1)*C8 -> 160000 | D10: =(Paramètres!$D$128+Paramètres!$D$153*Top1)*D8 -> 177334.05 | E10: =(Paramètres!$E$128+Paramètres!$E$153*Top1)*E8 -> 196938.74 | F10: =(Paramètres!$F$128+Paramètres!$F$153*Top1)*F8 -> 219990.29 | G10: =(Paramètres!$G$128+Paramètres!$G$153*Top1)*G8 -> 245730.25 | H10: =(Paramètres!$H$128+Paramètres!$H$153*Top1)*H8 -> 274459.08 | I10: =(Paramètres!$I$128+Paramètres!$I$153*Top1)*I8 -> 306516.1 | J10: =(Paramètres!$J$128+Paramètres!$J$153*Top1)*J8 -> 342278.95 | K10: Taux du scénario × AN, plus sortie du premier porteur le cas échéant
B11: Demandes reportées des dates précédentes | C11: =0 -> 0 | D11: =C16 -> 0 | E11: =D16 -> 0 | F11: =E16 -> 0 | G11: =F16 -> 0 | H11: =G16 -> 0 | I11: =H16 -> 0 | J11: =I16 -> 0 | K11: Report automatique (art. 7.2.6)
B12: Demandes totales à la date | C12: =C10+C11 -> 160000 | D12: =D10+D11 -> 177334.05 | E12: =E10+E11 -> 196938.74 | F12: =F10+F11 -> 219990.29 | G12: =G10+G11 -> 245730.25 | H12: =H10+H11 -> 274459.08 | I12: =I10+I11 -> 306516.1 | J12: =J10+J11 -> 342278.95
B13: Montant exécutable (plafond net des souscriptions) | C13: =IF(Gate_actif=1,Gate*C8+C9,C12) -> 1200000 | D13: =IF(Gate_actif=1,Gate*D8+D9,D12) -> 1330005.3 | E13: =IF(Gate_actif=1,Gate*E8+E9,E12) -> 1477040.6 | F13: =IF(Gate_actif=1,Gate*F8+F9,F12) -> 1649927.2 | G13: =IF(Gate_actif=1,Gate*G8+G9,G12) -> 1842976.9 | H13: =IF(Gate_actif=1,Gate*H8+H9,H12) -> 2058443.1 | I13: =IF(Gate_actif=1,Gate*I8+I9,I12) -> 2298870.7 | J13: =IF(Gate_actif=1,Gate*J8+J9,J12) -> 2567092.1 | K13: Gate × AN + souscriptions versées ; sans limite si le gate est levé
B14: Suspension des rachats active (1/0) | C14: =0 -> 0 | D14: =IF(OR(C14=1,AND(Suspension_auto=1,C18>=Reports_max)),1,0) -> 0 | E14: =IF(OR(D14=1,AND(Suspension_auto=1,D18>=Reports_max)),1,0) -> 0 | F14: =IF(OR(E14=1,AND(Suspension_auto=1,E18>=Reports_max)),1,0) -> 0 | G14: =IF(OR(F14=1,AND(Suspension_auto=1,F18>=Reports_max)),1,0) -> 0 | H14: =IF(OR(G14=1,AND(Suspension_auto=1,G18>=Reports_max)),1,0) -> 0 | I14: =IF(OR(H14=1,AND(Suspension_auto=1,H18>=Reports_max)),1,0) -> 0 | J14: =IF(OR(I14=1,AND(Suspension_auto=1,I18>=Reports_max)),1,0) -> 0 | K14: Déclenchée après le nombre maximal de reports consécutifs (Paramètres E)
B15: Rachats exécutés | C15: =IF(C14=1,0,MIN(C12,C13)) -> 160000 | D15: =IF(D14=1,0,MIN(D12,D13)) -> 177334.05 | E15: =IF(E14=1,0,MIN(E12,E13)) -> 196938.74 | F15: =IF(F14=1,0,MIN(F12,F13)) -> 219990.29 | G15: =IF(G14=1,0,MIN(G12,G13)) -> 245730.25 | H15: =IF(H14=1,0,MIN(H12,H13)) -> 274459.08 | I15: =IF(I14=1,0,MIN(I12,I13)) -> 306516.1 | J15: =IF(J14=1,0,MIN(J12,J13)) -> 342278.95 | K15: Zéro en suspension
B16: Demandes reportées à la date suivante | C16: =C12-C15 -> 0 | D16: =D12-D15 -> 0 | E16: =E12-E15 -> 0 | F16: =F12-F15 -> 0 | G16: =G12-G15 -> 0 | H16: =H12-H15 -> 0 | I16: =I12-I15 -> 0 | J16: =J12-J15 -> 0
B17: Date plafonnée ou suspendue (1/0) | C17: =IF(C16>1,1,0) -> 0 | D17: =IF(D16>1,1,0) -> 0 | E17: =IF(E16>1,1,0) -> 0 | F17: =IF(F16>1,1,0) -> 0 | G17: =IF(G16>1,1,0) -> 0 | H17: =IF(H16>1,1,0) -> 0 | I17: =IF(I16>1,1,0) -> 0 | J17: =IF(J16>1,1,0) -> 0
B18: Dates plafonnées consécutives | C18: =C17 -> 0 | D18: =IF(D17=1,C18+1,0) -> 0 | E18: =IF(E17=1,D18+1,0) -> 0 | F18: =IF(F17=1,E18+1,0) -> 0 | G18: =IF(G17=1,F18+1,0) -> 0 | H18: =IF(H17=1,G18+1,0) -> 0 | I18: =IF(I17=1,H18+1,0) -> 0 | J18: =IF(J17=1,I18+1,0) -> 0
B19: File d'attente en % de l'AN de début | C19: =C16/C8 -> 0 | D19: =D16/D8 -> 0 | E19: =E16/E8 -> 0 | F19: =F16/F8 -> 0 | G19: =G16/G8 -> 0 | H19: =H16/H8 -> 0 | I19: =I16/I8 -> 0 | J19: =J16/J8 -> 0
B21: MAPIF II - valeur de début | C21: =Paramètres!$D$68*AN_depart -> 2800000 | D21: =C53 -> 3084337.6 | E21: =D53 -> 3377239.5 | F21: =E53 -> 3703886 | G21: =F53 -> 4042781.8 | H21: =G53 -> 4394386.1 | I21: =H53 -> 4759175.5 | J21: =I53 -> 4937644.6
B22: MSIG 3 - valeur de début | C22: =Paramètres!$D$69*AN_depart -> 0 | D22: =C54 -> 0 | E22: =D54 -> 0 | F22: =E54 -> 0 | G22: =F54 -> 0 | H22: =G54 -> 0 | I22: =H54 -> 0 | J22: =I54 -> 0
B23: PG NGI - valeur de début | C23: =Paramètres!$D$70*AN_depart -> 1960000 | D23: =C55 -> 2225703.3 | E23: =D55 -> 2524051.2 | F23: =E55 -> 2885119.1 | G23: =F55 -> 3297633.3 | H23: =G55 -> 3772913.4 | I23: =H55 -> 4318826.2 | J23: =I55 -> 5044138.4
B24: Ares AGI - valeur de début | C24: =Paramètres!$D$71*AN_depart -> 1960000 | D24: =C56 -> 2174261.4 | E24: =D56 -> 2413480.1 | F24: =E56 -> 2708958.9 | G24: =F56 -> 3045381.5 | H24: =G56 -> 3432545.1 | I24: =H56 -> 3876476.8 | J24: =I56 -> 4483865.4
B25: Fonds HY UCITS - valeur de début | C25: =Paramètres!$D$72*AN_depart -> 880000 | D25: =C57 -> 950400 | E25: =D57 -> 1053364.2 | F25: =E57 -> 1169816.1 | G25: =F57 -> 1306742.4 | H25: =G57 -> 1459637.7 | I25: =H57 -> 1630286.9 | J25: =I57 -> 1820705.6
B26: Trésorerie de début | C26: =W_cash*AN_depart -> 400000 | D26: =C51 -> 432000 | E26: =D51 -> 478801.92 | F26: =E51 -> 531734.6 | G26: =F51 -> 593973.8 | H26: =G51 -> 663471.69 | I26: =H51 -> 741039.51 | J26: =I51 -> 827593.47
B27: Non-appelé de début (fonds fermés) | C27: =NA_total -> 1200000 | D27: =C58 -> 1000000 | E27: =D58 -> 800000 | F27: =E58 -> 600000 | G27: =F58 -> 400000 | H27: =G58 -> 200000 | I27: =H58 -> 0 | J27: =I58 -> 0 | K27: Engagements restant à appeler
B29: Appels de fonds des fonds fermés | C29: =MIN(C27,NA_total*Appels_base*Paramètres!$C$143) -> 200000 | D29: =MIN(D27,NA_total*Appels_base*Paramètres!$D$143) -> 200000 | E29: =MIN(E27,NA_total*Appels_base*Paramètres!$E$143) -> 200000 | F29: =MIN(F27,NA_total*Appels_base*Paramètres!$F$143) -> 200000 | G29: =MIN(G27,NA_total*Appels_base*Paramètres!$G$143) -> 200000 | H29: =MIN(H27,NA_total*Appels_base*Paramètres!$H$143) -> 200000 | I29: =MIN(I27,NA_total*Appels_base*Paramètres!$I$143) -> 0 | J29: =MIN(J27,NA_total*Appels_base*Paramètres!$J$143) -> 0 | K29: Rythme normal × multiplicateur ; MAPIF II 60 %, MSIG 3 40 % du non-appelé
B30: Distributions des fonds fermés | C30: =(C21*Paramètres!$D$79+C22*Paramètres!$D$80)/2*Paramètres!$C$138 -> 84000 | D30: =(D21*Paramètres!$D$79+D22*Paramètres!$D$80)/2*Paramètres!$D$138 -> 92530.127 | E30: =(E21*Paramètres!$D$79+E22*Paramètres!$D$80)/2*Paramètres!$E$138 -> 101317.19 | F30: =(F21*Paramètres!$D$79+F22*Paramètres!$D$80)/2*Paramètres!$F$138 -> 111116.58 | G30: =(G21*Paramètres!$D$79+G22*Paramètres!$D$80)/2*Paramètres!$G$138 -> 121283.45 | H30: =(H21*Paramètres!$D$79+H22*Paramètres!$D$80)/2*Paramètres!$H$138 -> 131831.58 | I30: =(I21*Paramètres!$D$79+I22*Paramètres!$D$80)/2*Paramètres!$I$138 -> 142775.27 | J30: =(J21*Paramètres!$D$79+J22*Paramètres!$D$80)/2*Paramètres!$J$138 -> 148129.34 | K30: Valeur × taux annuel / 2 × multiplicateur
B31: Distributions des fonds evergreen | C31: =(C23*Paramètres!$D$81+C24*Paramètres!$D$82)/2*Paramètres!$C$138 -> 68600 | D31: =(D23*Paramètres!$D$81+D24*Paramètres!$D$82)/2*Paramètres!$D$138 -> 76613.569 | E31: =(E23*Paramètres!$D$81+E24*Paramètres!$D$82)/2*Paramètres!$E$138 -> 85577.516 | F31: =(F23*Paramètres!$D$81+F24*Paramètres!$D$82)/2*Paramètres!$F$138 -> 96575.163 | G31: =(G23*Paramètres!$D$81+G24*Paramètres!$D$82)/2*Paramètres!$G$138 -> 109110.87 | H31: =(H23*Paramètres!$D$81+H24*Paramètres!$D$82)/2*Paramètres!$H$138 -> 123542.76 | I31: =(I23*Paramètres!$D$81+I24*Paramètres!$D$82)/2*Paramètres!$I$138 -> 140100.18 | J31: =(J23*Paramètres!$D$81+J24*Paramètres!$D$82)/2*Paramètres!$J$138 -> 162538.02 | K31: Imputées sur la capacité de rachat des fonds (PG NGI)
B32: Frais du Fonds | C32: =Frais_an/2*C8 -> 130396 | D32: =Frais_an/2*D8 -> 144522.81 | E32: =Frais_an/2*E8 -> 160500.15 | F32: =Frais_an/2*F8 -> 179286.59 | G32: =Frais_an/2*G8 -> 200264.01 | H32: =Frais_an/2*H8 -> 223677.29 | I32: =Frais_an/2*I8 -> 249802.96 | J32: =Frais_an/2*J8 -> 278948.79
B33: Produits de trésorerie | C33: =C26*Paramètres!$C$84/2 -> 5000 | D33: =D26*Paramètres!$C$84/2 -> 5400 | E33: =E26*Paramètres!$C$84/2 -> 5985.0241 | F33: =F26*Paramètres!$C$84/2 -> 6646.6825 | G33: =G26*Paramètres!$C$84/2 -> 7424.6725 | H33: =H26*Paramètres!$C$84/2 -> 8293.3961 | I33: =I26*Paramètres!$C$84/2 -> 9262.9939 | J33: =J26*Paramètres!$C$84/2 -> 10344.918
B34: Besoin de trésorerie brut | C34: =C15+C29+C32-C9-C30-C31-C33 -> -467204 | D34: =D15+D29+D32-D9-D30-D31-D33 -> -539357.07 | E34: =E15+E29+E32-E9-E30-E31-E33 -> -620134.54 | F34: =F15+F29+F32-F9-F30-F31-F33 -> -715013.02 | G34: =G15+G29+G32-G9-G30-G31-G33 -> -820476 | H34: =H15+H29+H32-H9-H30-H31-H33 -> -937826.77 | I34: =I15+I29+I32-I9-I30-I31-I33 -> -1268399.9 | J34: =J15+J29+J32-J9-J30-J31-J33 -> -1411179.3 | K34: Sorties moins entrées de la période
B35: Trésorerie mobilisable au-dessus du plancher | C35: =MAX(0,C26-Cash_min*C8) -> 320000 | D35: =MAX(0,D26-Cash_min*D8) -> 343332.98 | E35: =MAX(0,E26-Cash_min*E8) -> 380332.55 | F35: =MAX(0,F26-Cash_min*F8) -> 421739.45 | G35: =MAX(0,G26-Cash_min*G8) -> 471108.67 | H35: =MAX(0,H26-Cash_min*H8) -> 526242.15 | I35: =MAX(0,I26-Cash_min*I8) -> 587781.46 | J35: =MAX(0,J26-Cash_min*J8) -> 656453.99 | K35: Plancher opérationnel (Paramètres D)
B36: Besoin après trésorerie | C36: =MAX(0,C34-C35) -> 0 | D36: =MAX(0,D34-D35) -> 0 | E36: =MAX(0,E34-E35) -> 0 | F36: =MAX(0,F34-F35) -> 0 | G36: =MAX(0,G34-G35) -> 0 | H36: =MAX(0,H34-H35) -> 0 | I36: =MAX(0,I34-I35) -> 0 | J36: =MAX(0,J34-J35) -> 0
B37: Vente du fonds HY | C37: =MIN(C36,C25*(1+'MST Scénarios'!C20)) -> 0 | D37: =MIN(D36,D25*(1+'MST Scénarios'!D20)) -> 0 | E37: =MIN(E36,E25*(1+'MST Scénarios'!E20)) -> 0 | F37: =MIN(F36,F25*(1+'MST Scénarios'!F20)) -> 0 | G37: =MIN(G36,G25*(1+'MST Scénarios'!G20)) -> 0 | H37: =MIN(H36,H25*(1+'MST Scénarios'!H20)) -> 0 | I37: =MIN(I36,I25*(1+'MST Scénarios'!I20)) -> 0 | J37: =MIN(J36,J25*(1+'MST Scénarios'!J20)) -> 0 | K37: Première ressource après la trésorerie
B38: Décote réalisée sur la vente HY | C38: =C37*0 -> 0 | D38: =D37*0 -> 0 | E38: =E37*0 -> 0 | F38: =F37*0 -> 0 | G38: =G37*0 -> 0 | H38: =H37*0 -> 0 | I38: =I37*0 -> 0 | J38: =J37*0 -> 0 | K38: Haircut S2 à S4 (Paramètres C bis)
B39: Besoin après vente HY | C39: =MAX(0,C36-C37*(1-0)) -> 0 | D39: =MAX(0,D36-D37*(1-0)) -> 0 | E39: =MAX(0,E36-E37*(1-0)) -> 0 | F39: =MAX(0,F36-F37*(1-0)) -> 0 | G39: =MAX(0,G36-G37*(1-0)) -> 0 | H39: =MAX(0,H36-H37*(1-0)) -> 0 | I39: =MAX(0,I36-I37*(1-0)) -> 0 | J39: =MAX(0,J36-J37*(1-0)) -> 0
B40: Capacité de rachat des fonds evergreen (gates, pairs, distributions) | C40: =MAX(0,(C23*Paramètres!$F$70+C24*Paramètres!$F$71)*2*(1-Paramètres!$C$148)-C31) -> 205800 | D40: =MAX(0,(D23*Paramètres!$F$70+D24*Paramètres!$F$71)*2*(1-Paramètres!$D$148)-D31) -> 231383.96 | E40: =MAX(0,(E23*Paramètres!$F$70+E24*Paramètres!$F$71)*2*(1-Paramètres!$E$148)-E31) -> 260049.68 | F40: =MAX(0,(F23*Paramètres!$F$70+F24*Paramètres!$F$71)*2*(1-Paramètres!$F$148)-F31) -> 295010.3 | G40: =MAX(0,(G23*Paramètres!$F$70+G24*Paramètres!$F$71)*2*(1-Paramètres!$G$148)-G31) -> 334900.17 | H40: =MAX(0,(H23*Paramètres!$F$70+H24*Paramètres!$F$71)*2*(1-Paramètres!$H$148)-H31) -> 380839.33 | I40: =MAX(0,(I23*Paramètres!$F$70+I24*Paramètres!$F$71)*2*(1-Paramètres!$I$148)-I31) -> 433571.03 | J40: =MAX(0,(J23*Paramètres!$F$70+J24*Paramètres!$F$71)*2*(1-Paramètres!$J$148)-J31) -> 504422.25 | K40: Deux trimestres de gate à 5 %, part des pairs déduite
B41: Rachats evergreen demandés : besoin résiduel et reconstitution de la poche d'exécution | C41: =MAX(C39,Poche_min_exec*C8-(C26-C34+C37*(1-0)+C25*(1+'MST Scénarios'!C20)-C37)) -> 0 | D41: =MAX(D39,Poche_min_exec*D8-(D26-D34+D37*(1-0)+D25*(1+'MST Scénarios'!D20)-D37)) -> 0 | E41: =MAX(E39,Poche_min_exec*E8-(E26-E34+E37*(1-0)+E25*(1+'MST Scénarios'!E20)-E37)) -> 0 | F41: =MAX(F39,Poche_min_exec*F8-(F26-F34+F37*(1-0)+F25*(1+'MST Scénarios'!F20)-F37)) -> 0 | G41: =MAX(G39,Poche_min_exec*G8-(G26-G34+G37*(1-0)+G25*(1+'MST Scénarios'!G20)-G37)) -> 0 | H41: =MAX(H39,Poche_min_exec*H8-(H26-H34+H37*(1-0)+H25*(1+'MST Scénarios'!H20)-H37)) -> 0 | I41: =MAX(I39,Poche_min_exec*I8-(I26-I34+I37*(1-0)+I25*(1+'MST Scénarios'!I20)-I37)) -> 0 | J41: =MAX(J39,Poche_min_exec*J8-(J26-J34+J37*(1-0)+J25*(1+'MST Scénarios'!J20)-J37)) -> 0 | K41: La Fonction Risques demande le rachat dès que trésorerie + HY passent sous la poche d'exécution (Paramètres D)
B42: Rachats obtenus des fonds evergreen | C42: =MAX(0,MIN(C41,C40)) -> 0 | D42: =MAX(0,MIN(D41,D40)) -> 0 | E42: =MAX(0,MIN(E41,E40)) -> 0 | F42: =MAX(0,MIN(F41,F40)) -> 0 | G42: =MAX(0,MIN(G41,G40)) -> 0 | H42: =MAX(0,MIN(H41,H40)) -> 0 | I42: =MAX(0,MIN(I41,I40)) -> 0 | J42: =MAX(0,MIN(J41,J40)) -> 0 | K42: Au prorata PG NGI / Ares AGI, dans la limite de la capacité sous gate
B43: Besoin résiduel | C43: =MAX(0,C39-C42) -> 0 | D43: =MAX(0,D39-D42) -> 0 | E43: =MAX(0,E39-E42) -> 0 | F43: =MAX(0,F39-F42) -> 0 | G43: =MAX(0,G39-G42) -> 0 | H43: =MAX(0,H39-H42) -> 0 | I43: =MAX(0,I39-I42) -> 0 | J43: =MAX(0,J39-J42) -> 0
B44: Cession secondaire des fonds fermés (valeur cédée) | C44: =IF(Cession_autorisee=1,MIN(C43/(1-0),C21+C22),0) -> 0 | D44: =IF(Cession_autorisee=1,MIN(D43/(1-0),D21+D22),0) -> 0 | E44: =IF(Cession_autorisee=1,MIN(E43/(1-0),E21+E22),0) -> 0 | F44: =IF(Cession_autorisee=1,MIN(F43/(1-0),F21+F22),0) -> 0 | G44: =IF(Cession_autorisee=1,MIN(G43/(1-0),G21+G22),0) -> 0 | H44: =IF(Cession_autorisee=1,MIN(H43/(1-0),H21+H22),0) -> 0 | I44: =IF(Cession_autorisee=1,MIN(I43/(1-0),I21+I22),0) -> 0 | J44: =IF(Cession_autorisee=1,MIN(J43/(1-0),J21+J22),0) -> 0 | K44: Montant à céder pour encaisser le besoin après décote
...

Sheet LST Reverse
B2: LST - TESTS INVERSÉS : TAUX DE RACHAT PERSISTANT, AVEC ET SANS PLAFONNEMENT
B3: Moteur compact en % de l'actif net de départ (actif net supposé constant, effet marché neutralisé) : un même taux de rachat demandé à chaque date, collecte nulle, flux de ressources du profil choisi dans l'onglet Paramètres (par défaut le régime normal, pour isoler l'effet des rachats ; 3 pour cumuler avec les flux S3). Cascade identique au moteur principal : poche liquide, rachats evergreen pour reconstituer la poche d'exécution, cession secondaire décotée au-delà. Avec plafonnement : suspension après le nombre maximal de reports. L'écart entre les deux points de rupture mesure la valeur du plafonnement.
B5: A. RESSOURCES PAR DATE EN % DE L'ACTIF NET (profil de flux choisi, hors rachats et hors collecte)
B6: Flux | C6: Date 1 | D6: Date 2 | E6: Date 3 | F6: Date 4 | G6: Date 5 | H6: Date 6 | I6: Date 7 | J6: Date 8 | O6: Source
B7: Capacité de rachat des fonds evergreen | C7: =(Paramètres!$D$70*Paramètres!$F$70+Paramètres!$D$71*Paramètres!$F$71)*2*(1-CHOOSE(Reverse_flux,Paramètres!$C$148,Paramètres!$C$149,Paramètres!$C$150,Paramètres!$C$151)) -> 0.0343 | D7: =(Paramètres!$D$70*Paramètres!$F$70+Paramètres!$D$71*Paramètres!$F$71)*2*(1-CHOOSE(Reverse_flux,Paramètres!$D$148,Paramètres!$D$149,Paramètres!$D$150,Paramètres!$D$151)) -> 0.0343 | E7: =(Paramètres!$D$70*Paramètres!$F$70+Paramètres!$D$71*Paramètres!$F$71)*2*(1-CHOOSE(Reverse_flux,Paramètres!$E$148,Paramètres!$E$149,Paramètres!$E$150,Paramètres!$E$151)) -> 0.0343 | F7: =(Paramètres!$D$70*Paramètres!$F$70+Paramètres!$D$71*Paramètres!$F$71)*2*(1-CHOOSE(Reverse_flux,Paramètres!$F$148,Paramètres!$F$149,Paramètres!$F$150,Paramètres!$F$151)) -> 0.0343 | G7: =(Paramètres!$D$70*Paramètres!$F$70+Paramètres!$D$71*Paramètres!$F$71)*2*(1-CHOOSE(Reverse_flux,Paramètres!$G$148,Paramètres!$G$149,Paramètres!$G$150,Paramètres!$G$151)) -> 0.0343 | H7: =(Paramètres!$D$70*Paramètres!$F$70+Paramètres!$D$71*Paramètres!$F$71)*2*(1-CHOOSE(Reverse_flux,Paramètres!$H$148,Paramètres!$H$149,Paramètres!$H$150,Paramètres!$H$151)) -> 0.0343 | I7: =(Paramètres!$D$70*Paramètres!$F$70+Paramètres!$D$71*Paramètres!$F$71)*2*(1-CHOOSE(Reverse_flux,Paramètres!$I$148,Paramètres!$I$149,Paramètres!$I$150,Paramètres!$I$151)) -> 0.0343 | J7: =(Paramètres!$D$70*Paramètres!$F$70+Paramètres!$D$71*Paramètres!$F$71)*2*(1-CHOOSE(Reverse_flux,Paramètres!$J$148,Paramètres!$J$149,Paramètres!$J$150,Paramètres!$J$151)) -> 0.0343 | O7: Gates trimestriels × 2, part des pairs déduite
B8: Distributions des fonds cibles | C8: =((Paramètres!$D$68*Paramètres!$D$79+Paramètres!$D$69*Paramètres!$D$80)+(Paramètres!$D$70*Paramètres!$D$81+Paramètres!$D$71*Paramètres!$D$82))/2*CHOOSE(Reverse_flux,Paramètres!$C$138,Paramètres!$C$139,Paramètres!$C$140,Paramètres!$C$141) -> 0.019075 | D8: =((Paramètres!$D$68*Paramètres!$D$79+Paramètres!$D$69*Paramètres!$D$80)+(Paramètres!$D$70*Paramètres!$D$81+Paramètres!$D$71*Paramètres!$D$82))/2*CHOOSE(Reverse_flux,Paramètres!$D$138,Paramètres!$D$139,Paramètres!$D$140,Paramètres!$D$141) -> 0.019075 | E8: =((Paramètres!$D$68*Paramètres!$D$79+Paramètres!$D$69*Paramètres!$D$80)+(Paramètres!$D$70*Paramètres!$D$81+Paramètres!$D$71*Paramètres!$D$82))/2*CHOOSE(Reverse_flux,Paramètres!$E$138,Paramètres!$E$139,Paramètres!$E$140,Paramètres!$E$141) -> 0.019075 | F8: =((Paramètres!$D$68*Paramètres!$D$79+Paramètres!$D$69*Paramètres!$D$80)+(Paramètres!$D$70*Paramètres!$D$81+Paramètres!$D$71*Paramètres!$D$82))/2*CHOOSE(Reverse_flux,Paramètres!$F$138,Paramètres!$F$139,Paramètres!$F$140,Paramètres!$F$141) -> 0.019075 | G8: =((Paramètres!$D$68*Paramètres!$D$79+Paramètres!$D$69*Paramètres!$D$80)+(Paramètres!$D$70*Paramètres!$D$81+Paramètres!$D$71*Paramètres!$D$82))/2*CHOOSE(Reverse_flux,Paramètres!$G$138,Paramètres!$G$139,Paramètres!$G$140,Paramètres!$G$141) -> 0.019075 | H8: =((Paramètres!$D$68*Paramètres!$D$79+Paramètres!$D$69*Paramètres!$D$80)+(Paramètres!$D$70*Paramètres!$D$81+Paramètres!$D$71*Paramètres!$D$82))/2*CHOOSE(Reverse_flux,Paramètres!$H$138,Paramètres!$H$139,Paramètres!$H$140,Paramètres!$H$141) -> 0.019075 | I8: =((Paramètres!$D$68*Paramètres!$D$79+Paramètres!$D$69*Paramètres!$D$80)+(Paramètres!$D$70*Paramètres!$D$81+Paramètres!$D$71*Paramètres!$D$82))/2*CHOOSE(Reverse_flux,Paramètres!$I$138,Paramètres!$I$139,Paramètres!$I$140,Paramètres!$I$141) -> 0.019075 | J8: =((Paramètres!$D$68*Paramètres!$D$79+Paramètres!$D$69*Paramètres!$D$80)+(Paramètres!$D$70*Paramètres!$D$81+Paramètres!$D$71*Paramètres!$D$82))/2*CHOOSE(Reverse_flux,Paramètres!$J$138,Paramètres!$J$139,Paramètres!$J$140,Paramètres!$J$141) -> 0.019075 | O8: Multiplicateur S3
B9: Appels des fonds fermés | C9: =MIN(NA_total/AN_depart,NA_total/AN_depart*Appels_base*CHOOSE(Reverse_flux,Paramètres!$C$143,Paramètres!$C$144,Paramètres!$C$145,Paramètres!$C$146)) -> 0.025 | D9: =MIN(MAX(0,NA_total/AN_depart-SUM($C$9:C$9)),NA_total/AN_depart*Appels_base*CHOOSE(Reverse_flux,Paramètres!$D$143,Paramètres!$D$144,Paramètres!$D$145,Paramètres!$D$146)) -> 0.025 | E9: =MIN(MAX(0,NA_total/AN_depart-SUM($C$9:D$9)),NA_total/AN_depart*Appels_base*CHOOSE(Reverse_flux,Paramètres!$E$143,Paramètres!$E$144,Paramètres!$E$145,Paramètres!$E$146)) -> 0.025 | F9: =MIN(MAX(0,NA_total/AN_depart-SUM($C$9:E$9)),NA_total/AN_depart*Appels_base*CHOOSE(Reverse_flux,Paramètres!$F$143,Paramètres!$F$144,Paramètres!$F$145,Paramètres!$F$146)) -> 0.025 | G9: =MIN(MAX(0,NA_total/AN_depart-SUM($C$9:F$9)),NA_total/AN_depart*Appels_base*CHOOSE(Reverse_flux,Paramètres!$G$143,Paramètres!$G$144,Paramètres!$G$145,Paramètres!$G$146)) -> 0.025 | H9: =MIN(MAX(0,NA_total/AN_depart-SUM($C$9:G$9)),NA_total/AN_depart*Appels_base*CHOOSE(Reverse_flux,Paramètres!$H$143,Paramètres!$H$144,Paramètres!$H$145,Paramètres!$H$146)) -> 0.025 | I9: =MIN(MAX(0,NA_total/AN_depart-SUM($C$9:H$9)),NA_total/AN_depart*Appels_base*CHOOSE(Reverse_flux,Paramètres!$I$143,Paramètres!$I$144,Paramètres!$I$145,Paramètres!$I$146)) -> 0 | J9: =MIN(MAX(0,NA_total/AN_depart-SUM($C$9:I$9)),NA_total/AN_depart*Appels_base*CHOOSE(Reverse_flux,Paramètres!$J$143,Paramètres!$J$144,Paramètres!$J$145,Paramètres!$J$146)) -> 0 | O9: Jusqu'à épuisement du non-appelé
B10: Frais du Fonds | C10: =Frais_an/2 -> 0.0162995 | D10: =Frais_an/2 -> 0.0162995 | E10: =Frais_an/2 -> 0.0162995 | F10: =Frais_an/2 -> 0.0162995 | G10: =Frais_an/2 -> 0.0162995 | H10: =Frais_an/2 -> 0.0162995 | I10: =Frais_an/2 -> 0.0162995 | J10: =Frais_an/2 -> 0.0162995
B11: Ressources nettes hors rachats | C11: =C8-C9-C10 -> -0.0222245 | D11: =D8-D9-D10 -> -0.0222245 | E11: =E8-E9-E10 -> -0.0222245 | F11: =F8-F9-F10 -> -0.0222245 | G11: =G8-G9-G10 -> -0.0222245 | H11: =H8-H9-H10 -> -0.0222245 | I11: =I8-I9-I10 -> 0.0027755 | J11: =J8-J9-J10 -> 0.0027755 | O11: Négatif : les appels dépassent les distributions
B13: B. AVEC PLAFONNEMENT (gate 5 % par date, reports automatiques, suspension après le nombre maximal de reports)
B14: Taux par date et variable | C14: Date 1 | D14: Date 2 | E14: Date 3 | F14: Date 4 | G14: Date 5 | H14: Date 6 | I14: Date 7 | J14: Date 8 | L14: File à la date 8 | M14: Poche min | N14: Cessions à la date 4 | O14: Cessions à la date 8 | P14: Verdict
B15: 0.025 | L15: =J18 -> 0 | M15: =MIN(C22:J22) -> 0.048153 | N15: =F23 -> 0 | O15: =J23 -> 0 | P15: =IF(AND($B$15>Gate+0.0001,Reports_max<8,Suspension_auto=1),"Rouge : suspension à la date "&(Reports_max+1),IF(N15>0.0001,"Rouge : cessions décotées",IF(M15<S_poche_rouge,"Rouge : poche sous 5 %",IF(OR(M15<S_poche_orange,$B$15>Gate+0.0001),"Orange","Vert")))) -> Rouge : poche sous 5 %
B16: Demande totale (nouvelle + reportée) | C16: =$B$15 -> 0.025 | D16: =$B$15+C18 -> 0.025 | E16: =$B$15+D18 -> 0.025 | F16: =$B$15+E18 -> 0.025 | G16: =$B$15+F18 -> 0.025 | H16: =$B$15+G18 -> 0.025 | I16: =$B$15+H18 -> 0.025 | J16: =$B$15+I18 -> 0.025
B17: Exécuté | C17: =IF(AND($B$15>Gate+0.0001,1>Reports_max,Suspension_auto=1),0,MIN(C16,Gate)) -> 0.025 | D17: =IF(AND($B$15>Gate+0.0001,2>Reports_max,Suspension_auto=1),0,MIN(D16,Gate)) -> 0.025 | E17: =IF(AND($B$15>Gate+0.0001,3>Reports_max,Suspension_auto=1),0,MIN(E16,Gate)) -> 0.025 | F17: =IF(AND($B$15>Gate+0.0001,4>Reports_max,Suspension_auto=1),0,MIN(F16,Gate)) -> 0.025 | G17: =IF(AND($B$15>Gate+0.0001,5>Reports_max,Suspension_auto=1),0,MIN(G16,Gate)) -> 0.025 | H17: =IF(AND($B$15>Gate+0.0001,6>Reports_max,Suspension_auto=1),0,MIN(H16,Gate)) -> 0.025 | I17: =IF(AND($B$15>Gate+0.0001,7>Reports_max,Suspension_auto=1),0,MIN(I16,Gate)) -> 0.025 | J17: =IF(AND($B$15>Gate+0.0001,8>Reports_max,Suspension_auto=1),0,MIN(J16,Gate)) -> 0.025
B18: File reportée | C18: =C16-C17 -> 0 | D18: =D16-D17 -> 0 | E18: =E16-E17 -> 0 | F18: =F16-F17 -> 0 | G18: =G16-G17 -> 0 | H18: =H16-H17 -> 0 | I18: =I16-I17 -> 0 | J18: =J16-J17 -> 0
B19: Poche liquide avant appel aux fonds cibles | C19: =W_cash+W_HY-C17+C11 -> 0.1127755 | D19: =C22-D17+D11 -> 0.065551 | E19: =D22-E17+E11 -> 0.0526265 | F19: =E22-F17+F11 -> 0.039702 | G19: =F22-G17+G11 -> 0.0267775 | H19: =G22-H17+H11 -> 0.013853 | I19: =H22-I17+I11 -> 0.0259285 | J19: =I22-J17+J11 -> 0.038004
B20: Rachats obtenus des fonds evergreen | C20: =MIN(C7,MAX(0,Poche_min_exec-C19)) -> 0 | D20: =MIN(D7,MAX(0,Poche_min_exec-D19)) -> 0.0343 | E20: =MIN(E7,MAX(0,Poche_min_exec-E19)) -> 0.0343 | F20: =MIN(F7,MAX(0,Poche_min_exec-F19)) -> 0.0343 | G20: =MIN(G7,MAX(0,Poche_min_exec-G19)) -> 0.0343 | H20: =MIN(H7,MAX(0,Poche_min_exec-H19)) -> 0.0343 | I20: =MIN(I7,MAX(0,Poche_min_exec-I19)) -> 0.0343 | J20: =MIN(J7,MAX(0,Poche_min_exec-J19)) -> 0.0343
B21: Cession secondaire (valeur cédée) | C21: =IF(Cession_autorisee=1,MAX(0,Cash_min-(C19+C20))/(1-CHOOSE(Reverse_flux,Paramètres!$J$79,Paramètres!$J$79,Paramètres!$K$79,Paramètres!$L$79)),0) -> 0 | D21: =IF(Cession_autorisee=1,MAX(0,Cash_min-(D19+D20))/(1-CHOOSE(Reverse_flux,Paramètres!$J$79,Paramètres!$J$79,Paramètres!$K$79,Paramètres!$L$79)),0) -> 0 | E21: =IF(Cession_autorisee=1,MAX(0,Cash_min-(E19+E20))/(1-CHOOSE(Reverse_flux,Paramètres!$J$79,Paramètres!$J$79,Paramètres!$K$79,Paramètres!$L$79)),0) -> 0 | F21: =IF(Cession_autorisee=1,MAX(0,Cash_min-(F19+F20))/(1-CHOOSE(Reverse_flux,Paramètres!$J$79,Paramètres!$J$79,Paramètres!$K$79,Paramètres!$L$79)),0) -> 0 | G21: =IF(Cession_autorisee=1,MAX(0,Cash_min-(G19+G20))/(1-CHOOSE(Reverse_flux,Paramètres!$J$79,Paramètres!$J$79,Paramètres!$K$79,Paramètres!$L$79)),0) -> 0 | H21: =IF(Cession_autorisee=1,MAX(0,Cash_min-(H19+H20))/(1-CHOOSE(Reverse_flux,Paramètres!$J$79,Paramètres!$J$79,Paramètres!$K$79,Paramètres!$L$79)),0) -> 0 | I21: =IF(Cession_autorisee=1,MAX(0,Cash_min-(I19+I20))/(1-CHOOSE(Reverse_flux,Paramètres!$J$79,Paramètres!$J$79,Paramètres!$K$79,Paramètres!$L$79)),0) -> 0 | J21: =IF(Cession_autorisee=1,MAX(0,Cash_min-(J19+J20))/(1-CHOOSE(Reverse_flux,Paramètres!$J$79,Paramètres!$J$79,Paramètres!$K$79,Paramètres!$L$79)),0) -> 0
B22: Poche liquide de fin | C22: =C19+C20+C21*(1-CHOOSE(Reverse_flux,Paramètres!$J$79,Paramètres!$J$79,Paramètres!$K$79,Paramètres!$L$79)) -> 0.1127755 | D22: =D19+D20+D21*(1-CHOOSE(Reverse_flux,Paramètres!$J$79,Paramètres!$J$79,Paramètres!$K$79,Paramètres!$L$79)) -> 0.099851 | E22: =E19+E20+E21*(1-CHOOSE(Reverse_flux,Paramètres!$J$79,Paramètres!$J$79,Paramètres!$K$79,Paramètres!$L$79)) -> 0.0869265 | F22: =F19+F20+F21*(1-CHOOSE(Reverse_flux,Paramètres!$J$79,Paramètres!$J$79,Paramètres!$K$79,Paramètres!$L$79)) -> 0.074002 | G22: =G19+G20+G21*(1-CHOOSE(Reverse_flux,Paramètres!$J$79,Paramètres!$J$79,Paramètres!$K$79,Paramètres!$L$79)) -> 0.0610775 | H22: =H19+H20+H21*(1-CHOOSE(Reverse_flux,Paramètres!$J$79,Paramètres!$J$79,Paramètres!$K$79,Paramètres!$L$79)) -> 0.048153 | I22: =I19+I20+I21*(1-CHOOSE(Reverse_flux,Paramètres!$J$79,Paramètres!$J$79,Paramètres!$K$79,Paramètres!$L$79)) -> 0.0602285 | J22: =J19+J20+J21*(1-CHOOSE(Reverse_flux,Paramètres!$J$79,Paramètres!$J$79,Paramètres!$K$79,Paramètres!$L$79)) -> 0.072304
B23: Cessions cumulées | C23: =SUM($C$21:C21) -> 0 | D23: =SUM($C$21:D21) -> 0 | E23: =SUM($C$21:E21) -> 0 | F23: =SUM($C$21:F21) -> 0 | G23: =SUM($C$21:G21) -> 0 | H23: =SUM($C$21:H21) -> 0 | I23: =SUM($C$21:I21) -> 0 | J23: =SUM($C$21:J21) -> 0
B24: 0.05 | L24: =J27 -> 0 | M24: =MIN(C31:J31) -> 0.01 | N24: =F32 -> 0.027968824 | O24: =J32 -> 0.14761353 | P24: =IF(AND($B$24>Gate+0.0001,Reports_max<8,Suspension_auto=1),"Rouge : suspension à la date "&(Reports_max+1),IF(N24>0.0001,"Rouge : cessions décotées",IF(M24<S_poche_rouge,"Rouge : poche sous 5 %",IF(OR(M24<S_poche_orange,$B$24>Gate+0.0001),"Orange","Vert")))) -> Rouge : cessions décotées
B25: Demande totale (nouvelle + reportée) | C25: =$B$24 -> 0.05 | D25: =$B$24+C27 -> 0.05 | E25: =$B$24+D27 -> 0.05 | F25: =$B$24+E27 -> 0.05 | G25: =$B$24+F27 -> 0.05 | H25: =$B$24+G27 -> 0.05 | I25: =$B$24+H27 -> 0.05 | J25: =$B$24+I27 -> 0.05
