Workbook

Sheet PREVIEW
B1: Openstone Infraworld · Compartiment I | G1: Rapport de risque initial · Octobre 2026 · Prospectus du 30/09/2026 | H1: BAND
H2: COVER
B3: RAPPORT DE RISQUE INITIAL · OCTOBRE 2026 | H3: COVER
B4: Openstone Infraworld - Compartiment I | H4: COVER
B5: Fonds de fonds d'infrastructure evergreen semi-liquide · quatre fonds cibles, deux fermés et deux evergreen | H5: COVER
B6: Fonction permanente de gestion des risques - Fundcraft France | H6: COVER
H7: COVER
B8: PRÉ-LANCEMENT · PROSPECTUS PROJET DU 30 SEPTEMBRE 2026 · ACTIF NET CIBLE 50 M€ · SRI 4 / 7 · FPS - RG AMF ART. 423-27 | H8: COVER
B9: Document interne - ne pas diffuser · AIFMD art. 15-16 · ESMA 34-39-897 | H9: COVER
H10: COVER
B11: SOCIÉTÉ DE GESTION | H11: COVER
B12: Fundcraft France SAS - AMF GP-20260008 | H12: COVER
B13: CONSEILLER ET DISTRIBUTEUR PRINCIPAL | H13: COVER
B14: Openstone (Innovative Finance SAS) - CIF ORIAS 23002459 | H14: COVER
B15: GÉRANTS DES FONDS CIBLES | H15: COVER
B16: Macquarie (MAPIF II, MSIG 3) · Partners Group (Next Generation Infrastructure) · Ares (Global Infrastructure ELTIF) | H16: COVER
B17: DÉPOSITAIRE · DÉLÉGATAIRE COMPTABLE · COMMISSAIRE AUX COMPTES | H17: COVER
B18: BFCM · CIC · APLITEC | H18: COVER
H19: COVER
B20: Rapport établi sur la documentation : le Fonds n'est pas constitué, aucune valeur liquidative ni aucun porteur. Toutes les grandeurs en euros sont des cibles. | H20: COVER
H21: COVER
B23: Openstone Infraworld · Compartiment I | G23: Rapport de risque initial · Octobre 2026 · Prospectus du 30/09/2026 | H23: BAND
B24: 00. Synthèse pour le Comité des Risques | H24: TITLE
B25: Verdict · trois chiffres · six décisions | H25: SUB
B27: VERDICT DE LA FONCTION RISQUES charte Fundcraft, verdict d'ensemble = pire domaine Échelle à cinq niveaux : Routine, Vigilance, Élevé, Sévère, Critique. Rapport initial : le verdict porte sur la conception du véhicule, non sur une position. | H27: SEC
B28: Domaine | C28: Verdict | D28: Fondement | G28: Implication | H28: HDR
B29: Liquidité structurelle | C29: Élevé | D29: =(ROUND((W_FERMES)*100,0)&" %")&" de l'actif sans fenêtre avant échéance ; écart actif-passif de "&(ROUND(Ecart_TTL,0)&"")&" jours" -> 51 % de l'actif sans fenêtre avant échéance ; écart actif-passif de 733 jours | G29: Le plafonnement de 5 % est la seule digue ; au-delà de quatre dates, la suspension. | H29: ROW
B30: Stress tests | C30: Élevé | D30: =N_rouge&" scénarios rouges sur "&(N_vert+N_orange+N_rouge)&" : rachats de 15 % puis 20 %, crise combinée ; point de rupture à "&(SUBSTITUTE(ROUND((Rupture_rachats)*100,1)&"",".",",")&" %")&" par date" -> 2 scénarios rouges sur 8 : rachats de 15 % puis 20 %, crise combinée ; point de rupture à 7,5 % par date | G30: Décision 5 : séquencer les engagements ; rejouer sur l'encours réel (R12). | H30: ROW
B31: Concentration | C31: Élevé | D31: =(ROUND((W_MACQ)*100,0)&" %")&" de l'allocation chez Macquarie, "&(ROUND((W_MAPIF)*100,0)&" %")&" sur MAPIF II ; aucune limite au prospectus" -> 51 % de l'allocation chez Macquarie, 34 % sur MAPIF II ; aucune limite au prospectus | G31: Décision 4 : limites internes gérant 40 % et fonds cible 35 %. | H31: ROW
B32: Marché, change et valorisation | C32: Vigilance | D32: ="Dollar non couvert de "&(ROUND((W_USD_BAS)*100,0)&" %")&" à "&(ROUND((W_USD_HAUT)*100,0)&" %")&" de l'actif ; VL trimestrielles décalées sur "&(ROUND((W_FERMES)*100,0)&" %") -> Dollar non couvert de 34 % à 68 % de l'actif ; VL trimestrielles décalées sur 51 % | G32: Décision 4 : limite de change ; décision 6 : revue des VL reçues. | H32: ROW
B33: Documentation et gouvernance | C33: Élevé | D33: ="Préavis 91 jours au prospectus contre 180 dans la note de liquidité ; "&Lim_a_arreter&" seuils à arrêter, "&Lim_a_valider&" à valider ; douze écarts au registre" -> Préavis 91 jours au prospectus contre 180 dans la note de liquidité ; 4 seuils à arrêter, 7 à valider ; douze écarts au registre | G33: Décisions 1, 2 et 6 avant le dépôt du prospectus. | H33: ROW
B34: Verdict d'ensemble | C34: ÉLEVÉ | D34: Fixé par la liquidité, les stress tests, la concentration et la documentation. Aucune limite du prospectus n'est testable avant la première valeur liquidative. | G34: Lancement conditionné aux décisions 1 à 3 ; revue à la première VL. | H34: ROW
B36: TROIS CHIFFRES QUI COMMANDENT LES DÉCISIONS | H36: SEC
B37: PART DE L'ACTIF SANS LIQUIDITÉ AVANT ÉCHÉANCE | C37: POINT DE RUPTURE DES RACHATS PERSISTANTS | D37: CONCENTRATION SUR UN SEUL GÉRANT | H37: KPI1
B38: =(ROUND((W_FERMES)*100,0)&" %")&" de l'actif net" -> 51 % de l'actif net | C38: =(SUBSTITUTE(ROUND((Rupture_rachats)*100,1)&"",".",",")&" %")&" par date" -> 7,5 % par date | D38: =(ROUND((W_MACQ)*100,0)&" %")&" de l'actif net" -> 51 % de l'actif net | H38: KPI2
B39: ="MAPIF II et MSIG 3 ; délai moyen de liquidation de l'actif "&(ROUND(TTL_actif,0)&"")&" jours contre "&(ROUND(TTL_passif,0)&"")&" jours pour la sortie d'un porteur" -> MAPIF II et MSIG 3 ; délai moyen de liquidation de l'actif 964 jours contre 231 jours pour la sortie d'un porteur | C39: ="Quatre dates plafonnées puis suspension fin 2030 ; sans plafonnement, "&SUBSTITUTE(ROUND(Rupture_cession,1)&"",".",",")&" M€ de cessions secondaires - décisions 1 et 5" -> Quatre dates plafonnées puis suspension fin 2030 ; sans plafonnement, 5,2 M€ de cessions secondaires - décisions 1 et 5 | D39: ="Macquarie, deux fonds fermés dont un non lancé ; score IRP en transparence "&SUBSTITUTE(ROUND(IRPc_Transp,1)&"",".",",")&" sur 100 - décision 4" -> Macquarie, deux fonds fermés dont un non lancé ; score IRP en transparence 62,1 sur 100 - décision 4 | H39: KPI3
B41: SIX DÉCISIONS SOUMISES AU COMITÉ détail en onglet 5 | H41: SEC
B42: N° | C42: Décision | E42: Proposition de la Fonction Risques | G42: Échéance | H42: HDR
B43: 1 | C43: =Dec1 -> Figer le texte de liquidité du prospectus avant dépôt | E43: =DecP1 -> Préavis 91 jours, Demandes Prioritaires, issue après 4 dates, assiette du plafonnement, clause de dépassement passif du plancher de 15 %. | G43: =DecE1 -> Avant le dépôt | H43: ROW
B44: 2 | C44: =Dec2 -> Réintroduire le levier maximal AIFM (100 % engagement et brut) | E44: =DecP2 -> Obligation de l'art. 23 § 1 a) de la directive ; sans emprunt ni dérivé, le niveau est sans coût. | G44: =DecE2 -> Avant le dépôt | H44: ROW
...

Sheet 0 Paramètres
B2: PARAMÈTRES - OPENSTONE INFRAWORLD, COMPARTIMENT I · rapport de risque initial, octobre 2026
B3: Toutes les valeurs du rapport découlent de ce bloc ; aucune autre feuille ne redéfinit un paramètre. Saisies sur fond crème, valeurs dérivées en formules.
B5: Paramètre | C5: Valeur | D5: Unité | E5: Source | F5: Fiabilité | G5: Réserve
B6: FONDS ET DATES
B7: Date d'arrêté du rapport | C7: 46301 | D7: date | E7: Date de l'analyse ; prospectus projet du 30 septembre 2026 | F7: Élevée | G7: Le Fonds n'est pas constitué : rapport initial sur documentation, sans valeur liquidative ni passif.
B8: Date du projet de prospectus | C8: 46295 | D8: date | E8: Prospectus Openstone Infraworld, projet du 30 septembre 2026 | F8: Élevée | G8: Plusieurs mentions restent à compléter (SRI, ISIN A3c, mentions de liquidité).
B9: Actif net cible | C9: 50000000 | D9: euros | E9: Encours cible retenu par la note de liquidité et l'IRP | F9: Moyenne | G9: Prévision commerciale ; les simulations sont rejouées sur l'encours réel une fois le Fonds lancé.
B10: Actif net minimal réglementaire | C10: 300000 | D10: euros | E10: Règlement art. 2 ; dissolution si l'actif reste en deçà 30 jours | F10: Élevée
B11: Seuil de la Date de Déclenchement | C11: 10000000 | D11: euros | E11: Prospectus, définitions du Compartiment I : 10 M€ d'engagements cumulés ou 2e anniversaire | F11: Élevée | G11: Bascule des parts B (conseil 0,57 %) vers le barème des parts A (1,07 %).
B12: Valeur nominale de la part | C12: 100 | D12: euros | E12: Prospectus art. 26.3 - souscription au nominal tant que la VL lui est inférieure | F12: Élevée | G12: Souscription au-dessus de la VL si celle-ci passe sous 100 € : point de traitement équitable (registre, n° 9).
B13: ALLOCATION CIBLE · synthèse Openstone de septembre 2026, non contractuelle
B14: Macquarie Alliance Partners Infrastructure Fund II (MAPIF II) | C14: 0.34 | D14: % AN | E14: Synthèse Openstone septembre 2026, p. 2 | F14: Moyenne | G14: Fonds fermé de secondaires, USD ; conditionné à l'acceptation de la souscription et à la dérogation de ticket (10 M$).
B15: Macquarie Specialized Infrastructure Global 3 (MSIG 3) | C15: 0.17 | D15: % AN | E15: Synthèse Openstone septembre 2026, p. 2 | F15: Moyenne | G15: Fonds de dette fermé hybride ; véhicule (USD / EUR) et manche (levered / unlevered) non arrêtés.
B16: Partners Group Next Generation Infrastructure (PG NGI) | C16: 0.17 | D16: % AN | E16: Synthèse Openstone septembre 2026, p. 2 | F16: Moyenne | G16: Evergreen, devise de référence USD ; classe I ou classe H couverte à arrêter.
B17: Ares Global Infrastructure ELTIF (Ares AGI) | C17: 0.17 | D17: % AN | E17: Synthèse Openstone septembre 2026, p. 2 | F17: Moyenne | G17: Evergreen ELTIF en EUR ; souscription au nominal jusqu'au 01/11/2026 attendu.
B18: Actifs liquides | C18: 0.15 | D18: % AN | E18: Synthèse septembre 2026 ; prospectus art. 21.8 (minimum 15 % de l'actif) | F18: Élevée | G18: Plancher écrit comme obligation permanente, sans clause de dépassement passif (registre, n° 2).
B19: Total de l'allocation | C19: =W_MAPIF+W_MSIG+W_PG+W_ARES+W_LIQ -> 1 | D19: % AN | E19: dérivé | F19: - | G19: Doit boucler à 100 %.
B20: Part des fonds fermés (MAPIF II + MSIG 3) | C20: =W_MAPIF+W_MSIG -> 0.51 | D20: % AN | E20: dérivé | F20: - | G20: Aucune liquidité avant échéance ; sortie par cession secondaire décotée.
B21: Part des fonds evergreen (PG NGI + Ares AGI) | C21: =W_PG+W_ARES -> 0.34 | D21: % AN | E21: dérivé | F21: - | G21: Rachat trimestriel plafonné à 5 % du fonds cible.
B22: Part gérée par Macquarie | C22: =W_MAPIF+W_MSIG -> 0.51 | D22: % AN | E22: dérivé | F22: - | G22: Concentration gérant : 51 % de l'allocation cible chez un seul groupe.
B23: Part libellée en dollars - hypothèse basse (MAPIF II) | C23: =W_MAPIF -> 0.34 | D23: % AN | E23: dérivé | F23: - | G23: Si MSIG 3 est souscrit via le fonds EUR et PG NGI en classe couverte.
B24: Part libellée en dollars - hypothèse haute (MAPIF II + MSIG 3 USD + PG NGI) | C24: =W_MAPIF+W_MSIG+W_PG -> 0.68 | D24: % AN | E24: dérivé | F24: - | G24: Devise de référence de PG NGI : USD (supplément 2) ; MSIG 3 (USD) sans classe EUR.
B25: CONDITIONS DE LIQUIDITÉ DU FONDS · prospectus du 30 septembre 2026
B26: Période de Blocage par souscription | C26: 24 | D26: mois | E26: Prospectus art. 7.2.2 - 2 ans à compter de chaque souscription, imputation FIFO | F26: Élevée
B27: Préavis de rachat | C27: 91 | D27: jours | E27: Prospectus art. 7.2.3 - centralisation le 31 mars pour la VL du 30 juin, le 30 septembre pour celle du 31 décembre | F27: Élevée | G27: La note de liquidité du 24/09 et le classeur de stress tests retiennent 180 jours : à recaler.
B28: Préavis prolongé au plus | C28: 180 | D28: jours | E28: Prospectus art. 7.2.7 - 180 jours calendaires au plus, 12 mois au plus | F28: Élevée
B29: Plafonnement des Rachats par date de centralisation | C29: 0.05 | D29: % AN | E29: Prospectus art. 7.2.6 - 5 % de l'Actif Net, demandes nettes des souscriptions | F29: Élevée | G29: Assiette : actif net de la VL d'exécution, inconnue à l'activation (registre, n° 7).
B30: Reports successifs au plus | C30: 4 | D30: dates | E30: Prospectus art. 7.2.6 - 4 Dates de Centralisation ; Demandes Prioritaires après 2 reports | F30: Élevée | G30: L'issue au-delà de 4 dates n'est pas écrite ; la note de liquidité prévoit l'examen de la suspension.
B31: Délai de règlement des rachats | C31: 35 | D31: j.o. | E31: Prospectus art. 7.2.5 - 5 Jours Ouvrés après publication, publication sous 30 Jours Ouvrés | F31: Élevée
B32: Centralisation des souscriptions avant la VL | C32: 25 | D32: j.o. | E32: Prospectus art. 7.1.2 | F32: Élevée | G32: Paiement intégral à la centralisation ; sommes bloquées hors actif net.
B33: Publication de la valeur liquidative | C33: 30 | D33: j.o. | E33: Prospectus art. 6.2 | F33: Élevée | G33: VL mensuelle au dernier Jour Ouvré du mois.
B34: Plancher d'actifs liquides | C34: 0.15 | D34: % actif | E34: Prospectus art. 21.8 | F34: Élevée | G34: Assiette en actif, les autres limites en actif net (registre, n° 8).
B35: Poche liquide visée par la gestion | C35: 0.16 | D35: % AN | E35: Note de liquidité du 24/09/2026, § 1 | F35: Moyenne
B36: Dont monétaire et dépôts au minimum (règle interne) | C36: 0.05 | D36: % actif | E36: Note de liquidité, § 2 | F36: Moyenne | G36: Règle interne, non opposable.
B37: Plafond de Sur-Engagement | C37: 1.3 | D37: % AN | E37: Prospectus art. 23 ; art. 3.1.1 (engagements hors bilan, 130 %) | F37: Élevée | G37: Deux plafonds à 130 % sans précision de cumul (registre, n° 6).
B38: Emprunts d'espèces | C38: 0 | D38: % AN | E38: Prospectus art. 22 - néant ; ni ligne de crédit ni instrument dérivé | F38: Élevée | G38: Les art. 3.1.1, 14.2 et 25.2.6 supposent encore un emprunt (registre, n° 1).
B39: Levier AIFM, méthode de l'engagement | C39: 1 | D39: % AN | E39: Note de liquidité § 4 ; à réintroduire au prospectus (art. 23 § 1 a) de la directive 2011/61/UE) | F39: Moyenne | G39: Le projet du 30/09 ne mentionne plus de niveau maximal de levier.
B40: Entreprises Cibles (co-investissements directs) | C40: 0.3 | D40: % AN | E40: Prospectus art. 22 | F40: Élevée | G40: Traitement d'un dépassement passif non précisé.
B41: Détention maximale d'une personne physique | C41: 0.1 | D41: % parts | E41: Prospectus art. 5.1 et 8.1 | F41: Élevée | G41: Contrôle à la souscription et au transfert.
B42: FRAIS · prospectus art. 27
...

Sheet 1 Limites
B2: RÉFÉRENTIEL DES LIMITES - OPENSTONE INFRAWORLD, COMPARTIMENT I
B3: Limites du prospectus (projet du 30/09/2026), seuils internes de la note de liquidité et points de contrôle. Statut à la date d'arrêté : le Fonds n'est pas constitué.
B5: Réf. | C5: Limite | D5: Type | E5: Limite | F5: Alerte | G5: Statut | H5: Base et contrôle | I5: Source et commentaire
B6: A. LIMITES DU PROSPECTUS - opposables
B7: IR-01 | C7: Fonds Cibles principalement d'infrastructure | D7: Qualitative | E7: - | F7: - | G7: Non testable | H7: Chaque investissement | I7: Art. 19 et 21.2 ; « principalement », sans seuil chiffré.
B8: IR-03 | C8: Zone : Europe privilégiée, Amérique du Nord et Asie admises | D8: Qualitative | E8: - | F8: - | G8: Non testable | H8: Chaque investissement | I8: Art. 21.2 ; aucun seuil. Allocation cible : environ 80 % Amérique du Nord et Europe par transparence.
B9: IR-04 | C9: Entreprises Cibles (co-investissements directs) | D9: Dure | E9: =Entreprises_max -> 0.3 | F9: =Entreprises_max-0.05 -> 0.25 | G9: Non testable | H9: Actif net, chaque VL | I9: Art. 22 ; traitement d'un dépassement passif non précisé.
B10: IR-06 | C10: Parts de fonds (OPCVM, FIA, fonds étrangers) | D10: Dure | E10: 1 | F10: - | G10: Non testable | H10: Actif net, chaque VL | I10: Art. 22 ; sous le plafond de sur-engagement.
B11: IR-07 | C11: Instruments dérivés | D11: Dure | E11: 0 | F11: - | G11: Paramétré | H11: Pré-négociation | I11: Art. 22 : néant. Exclut toute couverture de change ou de taux.
B12: IR-08 | C12: Actifs immobiliers, acquisitions et cessions temporaires de titres | D12: Dure | E12: 0 | F12: - | G12: Paramétré | H12: Pré-négociation | I12: Art. 22 : néant.
B13: IR-10 | C13: Fonds gérés par la Société de Gestion | D13: Procédure | E13: - | F13: - | G13: Paramétré | H13: Chaque investissement | I13: Art. 21.2 ; politique de conflits d'intérêts à appliquer avant investissement.
B14: RL-01 | C14: Sur-engagement : engagements appelés et non appelés / actif net | D14: Dure | E14: =Surengagement_max -> 1.3 | F14: =S_sureng_orange -> 1.2 | G14: Non testable | H14: Avant chaque engagement et chaque VL | I14: Art. 23 ; dépassement passif toléré sans nouvel engagement.
B15: RL-02 | C15: Plancher d'actifs liquides | D15: Dure | E15: =Liq_min -> 0.15 | F15: =Liq_cible -> 0.16 | G15: Non testable | H15: Actif, chaque VL | I15: Art. 21.8 ; écrit comme obligation permanente, assiette en actif (registre n° 2 et 8).
B16: RL-03 | C16: Engagements hors bilan (garanties, nantissements) | D16: Dure | E16: =Surengagement_max -> 1.3 | F16: - | G16: Paramétré | H16: Actif net | I16: Art. 3.1.1 ; cumul avec RL-01 non précisé (registre n° 6).
B17: RL-04 | C17: Emprunts d'espèces | D17: Dure | E17: =Emprunt_max -> 0 | F17: - | G17: Paramétré | H17: Pré-négociation | I17: Art. 22 : néant ; art. 3.1.1, 14.2 et 25.2.6 à nettoyer (registre n° 1).
B18: RL-05 | C18: Détention par une personne physique | D18: Dure | E18: =Pers_phys_max -> 0.1 | F18: - | G18: Non testable | H18: Parts émises, souscription et transfert | I18: Art. 5.1 et 8.1.
B19: RL-06 | C19: Plafonnement des Rachats par Date de Centralisation | D19: Dure | E19: =Gate -> 0.05 | F19: - | G19: Non testable | H19: Actif net de la VL d'exécution | I19: Art. 7.2.6 ; nette des souscriptions ; 4 reports au plus.
B20: RL-07 | C20: Contreparties : établissements OCDE notés au moins BBB+ | D20: Dure | E20: - | F20: - | G20: Paramétré | H20: À la mise en place | I20: Art. 15 ; revue spécifique sous A-.
B21: B. SEUILS INTERNES - note de liquidité du 24/09/2026, § 5, à valider en Comité des risques
B22: KRI-01 | C22: Demande nette de rachat par date | D22: Interne | E22: 0.1 | F22: 0.05 | G22: À valider | H22: Actif net | I22: Rouge au-delà de 10 % ; orange de 5 à 10 %.
B23: KRI-02 | C23: File d'attente de rachats reportés | D23: Interne | E23: =S_file_rouge -> 0.25 | F23: 0.0001 | G23: À valider | H23: Actif net | I23: Rouge au-delà de 25 % ; orange dès la première file.
B24: KRI-03 | C24: Dates plafonnées consécutives | D24: Interne | E24: =Gate_dates -> 4 | F24: 1 | G24: À valider | H24: Nombre | I24: Au-delà de 4 : suspension examinée.
B25: KRI-04 | C25: Couverture de liquidité à douze mois | D25: Interne | E25: =S_couv_rouge -> 1 | F25: =S_couv_vert -> 1.5 | G25: À valider | H25: Ressources 12 mois / besoins 12 mois | I25: Rouge en deçà de 1,0 ; orange de 1,0 à 1,5.
B26: KRI-05 | C26: Levier, méthode de l'engagement | D26: Interne | E26: =Levier_max -> 1 | F26: - | G26: À valider | H26: Actif net | I26: Niveau maximal à réintroduire au prospectus.
B27: KRI-06 | C27: Premier porteur | D27: Interne | E27: 0.15 | F27: =S_top1_orange -> 0.1 | G27: À valider | H27: Actif net | I27: Rouge au-delà de 15 %.
B28: KRI-07 | C28: Cinq premiers porteurs | D28: Interne | E28: 0.4 | F28: =S_top5_orange -> 0.25 | G28: À valider | H28: Actif net | I28: Rouge au-delà de 40 %.
B29: KRI-08 | C29: Concentration par gérant de fonds cibles | D29: Interne | E29: À arrêter | F29: À arrêter | G29: Seuil à arrêter | H29: Actif net | I29: Aucune limite au prospectus ; 51 % chez Macquarie à l'allocation cible. Proposition : 40 %, alerte 35 %.
B30: KRI-09 | C30: Concentration par fonds cible | D30: Interne | E30: À arrêter | F30: À arrêter | G30: Seuil à arrêter | H30: Actif net | I30: 34 % sur MAPIF II à l'allocation cible. Proposition : 35 %, alerte 30 %.
B31: KRI-10 | C31: Exposition au dollar non couverte | D31: Interne | E31: À arrêter | F31: À arrêter | G31: Seuil à arrêter | H31: Actif net | I31: 34 % à 68 % selon les véhicules retenus ; aucune couverture possible (IR-07).
B32: KRI-11 | C32: Péremption des VL reçues des fonds cibles | D32: Interne | E32: À arrêter | F32: À arrêter | G32: Seuil à arrêter | H32: Jours depuis la VL du fonds cible | I32: VL trimestrielles et décalées pour MAPIF II et MSIG 3 ; mensuelles à 15-21 j.o. pour Ares et PG NGI.
B33: C. SYNTHÈSE
C34: Limites et seuils recensés | D34: =COUNTA(B7:B35) -> 27
C35: Seuils internes à arrêter | D35: =COUNTIF(G7:G35,"Seuil à arrêter") -> 4
C36: Seuils internes à valider | D36: =COUNTIF(G7:G35,"À valider") -> 7
C37: Limites non testables avant lancement | D37: =COUNTIF(G7:G35,"Non testable") -> 8
C38: Franchissements de limite du prospectus | D38: =COUNTIF(G7:G35,"Dépassée") -> 0
B40: Statuts : Paramétré (limite inscrite au dispositif de contrôle, sans position à tester) ; Non testable (nécessite une valeur liquidative ou un registre) ; À valider (seuil interne proposé par la Fonction Risques, non encore arrêté par le Comité) ; Seuil à arrêter (aucune valeur proposée dans les documents) ; Dépassée (franchissement constaté).

Sheet 2 Liquidité
B2: PROFIL DE LIQUIDITÉ À L'ALLOCATION CIBLE - actif, passif, couverture
B3: Délais de liquidation par ligne (classeur de stress tests du 24/09/2026), passif recalculé sur le préavis du prospectus du 30/09/2026 (91 jours). Format Annexe IV.
B5: Ligne | C5: Poids cible | D5: Devise | E5: Délai normal (j) | F5: Délai stress (j) | G5: Rachat au fonds cible | H5: Source et hypothèse
B6: MAPIF II - secondaires, fermé | C6: =W_MAPIF -> 0.34 | D6: USD | E6: 1825 | F6: 1825 | G6: Néant | H6: PPM avril 2026 : aucun retrait ; durée 10 ans + 2 + 2. Sortie par cession agréée par le GP.
B7: MSIG 3 - dette, fermé hybride | C7: =W_MSIG -> 0.17 | D7: USD / EUR | E7: 1825 | F7: 1825 | G7: Annuel, run-off | H7: PPM février 2026 : lock-up 3 ans puis retrait au 31/03 payé par écoulement, sans date.
B8: PG NGI - evergreen | C8: =W_PG -> 0.17 | D8: USD | E8: 100 | F8: 270 | G8: 5 % / trimestre | H8: Supplément 2 : rachat mensuel, préavis 45 j.o., gate 5 % distributions comprises ; Special Dealing à 180 j.
B9: Ares AGI ELTIF - evergreen | C9: =W_ARES -> 0.17 | D9: EUR | E9: 90 | F9: 270 | G9: 5 % / trimestre | H9: Annexe 7 : rachat trimestriel, cut-off 1er j.o. du dernier mois, gate 5 % net, limite ELTIF.
B10: Actifs liquides | C10: =W_LIQ -> 0.15 | D10: EUR | E10: 3 | F10: 7 | G10: Quotidien | H10: Art. 21.8 : monétaire, dépôts, OPC obligataires à VL quotidienne.
B11: Délai moyen pondéré de liquidation de l'actif (TTL actif) | C11: =SUMPRODUCT(C6:C10,E6:E10) -> 963.5 | D11: jours | E11: =SUMPRODUCT(C6:C10,F6:F10) -> 1023.6 | F11: jours (stress)
B13: PASSIF - délai de sortie d'un porteur après la Période de Blocage
B14: Mesure | C14: Jours | H14: Lecture
B15: Règlement après la date de VL (35 j.o.) | C15: =ROUND(Reglement_JO*7/5,0) -> 49 | H15: Art. 7.2.5 : publication sous 30 j.o. puis paiement sous 5 j.o.
B16: Délai minimal de sortie (demande déposée à la centralisation) | C16: =Preavis_j+Reglement_cal -> 140 | H16: Centralisation le 31/03 ou le 30/09 pour la VL semestrielle suivante.
B17: Délai moyen de sortie | C17: =TTL_passif_min+91 -> 231 | H17: Attente moyenne d'une date de centralisation : un trimestre.
B18: Délai maximal de sortie | C18: =TTL_passif_min+182 -> 322 | H18: Demande déposée juste après une centralisation.
B19: Délai moyen avec préavis prolongé (180 jours) | C19: =Preavis_max_j+Reglement_cal+91 -> 320 | H19: Art. 7.2.7 : outil de gestion de la liquidité, 12 mois au plus.
B20: Écart actif - passif (délais moyens) | C20: =TTL_actif-TTL_passif -> 732.5 | H20: Positif : l'actif se liquide bien après la sortie des porteurs ; le plafonnement absorbe l'écart.
B22: ACTIF LIQUIDABLE PAR TRANCHE - format Annexe IV, à l'allocation cible
B23: Tranche de liquidation | C23: % actif | H23: Contenu
B24: 0 à 1 jour | C24: 0 | H24: Néant : la trésorerie est placée en monétaire et dépôts à J+2.
B25: 2 à 7 jours | C25: =W_LIQ -> 0.15 | H25: Actifs liquides (art. 21.8).
B26: 8 à 30 jours | C26: 0 | H26: Néant.
B27: 31 à 90 jours | C27: =W_ARES -> 0.17 | H27: Ares AGI : rachat trimestriel sous gate.
B28: 91 à 180 jours | C28: =W_PG -> 0.17 | H28: PG NGI : préavis de 45 j.o. puis règlement.
B29: 181 à 365 jours | C29: 0 | H29: Néant.
B30: Plus de 365 jours | C30: =W_FERMES -> 0.51 | H30: MAPIF II et MSIG 3 : aucune fenêtre avant échéance.
B31: Total | C31: =SUM(C24:C30) -> 1 | H31: Doit boucler à 100 %.
B33: COUVERTURE DES RACHATS - ratios structurels à l'allocation cible
B34: Indicateur | C34: Valeur | D34: Cible | E34: Statut | H34: Définition
B35: Plafond de rachat annuel (deux dates) | C35: =2*Gate -> 0.1 | H35: Deux Dates de Centralisation par an à 5 % chacune.
B36: Poche liquide / plafond par date | C36: =W_LIQ/Gate -> 3 | D36: 1.5 | E36: =IF(C36>=D36,"Respectée","Surveillance") -> Respectée | H36: La poche cible couvre trois dates de plafond sans autre ressource.
B37: Poche liquide / plafond annuel | C37: =W_LIQ/Gate_annuel -> 1.5 | D37: 1 | E37: =IF(C37>=D37,"Respectée","Surveillance") -> Respectée | H37: Une année de plafond servie sur la seule poche.
B38: Capacité de rachat semestrielle des fonds evergreen | C38: =W_EVER*0.05*2 -> 0.034 | H38: Deux trimestres à 5 % de chaque ligne evergreen, hors gate chez les fonds cibles.
B39: Capacité evergreen / plafond par date | C39: =Cap_evergreen/Gate -> 0.68 | D39: 1 | E39: =IF(C39>=D39,"Respectée","Surveillance") -> Surveillance | H39: Les deux lignes evergreen ne financent pas seules une date de plafond.
B40: Ressources à douze mois / plafond annuel (classeur de stress tests) | C40: 2.96 | D40: 1.5 | E40: =IF(C40>=D40,"Respectée","Surveillance") -> Respectée | H40: Classeur du 24/09/2026 : poche, distributions et rachats evergreen sur 12 mois, départ 30/09/2028.
B41: Couverture de liquidité à douze mois au départ (nette des appels, frais et acomptes) | C41: 2.38 | D41: =S_couv_vert -> 1.5 | E41: =IF(C41>=D41,"Respectée","Surveillance") -> Respectée | H41: Même classeur ; seuil vert 1,5.
B43: Convention TTL : délai complet pour disposer du cash, préavis et règlement compris ; une position sans fenêtre garantie est classée au-delà de 365 jours. Les délais des fonds cibles sont ceux du classeur de stress tests du 24/09/2026 ; le passif est recalculé sur le préavis contractuel du projet du 30/09/2026 (91 jours), là où la note de liquidité retenait 180 jours.

Sheet 3 Scénarios
B2: STRESS TESTS DE LIQUIDITÉ - résultats du classeur du 24/09/2026 et verdicts
B3: Projection trimestrielle sur 36 mois à partir du 30/09/2028, actif net de 50 M€, allocation cible, plafond 5 % par date, 4 dates au plus. Valeurs importées ; verdicts recalculés sur les seuils de la note de liquidité.
B5: Scénario | C5: Dates plaf. | D5: File max | E5: Résorption (mois) | F5: Poche min | G5: Couv. 12 m min | H5: Sur-eng. max | I5: Change max | J5: Cession (M€) | K5: Suspension | L5: Verdict | M5: Lecture
B6: Base : rachats 2 % par date, collecte 5 % par trimestre | C6: 0 | D6: 0 | E6: 0 | F6: 0.1637 | G6: 2.47 | H6: 0.968 | I6: 0.22 | J6: 0 | K6: - | L6: =IF(OR(D6>S_file_rouge,F6<S_poche_rouge,G6<S_couv_rouge,E6>S_resorption_rouge,K6<>"-"),"Rouge",IF(OR(C6>0,F6<Liq_min,G6<S_couv_vert,H6>S_sureng_orange),"Orange","Vert")) -> Vert | M6: Régime de croisière : aucune date plafonnée, poche au-dessus du plancher.
B7: Adverse : rachats de 10 % sur deux dates | C7: 4 | D7: 0.1049 | E7: 24 | F7: 0.0761 | G7: 1.148 | H7: 1.022 | I7: 0.343 | J7: 0 | K7: - | L7: =IF(OR(D7>S_file_rouge,F7<S_poche_rouge,G7<S_couv_rouge,E7>S_resorption_rouge,K7<>"-"),"Rouge",IF(OR(C7>0,F7<Liq_min,G7<S_couv_vert,H7>S_sureng_orange),"Orange","Vert")) -> Orange | M7: Quatre dates plafonnées, file résorbée en 24 mois ; poche sous le plancher pendant la résorption.
B8: Extrême : rachats de 15 % puis 20 % | C8: 4 | D8: 0.2616 | E8: 99 | F8: 0.0761 | G8: 0.683 | H8: 1.022 | I8: 0.342 | J8: 0 | K8: 12/2030 | L8: =IF(OR(D8>S_file_rouge,F8<S_poche_rouge,G8<S_couv_rouge,E8>S_resorption_rouge,K8<>"-"),"Rouge",IF(OR(C8>0,F8<Liq_min,G8<S_couv_vert,H8>S_sureng_orange),"Orange","Vert")) -> Rouge | M8: File de 26 % non résorbée ; suspension examinée à la 5e date (fin 2030).
B9: Concentration : sortie des cinq premiers porteurs (35 %) | C9: 0 | D9: 0 | E9: 0 | F9: 0.158 | G9: 3.69 | H9: 0.978 | I9: 0.289 | J9: 0 | K9: - | L9: =IF(OR(D9>S_file_rouge,F9<S_poche_rouge,G9<S_couv_rouge,E9>S_resorption_rouge,K9<>"-"),"Rouge",IF(OR(C9>0,F9<Liq_min,G9<S_couv_vert,H9>S_sureng_orange),"Orange","Vert")) -> Vert | M9: Servi sous plafonnement ordinaire ; les autres porteurs demandent 2 % par date.
B10: Distributions des fonds cibles divisées par deux et retardées d'un an | C10: 0 | D10: 0 | E10: 0 | F10: 0.1218 | G10: 2.1 | H10: 0.999 | I10: 0.348 | J10: 0 | K10: - | L10: =IF(OR(D10>S_file_rouge,F10<S_poche_rouge,G10<S_couv_rouge,E10>S_resorption_rouge,K10<>"-"),"Rouge",IF(OR(C10>0,F10<Liq_min,G10<S_couv_vert,H10>S_sureng_orange),"Orange","Vert")) -> Orange | M10: Poche entamée par les appels de fonds non compensés.
B11: Appels de fonds accélérés, dollar + 15 % | C11: 0 | D11: 0 | E11: 0 | F11: 0.1323 | G11: 1.99 | H11: 1.005 | I11: 0.358 | J11: 0 | K11: - | L11: =IF(OR(D11>S_file_rouge,F11<S_poche_rouge,G11<S_couv_rouge,E11>S_resorption_rouge,K11<>"-"),"Rouge",IF(OR(C11>0,F11<Liq_min,G11<S_couv_vert,H11>S_sureng_orange),"Orange","Vert")) -> Orange | M11: Appels de MAPIF II renchéris par le dollar ; sur-engagement au-dessus de 100 %.
B12: Valorisation - 20 % (capital), - 10 % (dette), dollar - 15 % | C12: 0 | D12: 0 | E12: 0 | F12: 0.1489 | G12: 2.19 | H12: 0.973 | I12: 0.288 | J12: 0 | K12: - | L12: =IF(OR(D12>S_file_rouge,F12<S_poche_rouge,G12<S_couv_rouge,E12>S_resorption_rouge,K12<>"-"),"Rouge",IF(OR(C12>0,F12<Liq_min,G12<S_couv_vert,H12>S_sureng_orange),"Orange","Vert")) -> Orange | M12: Poche juste sous le plancher par effet de dénominateur.
B13: Crise combinée : chocs de passif et d'actif simultanés | C13: 4 | D13: 0.2609 | E13: 99 | F13: 0 | G13: 0.172 | H13: 1.078 | I13: 0.334 | J13: 6.61 | K13: 12/2030 | L13: =IF(OR(D13>S_file_rouge,F13<S_poche_rouge,G13<S_couv_rouge,E13>S_resorption_rouge,K13<>"-"),"Rouge",IF(OR(C13>0,F13<Liq_min,G13<S_couv_vert,H13>S_sureng_orange),"Orange","Vert")) -> Rouge | M13: Poche épuisée dès 2029, cessions secondaires de 6,6 M€ à 10 % de décote, suspension fin 2030, triple gel dès 12/2028.
B14: Scénarios verts | C14: =COUNTIF(L6:L13,"Vert") -> 2
B15: Scénarios orange | C15: =COUNTIF(L6:L13,"Orange") -> 4
B16: Scénarios rouges | C16: =COUNTIF(L6:L13,"Rouge") -> 2
B17: Résorption « 99 » : file non résorbée à l'horizon de 36 mois. Les scénarios reprennent la note de liquidité § 6 ; le scénario « fonds evergreen au prorata » n'est pas restitué par le tableau de bord du classeur et reste à documenter.
B19: TESTS INVERSÉS
B20: Rachats persistants par date (% AN) | C20: Dates plaf. | D20: Suspension | E20: Poche min (gate) | F20: Cession sans gate (M€) | G20: Décote (M€) | L20: Verdict | M20: Lecture
B21: 0.05 | C21: 0 | D21: - | E21: 0.0338 | F21: 0 | G21: 0 | L21: =IF(OR(D21<>"-",E21<S_poche_rouge),"Rouge",IF(C21>0,"Orange","Vert")) -> Rouge | M21: Demandes égales au plafond : servies sans plafonnement, la poche passe sous 5 % dès la deuxième année.
B22: 0.075 | C22: 4 | D22: 12/2030 | E22: 0.0761 | F22: 5.16 | G22: 0.52 | L22: =IF(OR(D22<>"-",E22<S_poche_rouge),"Rouge",IF(C22>0,"Orange","Vert")) -> Rouge | M22: Point de rupture : quatre dates plafonnées puis suspension ; sans gate, 5,2 M€ de cessions.
B23: 0.1 | C23: 4 | D23: 12/2030 | E23: 0.0761 | F23: 11.58 | G23: 1.16 | L23: =IF(OR(D23<>"-",E23<S_poche_rouge),"Rouge",IF(C23>0,"Orange","Vert")) -> Rouge
B24: 0.125 | C24: 4 | D24: 12/2030 | E24: 0.0761 | F24: 17.31 | G24: 1.73 | L24: =IF(OR(D24<>"-",E24<S_poche_rouge),"Rouge",IF(C24>0,"Orange","Vert")) -> Rouge
B25: 0.15 | C25: 4 | D25: 12/2030 | E25: 0.0761 | F25: 22.33 | G25: 2.23 | L25: =IF(OR(D25<>"-",E25<S_poche_rouge),"Rouge",IF(C25>0,"Orange","Vert")) -> Rouge
B26: Point de rupture (suspension ou cession) | C26: 0.075
B28: Appels de fonds à 12 mois (% AN) | C28: Non-appelé départ | D28: Poche min | E28: Couv. 12 m min | F28: Cession (M€) | L28: Verdict | M28: Lecture
B29: 0.075 | C29: 0.15 | D29: 0.1397 | E29: 2.08 | F29: 0 | L29: =IF(OR(D29<S_poche_rouge,E29<S_couv_rouge),"Rouge",IF(OR(D29<Liq_min,E29<S_couv_vert),"Orange","Vert")) -> Orange
B30: 0.125 | C30: 0.25 | D30: 0.0747 | E30: 1.5 | F30: 0 | L30: =IF(OR(D30<S_poche_rouge,E30<S_couv_rouge),"Rouge",IF(OR(D30<Liq_min,E30<S_couv_vert),"Orange","Vert")) -> Orange | M30: Poche sous le plancher de 15 %.
B31: 0.175 | C31: 0.35 | D31: 0 | E31: 0.93 | F31: 0.68 | L31: =IF(OR(D31<S_poche_rouge,E31<S_couv_rouge),"Rouge",IF(OR(D31<Liq_min,E31<S_couv_vert),"Orange","Vert")) -> Rouge | M31: Poche épuisée, cessions.
B32: 0.225 | C32: 0.45 | D32: 0 | E32: 0.61 | F32: 6.41 | L32: =IF(OR(D32<S_poche_rouge,E32<S_couv_rouge),"Rouge",IF(OR(D32<Liq_min,E32<S_couv_vert),"Orange","Vert")) -> Rouge
B33: 0.45 | C33: 0.45 | D33: 0 | E33: 0.45 | F33: 12.39 | L33: =IF(OR(D33<S_poche_rouge,E33<S_couv_rouge),"Rouge",IF(OR(D33<Liq_min,E33<S_couv_vert),"Orange","Vert")) -> Rouge | M33: Tout le non-appelé tiré en un an.
B34: Point de rupture : poche sous le plancher | C34: 0.125
B36: Sortie d'un porteur unique (% AN) | C36: Dates plaf. | D36: File max | E36: Résorption (mois) | F36: Poche min | G36: Suspension | L36: Verdict | M36: Lecture
B37: 0.1 | C37: 2 | D37: 0.052 | E37: 12 | F37: 0.101 | G37: - | L37: =IF(OR(G37<>"-",E37>S_resorption_rouge),"Rouge",IF(C37>0,"Orange","Vert")) -> Orange
B38: 0.15 | C38: 4 | D38: 0.104 | E38: 24 | F38: 0.0706 | G38: - | L38: =IF(OR(G38<>"-",E38>S_resorption_rouge),"Rouge",IF(C38>0,"Orange","Vert")) -> Orange | M38: Taille maximale sans suspension ni cession.
B39: 0.2 | C39: 4 | D39: 0.156 | E39: 99 | F39: 0.0761 | G39: 12/2030 | L39: =IF(OR(G39<>"-",E39>S_resorption_rouge),"Rouge",IF(C39>0,"Orange","Vert")) -> Rouge
B40: 0.25 | C40: 4 | D40: 0.208 | E40: 99 | F40: 0.0761 | G40: 12/2030 | L40: =IF(OR(G40<>"-",E40>S_resorption_rouge),"Rouge",IF(C40>0,"Orange","Vert")) -> Rouge
B41: Sortie maximale d'un porteur sans suspension | C41: 0.15
B43: Hypothèses du classeur : poche de 15 % au départ, non-appelé 15 % tiré sur trois ans, rachats evergreen à 5 % par trimestre, décote de cession 10 %, frais 2 % par an, acomptes 5 % sur 20 % de parts de distribution, toutes les parts rachetables dès le départ (prudent). Préavis retenu : 180 jours, à recaler sur les 91 jours du projet du 30/09/2026 ; un préavis plus court ne change ni la file ni les verdicts, il réduit le délai d'information de la Société de Gestion avant chaque date.

Sheet 4 Fonds cibles
B2: FONDS CIBLES - conditions contractuelles et profil de risque initial
B3: Lecture des prospectus et PPM (classeur « Openstone underlying funds risk and liquidity terms », 3 septembre 2026) et Initial Risk Profile du 06/10/2026.
B5: Terme | C5: MAPIF II | D5: MSIG 3 (USD) | E5: PG NGI | F5: Ares AGI ELTIF
B6: Dénomination et forme | C6: Macquarie Alliance Partners Infrastructure Fund II SCSp, Luxembourg, non réglementée, FIA fermé | D6: Macquarie Specialized Infrastructure Global 3 (USD) : LP Delaware et SCSp luxembourgeoises, non réglementées | E6: Partners Group Evergreen SICAV, compartiment Next Generation Infrastructure, SICAV Partie II | F6: Ares Global Infrastructure ELTIF, compartiment d'AEFS SICAV, ELTIF agréé CSSF
B7: Stratégie | C7: Secondaires d'infrastructure : LP-led 55-75 %, GP-led 25-45 %, directs et primaires ≤ 5 % | D7: Dette d'infrastructure senior et subordonnée, originée ou acquise, OCDE à 80 % au moins | E7: Infrastructure « next generation » : directs 50-90 %, fonds 10-50 %, liquidités 0-20 % | F7: Infrastructure core, fonds propres et dette, ≥ 70 % d'actifs éligibles ELTIF, ≤ 30 % liquides
B8: Statut à la date d'arrêté | C8: Non opérationnel, blind pool (PPM avril 2026) | D8: Aucun actif, LPA non signés (PPM février 2026) | E8: En activité depuis 2024, seul fonds cible avec portefeuille | F8: Période de souscription initiale, blind pool, fin attendue le 01/11/2026
B9: Devise de référence | C9: USD, catégorie unique | D9: USD ; MSIG 3 (EUR) est un fonds distinct | E9: USD ; classes « H » couvertes sans obligation | F9: EUR
B10: Allocation cible | C10: 34 % | D10: 17 % | E10: 17 % | F10: 17 %
B11: Souscriptions | C11: Closings sur 12 mois (+ 6), appels à 10 j.o. de préavis | D11: Closings sur 2 ans (+ 6 mois), hausses d'engagement semestrielles | E11: Mensuelles, préavis 10 j.o. | F11: Mensuelles, cut-off 15 jours calendaires
B12: Rachats | C12: Aucun ; durée 10 ans + 2 + 2 ; cession agréée par le GP | D12: Annuel au 31/03 après lock-up de 3 ans, préavis 45 jours, payé au run-off (Withdrawing Account), minimum 10 M$ | E12: Mensuels, préavis 45 j.o., règlement 4 j.o. après VL | F12: Trimestriels, cut-off le 1er j.o. du dernier mois, règlement 2 j.o. après publication
B13: Plafonnement | C13: Sans objet | D13: Sans objet ; conversion forcée possible sous 300 M$ de VL | E13: 5 % de la VL par trimestre, distributions et conversions comprises ; Special Dealing à 180 jours, prix discrétionnaire | F13: 5 % de la VL par trimestre (net) et limite ELTIF (27,3 % de l'assiette liquide)
B14: Pénalité de sortie | C14: Sans objet | D14: Aucune ; non-appelé survivant au retrait | E14: Redemption Fee discrétionnaire ≤ 5 % (classe I) et Exit Fee ≤ 5 %, sans butoir de durée | F14: Early Redemption Deduction de 5 % avant 24 mois
B15: Valeur liquidative | C15: Au moins annuelle ; états trimestriels non audités | D15: Trimestrielle, US GAAP, exercice au 31/03, reporting à 30 j.o. | E15: Mensuelle, publiée 21 j.o. après le Dealing Day | F15: Mensuelle, publiée 15 j.o. après la Subscription Date
B16: Frais de gestion | C16: 1,25 % des engagements puis de la VL et du non-appelé | D16: 1,00 % du capital investi, levier compris | E16: 1,25 % de la VL augmentée des engagements non appelés | F16: Jusqu'à 1,25 % de la VL (classe C)
... B22: Prestataires | C22: AIFM Macquarie Asset Management Europe ; dépositaire J.P. Morgan SE ; PwC | D22: AIFM Macquarie Asset Management Credit Advisers US ; administrateur SEI ; aucun dépositaire AIFMD identifié | E22: AIFM Partners Group (Luxembourg) ; dépositaire Northern Trust ; PwC | F22: AIFM Ares Management Luxembourg ; dépositaire BNY Mellon ; EY
B24: INITIAL RISK PROFILE - scores par typologie (score / maximum atteignable), pondération 25 / 30 / 10 / 10 / 15 / 10
B25: Typologie | C25: Fonds (propre) | D25: MAPIF II | E25: MSIG 3 (USD) | F25: PG NGI | G25: Ares AGI ELTIF
B26: Risque de marché | C26: 10 / 13 | D26: 10 / 13 | E26: 11 / 13 | F26: 10 / 13 | G26: 10 / 13
B27: Risque de liquidité | C27: 4 / 4 | D27: 1 / 4 | E27: 3 / 4 | F27: 4 / 4 | G27: 4 / 4
B28: Risque de crédit | C28: 2 / 2 | D28: 0 / 2 | E28: 2 / 2 | F28: 2 / 2 | G28: 2 / 2
B29: Risque de contrepartie | C29: 1 / 6 | D29: 2 / 6 | E29: 4 / 6 | F29: 5 / 6 | G29: 4 / 6
B30: Risque opérationnel | C30: 7 / 10 | D30: 8 / 10 | E30: 8 / 10 | F30: 10 / 10 | G30: 7 / 10
B31: Risque de levier | C31: 0 / 3 | D31: 3 / 3 | E31: 3 / 3 | F31: 3 / 3 | G31: 3 / 3
B32: Score pondéré (0 à 100) | C32: =ROUND(100*(0.25*10/13+0.3*4/4+0.1*2/2+0.1*1/6+0.15*7/10+0.1*0/3),1) -> 71.4 | D32: =ROUND(100*(0.25*10/13+0.3*1/4+0.1*0/2+0.1*2/6+0.15*8/10+0.1*3/3),1) -> 52.1 | E32: =ROUND(100*(0.25*11/13+0.3*3/4+0.1*2/2+0.1*4/6+0.15*8/10+0.1*3/3),1) -> 82.3 | F32: =ROUND(100*(0.25*10/13+0.3*4/4+0.1*2/2+0.1*5/6+0.15*10/10+0.1*3/3),1) -> 92.6 | G32: =ROUND(100*(0.25*10/13+0.3*4/4+0.1*2/2+0.1*4/6+0.15*7/10+0.1*3/3),1) -> 86.4
B33: Notation | C33: =IF(C32>56,"Élevé",IF(C32>34,"Moyen","Faible")) -> Élevé | D33: =IF(D32>56,"Élevé",IF(D32>34,"Moyen","Faible")) -> Moyen | E33: =IF(E32>56,"Élevé",IF(E32>34,"Moyen","Faible")) -> Élevé | F33: =IF(F32>56,"Élevé",IF(F32>34,"Moyen","Faible")) -> Élevé | G33: =IF(G32>56,"Élevé",IF(G32>34,"Moyen","Faible")) -> Élevé
B34: Allocation cible | C34: - | D34: =W_MAPIF -> 0.34 | E34: =W_MSIG -> 0.17 | F34: =W_PG -> 0.17 | G34: =W_ARES -> 0.17
B35: Score en transparence (pondéré par l'allocation, poche liquide à 0) | C35: =ROUND(D34*D32+E34*E32+F34*F32+G34*G32,1) -> 62.1
B36: Score en transparence rebasé hors poche liquide | C36: =ROUND(C35/(1-W_LIQ),1) -> 73.1
B38: Échelle IRP : Faible 0 à 34, Moyen 34 à 56, Élevé 56 à 100. Les scores sont ceux du classeur Initial Risk Profile du 06/10/2026, recalculés ici à partir des scores par typologie ; les notations détaillées et sources figurent dans ce classeur.

Sheet 5 Recommandations
B2: RECOMMANDATIONS DE LA FONCTION RISQUES ET DÉCISIONS SOUMISES AU COMITÉ
B3: Classées par urgence ; chaque recommandation indique l'instance compétente et le délai proposé.
B5: N° | C5: Recommandation | D5: Motif | E5: Instance | F5: Délai
B6: R1 | C6: Recaler la note de liquidité et le classeur de stress tests sur le projet de prospectus du 30/09/2026 | D6: Préavis de 91 jours (centralisation 31/03 et 30/09) et non 180 ; Demandes Prioritaires maintenues à l'art. 7.2.6 ; issue du différé après 4 dates à écrire. | E6: Fonction Risques | F6: Avant le dépôt du prospectus
B7: R2 | C7: Trancher les onze écarts du registre des limites du prospectus | D7: Emprunt interdit mais supposé aux art. 3.1.1, 14.2 et 25.2.6 ; plancher de 15 % permanent sans clause de dépassement passif ; double plafond de 130 % ; assiette du plafonnement ; souscription au nominal ; durée de placement 10 ans contre 8 ans en synthèse ; barème de conseil. | E7: Société de Gestion, Conseiller, Paul Hastings | F7: Avant le dépôt du prospectus
B8: R3 | C8: Réintroduire au prospectus le niveau maximal de levier (brut et engagement) | D8: Art. 23 § 1 a) de la directive 2011/61/UE ; le projet du 30/09 l'a supprimé. Proposition : 100 % en engagement et en brut, trésorerie exclue. | E8: Société de Gestion | F8: Avant le dépôt du prospectus
B9: R4 | C9: Obtenir par écrit les dérogations de ticket minimum de MAPIF II et de MSIG 3 (10 M$ chacun) | D9: À 50 M€ d'encours cible, 34 % et 17 % représentent 17 et 8,5 M€ : l'allocation cible n'est pas constructible sans dérogation. | E9: Conseiller, puis Comité d'investissement | F9: Avant tout engagement
B10: R5 | C10: Arrêter le véhicule et la manche de MSIG 3, et la classe de PG NGI | D10: USD ou EUR ; levered (≈ 350 % de levier, hurdle 8 %) ou unlevered ; classe I ou classe H couverte. Confirmer l'admission d'Openstone Infraworld comme Automatic Withdrawing Investor avant signature. | E10: Comité d'investissement, avis de la Fonction Risques | F10: Avant tout engagement
B11: R6 | C11: Fixer des limites internes de concentration et de change | D11: Gérant unique 40 % de l'actif net (alerte 35 %) ; fonds cible 35 % (alerte 30 %) ; dollar non couvert 40 %. L'allocation cible (Macquarie 51 %, MAPIF II 34 %) devra être justifiée ou revue. | E11: Comité des risques | F11: Prochain comité
B12: R7 | C12: Séquencer les engagements fermés pour que les appels à douze mois restent couverts | D12: Point de rupture du test inversé : appels de 12,5 % de l'actif net sur douze mois (non-appelé de 25 %). Rythme d'engagement et non-appelé plafonné à 15 % de l'actif net à la fin du blocage. | E12: Comité d'investissement | F12: À chaque engagement
B13: R8 | C13: Caler la première fenêtre de rachat sur la fin de la déduction Ares (24 mois) | D13: Un rachat chez Ares avant 24 mois coûte 5 % de la ligne ; la première Date de Centralisation (31/03/2029 pour une constitution fin 2026) doit suivre les 24 mois de détention des parts Ares. | E13: Fonction Risques, gestion de trésorerie | F13: Au lancement
B14: R9 | C14: Écrire la procédure de revue des valeurs liquidatives reçues | D14: Seuil de péremption des VL des fonds cibles (trimestrielles et décalées pour MAPIF II et MSIG 3), contrôle de cohérence, escalade en cas d'écart. Calendrier Annexe IV tenant compte de l'exercice MSIG 3 au 31/03. | E14: Fonction Risques | F14: T4 2026
B15: R10 | C15: Documenter la gestion du conflit d'intérêts du Conseiller | D15: Le Conseiller cumule conseil en investissement, distribution principale et faculté de révoquer la Société de Gestion (art. 3.1.2 à 3.1.5) ; accord préalable requis pour toute modification du prospectus. | E15: Dirigeants effectifs, Conformité | F15: T4 2026
B16: R11 | C16: Compléter le DIC et la synthèse commerciale | D16: SRI 4 à reporter au prospectus et à la synthèse ; durée de détention 10 ans ; commission de rachat « néant » alors que le prospectus mentionne des droits de sortie de 5 % avant 2 ans dans des versions antérieures. | E16: Société de Gestion, Conseiller | F16: Avant la commercialisation
B17: R12 | C17: Rejouer les stress tests sur l'encours réel à chaque arrêté trimestriel et avant chaque décision de plafonnement | D17: Hypothèses du classeur à arrêter en Comité : collecte, non-appelé de départ, décote de cession, part des parts de distribution. | E17: Fonction Risques | F17: Dès la première VL
B19: SIX DÉCISIONS SOUMISES AU COMITÉ DES RISQUES
B20: N° | C20: Décision | D20: Proposition de la Fonction Risques | E20: Recommandations | F20: Instance | G20: Échéance
B21: 1 | C21: Figer le texte de liquidité du prospectus avant dépôt | D21: Préavis 91 jours, Demandes Prioritaires, issue après 4 dates, assiette du plafonnement, clause de dépassement passif du plancher de 15 %. | E21: R1, R2 | F21: Comité des risques puis Société de Gestion et Conseiller | G21: Avant le dépôt
B22: 2 | C22: Réintroduire le levier maximal AIFM (100 % engagement et brut) | D22: Obligation de l'art. 23 § 1 a) de la directive ; sans emprunt ni dérivé, le niveau est sans coût. | E22: R3 | F22: Société de Gestion | G22: Avant le dépôt
B23: 3 | C23: Conditionner tout engagement fermé aux dérogations écrites et aux choix de véhicule | D23: Dérogations de ticket MAPIF II et MSIG 3, confirmation AWI, manche et devise de MSIG 3, classe PG NGI. | E23: R4, R5 | F23: Comité d'investissement | G23: Avant tout engagement
B24: 4 | C24: Arrêter les limites internes KRI-08 à KRI-11 | D24: Gérant 40 %, fonds cible 35 %, dollar non couvert 40 %, péremption des VL à 120 jours pour les fonds fermés. | E24: R6, R9 | F24: Comité des risques | G24: Prochain comité
B25: 5 | C25: Adopter la règle de séquencement des engagements et de la première fenêtre | D25: Appels à douze mois couverts par la poche ; non-appelé ≤ 15 % de l'actif net à la fin du blocage ; première centralisation après 24 mois de détention Ares. | E25: R7, R8 | F25: Comité d'investissement, avis de la Fonction Risques | G25: Au lancement
B26: 6 | C26: Formaliser la gouvernance du Conseiller et la revue des VL reçues | D26: Cartographie du conflit conseil / distribution / révocation ; procédure de revue des VL et calendrier Annexe IV. | E26: R9, R10 | F26: Dirigeants effectifs | G26: T4 2026
B28: Les recommandations R11 et R12 sont suivies par la Fonction Risques sans décision du Comité. Les points entérinés sans débat : échelle de verdict de la charte, convention TTL (positions sans fenêtre garantie au-delà de 365 jours), scénarios de la note de liquidité § 6.

Sheet DATA
B2: SOURCES ET FRAÎCHEUR DES DONNÉES
B3: Chaque source, sa date, son ancienneté à la date d'arrêté et le seuil de péremption retenu.
B5: Source | C5: Date | D5: Ancienneté (j) | E5: Seuil (j) | F5: Statut | G5: Usage dans le rapport
B6: Prospectus et Règlement Openstone Infraworld, projet | C6: 46295 | D6: =DateArrete-C6 -> 6 | E6: 30 | F6: =IF(D6<=E6,"Conforme","Périmée") -> Conforme | G6: Référentiel des limites, conditions de rachat, frais, gouvernance.
B7: Synthèse commerciale Openstone Infraworld v5.4 | C7: 46295 | D7: =DateArrete-C7 -> 6 | E7: 60 | F7: =IF(D7<=E7,"Conforme","Périmée") -> Conforme | G7: Allocation cible, fonds sélectionnés, frais des fonds cibles, objectifs non garantis. Document de pré-commercialisation.
B8: Note de liquidité Openstone Infraworld | C8: 46293 | D8: =DateArrete-C8 -> 8 | E8: 90 | F8: =IF(D8<=E8,"Conforme","Périmée") -> Conforme | G8: Outils de gestion de la liquidité, seuils d'alerte, programme de simulations. Préavis de 180 jours à recaler.
B9: Classeur « Openstone Stress Test liquidité » | C9: 46289 | D9: =DateArrete-C9 -> 12 | E9: 90 | F9: =IF(D9<=E9,"Conforme","Périmée") -> Conforme | G9: Résultats des neuf scénarios et des tests inversés (onglet 3).
B10: Registre des limites du prospectus (25/09/2026) et liste des douze écarts | C10: 46300 | D10: =DateArrete-C10 -> 1 | E10: 30 | F10: =IF(D10<=E10,"Conforme","Périmée") -> Conforme | G10: Onglet 1 et recommandation R2.
B11: Initial Risk Profile Openstone Infraworld et quatre fonds cibles | C11: 46301 | D11: =DateArrete-C11 -> 0 | E11: 90 | F11: =IF(D11<=E11,"Conforme","Périmée") -> Conforme | G11: Scores IRP (onglet 4).
B12: Classeur « Openstone underlying funds risk and liquidity terms » | C12: 46279 | D12: =DateArrete-C12 -> 22 | E12: 90 | F12: =IF(D12<=E12,"Conforme","Périmée") -> Conforme | G12: Conditions des fonds cibles et vingt écarts documentaires (onglet 4).
B13: Documents d'informations clés PRIIPs, parts A1 à B3 | C13: 46294 | D13: =DateArrete-C13 -> 7 | E13: 60 | F13: =IF(D13<=E13,"Conforme","Périmée") -> Conforme | G13: SRI 4, période de détention 10 ans, scénarios de performance, coûts.
B14: Prospectus AEFS SICAV, annexe 7 Ares Global Infrastructure ELTIF | C14: 46245 | D14: =DateArrete-C14 -> 56 | E14: 180 | F14: =IF(D14<=E14,"Conforme","Périmée") -> Conforme | G14: Termes Ares (visa CSSF du 11/08/2026).
B15: Prospectus Partners Group Evergreen SICAV, supplément 2 | C15: 46182 | D15: =DateArrete-C15 -> 119 | E15: 180 | F15: =IF(D15<=E15,"Conforme","Périmée") -> Conforme | G15: Termes PG NGI (visa CSSF du 09/06/2026).
B16: PPM Macquarie Alliance Partners Infrastructure Fund II | C16: 46142 | D16: =DateArrete-C16 -> 159 | E16: 180 | F16: =IF(D16<=E16,"Conforme","Périmée") -> Conforme | G16: Termes MAPIF II ; LPA du 20/03/2026.
B17: PPM Macquarie Specialized Infrastructure Global 3 (USD) | C17: 46081 | D17: =DateArrete-C17 -> 220 | E17: 180 | F17: =IF(D17<=E17,"Conforme","Périmée") -> Périmée | G17: Termes MSIG 3 ; first closing non connu.
B18: Sources périmées | C18: =COUNTIF(F6:F17,"Périmée") -> 1
B19: Sources recensées | C19: =COUNTA(B6:B17) -> 12
B21: Cadre : directive 2011/61/UE art. 15 et 16, modifiée par la directive (UE) 2024/927 (annexe V) ; règlement délégué (UE) 231/2013 art. 38 à 49 ; orientations ESMA 34-39-897 (simulations de crise de liquidité) ; instruction AMF DOC-2017-05 (plafonnement des rachats) ; règlement (UE) 1286/2014 PRIIPs ; art. L. 214-154 et suivants du CMF et 423-27 et suivants du RG AMF.
