Workbook
Name Taux_Constitution: '01_Input'!$F$20
Name Distrib_Global_Classe_Selectionnee: '01_Input'!$F$30
Name ActifNet_Prev_An1: '01_Input'!$F$19
Name Distrib_SousDistrib_Classe_Selectionnee: '01_Input'!$F$31
Name AUM_Max: '01_Input'!$F$12
Name Classes_DistribGlobal: '02_Classes_de_Parts'!$D$7:$D$18
Name Classes_Distribuante: '02_Classes_de_Parts'!$F$7:$F$18
Name AUM_Min: '01_Input'!$F$11
Name Cout_Marginal_Investisseur: '01_Input'!$F$18
Name Nb_KYC_Gratuites_Par_Tranche: '01_Input'!$F$24
Name Seuil_Bareme_T2: '01_Input'!$F$43
Name Nb_Investisseurs: '01_Input'!$F$17
Name Conseil_Taux_T1: '01_Input'!$F$46
Name Majoration_Valorisation: '01_Input'!$F$38
Name Classes_Nom: '02_Classes_de_Parts'!$C$7:$C$18
Name Nb_Categories_Parts: '01_Input'!$F$37
Name Seuil_Bareme_T1: '01_Input'!$F$42
Name Plancher_Constitution: '01_Input'!$F$21
Name Nom_Fonds: '01_Input'!$F$8
Name Frequence_VL: '01_Input'!$F$35
Name Cout_Par_KYC_Supplementaire: '01_Input'!$F$26
Name Jours_Feries_FR: Jours_Feries_FR!$A$2:$A$452
Name AUM_Ladder: '01_Input'!$AS$7:$AS$156
Name Conseil_Taux_T2: '01_Input'!$F$47
Name Nb_Distributions_Par_An: '01_Input'!$F$22
Name Conseil_Taux_T3: '01_Input'!$F$48
Name Cout_Par_Distribution_CAC: '01_Input'!$F$23
Name AUM_Pas: '01_Input'!$F$13
Name Classe_Selectionnee_Distribue: '01_Input'!$F$32
Name Gestion_Taux_T2: '01_Input'!$E$47
Name Classes_DistribSousDistrib: '02_Classes_de_Parts'!$E$7:$E$18
Name Gestion_Taux_T1: '01_Input'!$E$46
Name Gestion_Taux_T3: '01_Input'!$E$48
Name Nb_Lignes_Valorisation: '01_Input'!$F$36
Name Classe_Selectionnee: '01_Input'!$F$29
Name Taille_Tranche_KYC: '01_Input'!$F$25

Sheet 00_Demarrage_Rapide
B1: 00_DÉMARRAGE RAPIDE — Comment utiliser ce classeur en 5 étapes
B2: Pour la méthode de calcul détaillée, les sources documentaires et les hypothèses retenues poste par poste : onglet 06_Documentation. Cet onglet-ci ne couvre que l'essentiel pour démarrer sans se tromper.
B4: 1. Renommez le fonds
C5: 01_Input, §1 "FONDS TESTÉ" — une seule cellule (lime) à remplir.
B7: 2. Fixez l'échelle d'AUM à tester
C8: 01_Input, §2 "ÉCHELLE D'AUM" — AUM minimum, maximum et pas. 04_Recap calculera chaque poste de frais pour tous les paliers de cette échelle, automatiquement.
B10: 3. Remplissez les paramètres et le tableau de frais
C11: 01_Input, §3 à §4 : renseignez les paramètres auxiliaires (§3), les 2 seuils et les 6 taux du tableau "Barèmes de Commissions" (§3D, pour Commission de Gestion et Commission de Conseil), puis une ligne par poste de frais (§4 — "Actif" = Oui/Non). Ne remplissez QUE les cases lime : les cases grises sont verrouillées (barèmes standard Fundcraft ou valeurs pilotées depuis un autre paramètre) et les cases rouges signalent une incohérence à corriger (voir légende en tête de 01_Input).
B13: 4. Vérifiez le résultat
C14: 04_Recap se met à jour automatiquement, ligne par ligne, palier d'AUM par palier d'AUM — aucune saisie supplémentaire n'y est nécessaire.
B16: 5. Réglez le prévisionnel de trésorerie
C17: 05_Tresorerie, §1 : date de lancement du fonds. §2 : AUM mensuel réel/prévisionnel. §3 et suivants : fréquence de facturation par poste (pré-remplie, modifiable). Le prorata du 1er mois et les jours fériés français sont gérés automatiquement.
B19: RAPPEL — CODE COULEUR (identique sur tout le classeur)
B20: lime | C20: cellule à saisir — propre à ce fonds.
B21: gris | C21: cellule verrouillée — barème standard Fundcraft, ou valeur pilotée depuis un autre paramètre. Ne pas modifier.
B22: rouge | C22: incohérence détectée (ex. AUM min ≥ AUM max) — à corriger avant de continuer.

Sheet 01_Input
B1: 01_INPUT — Seule zone de saisie manuelle du classeur
B2: Renseignez ici l'échelle d'AUM à tester et la liste des frais/provisions du fonds. L'onglet 04_Recap se met à jour automatiquement, ligne par ligne, sans aucune autre saisie. L'onglet 02_Classes_de_Parts est optionnel : à utiliser seulement si le fonds a des frais différenciés par classe (§3B et colonne "Mode de calcul" ci-dessous).
B4: Légende : | C4: cellule à saisir | E4: barème standard — ne pas modifier
C5: incohérence détectée — à corriger
AR6: Palier | AS6: AUM (Actif Net)
B7: 1. FONDS TESTÉ | AR7: 1 | AS7: =F11 -> 5000000
B8: Nom du fonds | F8: AF CVC | AR8: 2 | AS8: =IF(AS7="","",IF(AS7+$F$13>$F$12,"",AS7+$F$13)) -> 10000000
AR9: 3 | AS9: =IF(AS8="","",IF(AS8+$F$13>$F$12,"",AS8+$F$13)) -> 15000000
B10: 2. ÉCHELLE D'AUM (axe du Récap — Actif Net du fonds) | AR10: 4 | AS10: =IF(AS9="","",IF(AS9+$F$13>$F$12,"",AS9+$F$13)) -> 20000000
B11: AUM minimum testé (€) | F11: 5000000 | AR11: 5 | AS11: =IF(AS10="","",IF(AS10+$F$13>$F$12,"",AS10+$F$13)) -> 25000000
B12: AUM maximum testé (€) | F12: 50000000 | AR12: 6 | AS12: =IF(AS11="","",IF(AS11+$F$13>$F$12,"",AS11+$F$13)) -> 30000000
B13: Pas / incrément (€) | F13: 5000000 | AR13: 7 | AS13: =IF(AS12="","",IF(AS12+$F$13>$F$12,"",AS12+$F$13)) -> 35000000
B14: Nombre de paliers utilisés / disponibles | F14: =COUNT(AS7:AS156)&" / 150" -> 10 / 150 | AR14: 8 | AS14: =IF(AS13="","",IF(AS13+$F$13>$F$12,"",AS13+$F$13)) -> 40000000
AR15: 9 | AS15: =IF(AS14="","",IF(AS14+$F$13>$F$12,"",AS14+$F$13)) -> 45000000
B16: 3. PARAMÈTRES AUXILIAIRES — utilisés par certaines lignes de frais (formules ci-dessous) | AR16: 10 | AS16: =IF(AS15="","",IF(AS15+$F$13>$F$12,"",AS15+$F$13)) -> 50000000
B17: Nombre d'investisseurs (hypothèse fixe) | F17: 60 | AR17: 11 | AS17: =IF(AS16="","",IF(AS16+$F$13>$F$12,"",AS16+$F$13))
B18: Coût marginal par investisseur, €/an (Tenue du Passif) | F18: 15 | AR18: 12 | AS18: =IF(AS17="","",IF(AS17+$F$13>$F$12,"",AS17+$F$13))
B19: Actif Net prévisionnel au 1er anniversaire, € (Frais de Constitution) | F19: 0 | AR19: 13 | AS19: =IF(AS18="","",IF(AS18+$F$13>$F$12,"",AS18+$F$13))
B20: Taux des Frais de Constitution (%) | F20: 0.01 | AR20: 14 | AS20: =IF(AS19="","",IF(AS19+$F$13>$F$12,"",AS19+$F$13))
B21: Plancher des Frais de Constitution (€) | F21: 60000 | AR21: 15 | AS21: =IF(AS20="","",IF(AS20+$F$13>$F$12,"",AS20+$F$13))
B22: Nombre de distributions par an (Commissaire aux Comptes) | F22: 0 | AR22: 16 | AS22: =IF(AS21="","",IF(AS21+$F$13>$F$12,"",AS21+$F$13))
B23: Coût moyen par distribution, € (Commissaire aux Comptes) | F23: 1600 | AR23: 17 | AS23: =IF(AS22="","",IF(AS22+$F$13>$F$12,"",AS22+$F$13))
B24: Nombre de diligences KYC incluses par tranche (Frais KYC) | F24: 100 | AR24: 18 | AS24: =IF(AS23="","",IF(AS23+$F$13>$F$12,"",AS23+$F$13))
B25: Taille de la tranche d'AUM pour le renouvellement du forfait KYC, € (Frais KYC) | F25: 100000000 | AR25: 19 | AS25: =IF(AS24="","",IF(AS24+$F$13>$F$12,"",AS24+$F$13))
B26: Coût par diligence KYC supplémentaire, € (Frais KYC) | F26: 10 | AR26: 20 | AS26: =IF(AS25="","",IF(AS25+$F$13>$F$12,"",AS25+$F$13))
AR27: 21 | AS27: =IF(AS26="","",IF(AS26+$F$13>$F$12,"",AS26+$F$13))
B28: 3B. CLASSE DE PARTS SÉLECTIONNÉE (optionnel — voir 02_Classes_de_Parts) | AR28: 22 | AS28: =IF(AS27="","",IF(AS27+$F$13>$F$12,"",AS27+$F$13))
B29: Classe de parts sélectionnée pour le calcul de 04_Recap | F29: A | AR29: 23 | AS29: =IF(AS28="","",IF(AS28+$F$13>$F$12,"",AS28+$F$13))
B30: → Taux Distributeur Global de cette classe (calculé) | F30: {=IFERROR(INDEX(Classes_DistribGlobal,MATCH($F$29,Classes_Nom,0)),0)} -> 0.001 | AR30: 24 | AS30: =IF(AS29="","",IF(AS29+$F$13>$F$12,"",AS29+$F$13))
B31: → Taux Sous-distributeurs de cette classe (calculé) | F31: {=IFERROR(INDEX(Classes_DistribSousDistrib,MATCH($F$29,Classes_Nom,0)),0)} -> 0.009 | AR31: 25 | AS31: =IF(AS30="","",IF(AS30+$F$13>$F$12,"",AS30+$F$13))
B32: → Cette classe distribue-t-elle ? (calculé) | F32: {=IFERROR(INDEX(Classes_Distribuante,MATCH($F$29,Classes_Nom,0)),"Non")} -> Non | AR32: 26 | AS32: =IF(AS31="","",IF(AS31+$F$13>$F$12,"",AS31+$F$13))
AR33: 27 | AS33: =IF(AS32="","",IF(AS32+$F$13>$F$12,"",AS32+$F$13))
B34: 3C. PARAMÈTRES VALORISATION (CIC) — utilisés par la ligne "Valorisation (CIC)" | AR34: 28 | AS34: =IF(AS33="","",IF(AS33+$F$13>$F$12,"",AS33+$F$13))
B35: Fréquence de la VL (Mensuelle / Bi-mensuelle) | F35: Mensuelle | AR35: 29 | AS35: =IF(AS34="","",IF(AS34+$F$13>$F$12,"",AS34+$F$13))
B36: Nombre de lignes du portefeuille (valorisation) | F36: 2 | AR36: 30 | AS36: =IF(AS35="","",IF(AS35+$F$13>$F$12,"",AS35+$F$13))
B37: → Nombre de catégories de parts du fonds (déduit de 02_Classes_de_Parts) | F37: =COUNTIF(Classes_Nom,"<>") -> 2 | AR37: 31 | AS37: =IF(AS36="","",IF(AS36+$F$13>$F$12,"",AS36+$F$13))
B38: → Majoration applicable (calculée) | F38: =IF(F37>=5,0.15,IF(F37>=3,0.1,0)) -> 0 | AR38: 32 | AS38: =IF(AS37="","",IF(AS37+$F$13>$F$12,"",AS37+$F$13))
AR39: 33 | AS39: =IF(AS38="","",IF(AS38+$F$13>$F$12,"",AS38+$F$13))
B40: 3D. BARÈMES DE COMMISSIONS (Commission de Gestion + Commission de Conseil) | AR40: 34 | AS40: =IF(AS39="","",IF(AS39+$F$13>$F$12,"",AS39+$F$13))
B41: UN SEUL TABLEAU pour saisir les 2 commissions calculées par barème (Commission de Gestion, Commission de Conseil) : les 2 seuils et les 6 taux ci-dessous se répercutent automatiquement dans le tableau large du §4 (cases grisées, non éditables — à titre de contrôle visuel seulement) ainsi que dans 04_Recap et 05_Tresorerie. Décision du 14/09/2026 suite à un retour utilisateur : éviter d'avoir à modifier le tableau large (source d'erreur) — ne changez les taux ou les seuils de ces 2 commissions qu'ICI. | AR41: 35 | AS41: =IF(AS40="","",IF(AS40+$F$13>$F$12,"",AS40+$F$13))
...

Sheet 02_Classes_de_Parts
B1: 02_CLASSES DE PARTS — Optionnel — uniquement pour un fonds à frais différenciés par classe
B2: N'est utilisé par 01_Input / 04_Recap QUE pour les postes de frais dont le "Mode de calcul" (colonne du tableau de frais en 01_Input) est "Taux Classe sélectionnée" — ex. les 2 lignes de Commission de Distribution (Distributeur Global / Sous-distributeurs), qui varient par classe de parts. Si votre fonds n'a pas ce mécanisme, laissez cet onglet inutilisé et gardez tous les postes de 01_Input en mode "Barème". Sert aussi à déduire automatiquement le nombre de catégories de parts du fonds (01_Input §3C).
B4: Dans 01_Input, vous choisissez UNE classe — celle sur laquelle 04_Recap calcule le détail. Un poste en mode "Taux Classe sélectionnée" = Taux de cette classe x AUM. Détail de la méthode et des sources : onglet 06_Documentation.
C6: Nom de la classe | D6: Taux Distributeur Global | E6: Taux Sous- distributeurs | F6: Distribuante ? | G6: Commentaire / Source
C7: A | D7: 0.001 | E7: 0.009 | F7: Non
C8: B | D8: 0.001 | E8: 0 | F8: Non
D9: 0 | E9: 0 | F9: Non
D10: 0 | E10: 0 | F10: Non
D11: 0 | E11: 0 | F11: Non
D12: 0 | E12: 0 | F12: Non
D13: 0 | E13: 0 | F13: Non
D14: 0 | E14: 0 | F14: Non
D15: 0 | E15: 0 | F15: Non
D16: 0 | E16: 0 | F16: Non
D17: 0 | E17: 0 | F17: Non
D18: 0 | E18: 0 | F18: Non
B21: Lignes libres : ajoutez une classe en renseignant une ligne vide (jusqu'à 12 classes disponibles). Une ligne dont le nom est vide est ignorée par le sélecteur de 01_Input.

Sheet 03_Detail_Depositaire_Valo
B1: 03_DÉTAIL DÉPOSITAIRE / VALORISATION — Zéro saisie manuelle — décompose pas à pas 2 postes de 01_Input dont le calcul n'est pas un simple taux
B2: "Commission Dépositaire (BFCM)" (taux + plancher + PLAFOND) et "Valorisation (CIC)" (barème par tranche d'actif, fréquence de VL, majoration par nombre de catégories de parts, supplément lignes de portefeuille) sont les 2 postes les moins immédiats à lire directement dans le tableau de 01_Input. Cet onglet réexplique chaque paramètre, puis reconstitue le calcul complet sur toute l'échelle d'AUM testée — les lignes "Écart vs 04_Recap" prouvent que ce détail correspond exactement (doit toujours afficher 0).
B5: Zéro saisie manuelle : reconstitue pas à pas le calcul des 2 postes les moins immédiats à lire en 01_Input (Dépositaire, Valorisation). Détail de la méthode et des sources : onglet 06_Documentation.
B7: PARAMÈTRES ACTIFS (repris de 01_Input — rien à saisir ici)
B8: Commission Dépositaire (BFCM)
B9: Taux appliqué | C9: ='01_Input'!$M$57 -> 0.0003
B10: Plancher annuel | C10: ='01_Input'!$H$57 -> 12000
B11: Plafond annuel | C11: ='01_Input'!$I$57 -> 50000
B13: Valorisation (CIC)
B14: Fréquence de VL retenue | C14: =Frequence_VL -> Mensuelle
B15: Nombre de lignes du portefeuille | C15: =Nb_Lignes_Valorisation -> 2
B16: Nombre de catégories de parts | C16: =Nb_Categories_Parts -> 2
B17: Majoration applicable | C17: =Majoration_Valorisation -> 0
B20: DÉTAIL DU CALCUL SUR L'ÉCHELLE D'AUM TESTÉE (01_Input §2)
B21: Étape de calcul | E21: {=INDEX(AUM_Ladder,1)} -> 5000000 | F21: {=INDEX(AUM_Ladder,2)} -> 10000000 | G21: {=INDEX(AUM_Ladder,3)} -> 15000000 | H21: {=INDEX(AUM_Ladder,4)} -> 20000000 | I21: {=INDEX(AUM_Ladder,5)} -> 25000000 | J21: {=INDEX(AUM_Ladder,6)} -> 30000000 | K21: {=INDEX(AUM_Ladder,7)} -> 35000000 | L21: {=INDEX(AUM_Ladder,8)} -> 40000000 | M21: {=INDEX(AUM_Ladder,9)} -> 45000000 | N21: {=INDEX(AUM_Ladder,10)} -> 50000000 | O21: {=INDEX(AUM_Ladder,11)} | P21: {=INDEX(AUM_Ladder,12)} | Q21: {=INDEX(AUM_Ladder,13)} | R21: {=INDEX(AUM_Ladder,14)} | S21: {=INDEX(AUM_Ladder,15)} | T21: {=INDEX(AUM_Ladder,16)} | U21: {=INDEX(AUM_Ladder,17)} | V21: {=INDEX(AUM_Ladder,18)} | W21: {=INDEX(AUM_Ladder,19)} | X21: {=INDEX(AUM_Ladder,20)} | Y21: {=INDEX(AUM_Ladder,21)} | Z21: {=INDEX(AUM_Ladder,22)} | AA21: {=INDEX(AUM_Ladder,23)} | AB21: {=INDEX(AUM_Ladder,24)} | AC21: {=INDEX(AUM_Ladder,25)} | AD21: {=INDEX(AUM_Ladder,26)} | AE21: {=INDEX(AUM_Ladder,27)} | AF21: {=INDEX(AUM_Ladder,28)} | AG21: {=INDEX(AUM_Ladder,29)} | AH21: {=INDEX(AUM_Ladder,30)} | AI21: {=INDEX(AUM_Ladder,31)} | AJ21: {=INDEX(AUM_Ladder,32)} | AK21: {=INDEX(AUM_Ladder,33)} | AL21: {=INDEX(AUM_Ladder,34)} | AM21: {=INDEX(AUM_Ladder,35)} | AN21: {=INDEX(AUM_Ladder,36)} | AO21: {=INDEX(AUM_Ladder,37)} | AP21: {=INDEX(AUM_Ladder,38)} | AQ21: {=INDEX(AUM_Ladder,39)} | AR21: {=INDEX(AUM_Ladder,40)} | AS21: {=INDEX(AUM_Ladder,41)} | AT21: {=INDEX(AUM_Ladder,42)} | AU21: {=INDEX(AUM_Ladder,43)} | AV21: {=INDEX(AUM_Ladder,44)} | AW21: {=INDEX(AUM_Ladder,45)} | AX21: {=INDEX(AUM_Ladder,46)} | AY21: {=INDEX(AUM_Ladder,47)} | AZ21: {=INDEX(AUM_Ladder,48)} | BA21: {=INDEX(AUM_Ladder,49)} | BB21: {=INDEX(AUM_Ladder,50)} | BC21: {=INDEX(AUM_Ladder,51)} | BD21: {=INDEX(AUM_Ladder,52)} | BE21: {=INDEX(AUM_Ladder,53)} | BF21: {=INDEX(AUM_Ladder,54)} | BG21: {=INDEX(AUM_Ladder,55)} | BH21: {=INDEX(AUM_Ladder,56)} | BI21: {=INDEX(AUM_Ladder,57)} | BJ21: {=INDEX(AUM_Ladder,58)} | BK21: {=INDEX(AUM_Ladder,59)} | BL21: {=INDEX(AUM_Ladder,60)} | BM21: {=INDEX(AUM_Ladder,61)} | BN21: {=INDEX(AUM_Ladder,62)} | BO21: {=INDEX(AUM_Ladder,63)} | BP21: {=INDEX(AUM_Ladder,64)} | BQ21: {=INDEX(AUM_Ladder,65)} | BR21: {=INDEX(AUM_Ladder,66)} | BS21: {=INDEX(AUM_Ladder,67)} | BT21: {=INDEX(AUM_Ladder,68)} | BU21: {=INDEX(AUM_Ladder,69)} | BV21: {=INDEX(AUM_Ladder,70)} | BW21: {=INDEX(AUM_Ladder,71)} | BX21: {=INDEX(AUM_Ladder,72)} | BY21: {=INDEX(AUM_Ladder,73)} | BZ21: {=INDEX(AUM_Ladder,74)} | CA21: {=INDEX(AUM_Ladder,75)} | CB21: {=INDEX(AUM_Ladder,76)} | CC21: {=INDEX(AUM_Ladder,77)} | CD21: {=INDEX(AUM_Ladder,78)} | CE21: {=INDEX(AUM_Ladder,79)} | CF21: {=INDEX(AUM_Ladder,80)} | CG21: {=INDEX(AUM_Ladder,81)} | CH21: {=INDEX(AUM_Ladder,82)} | CI21: {=INDEX(AUM_Ladder,83)} | CJ21: {=INDEX(AUM_Ladder,84)} | CK21: {=INDEX(AUM_Ladder,85)} | CL21: {=INDEX(AUM_Ladder,86)} | CM21: {=INDEX(AUM_Ladder,87)} | CN21: {=INDEX(AUM_Ladder,88)} | CO21: {=INDEX(AUM_Ladder,89)} | CP21: {=INDEX(AUM_Ladder,90)} | CQ21: {=INDEX(AUM_Ladder,91)} | CR21: {=INDEX(AUM_Ladder,92)} | CS21: {=INDEX(AUM_Ladder,93)} | CT21: {=INDEX(AUM_Ladder,94)} | CU21: {=INDEX(AUM_Ladder,95)} | CV21: {=INDEX(AUM_Ladder,96)} | CW21: {=INDEX(AUM_Ladder,97)} | CX21: {=INDEX(AUM_Ladder,98)} | CY21: {=INDEX(AUM_Ladder,99)} | CZ21: {=INDEX(AUM_Ladder,100)} | DA21: {=INDEX(AUM_Ladder,101)} | DB21: {=INDEX(AUM_Ladder,102)} | DC21: {=INDEX(AUM_Ladder,103)} | DD21: {=INDEX(AUM_Ladder,104)} | DE21: {=INDEX(AUM_Ladder,105)} | DF21: {=INDEX(AUM_Ladder,106)} | DG21: {=INDEX(AUM_Ladder,107)} | DH21: {=INDEX(AUM_Ladder,108)} | DI21: {=INDEX(AUM_Ladder,109)} | DJ21: {=INDEX(AUM_Ladder,110)} | DK21: {=INDEX(AUM_Ladder,111)} | DL21: {=INDEX(AUM_Ladder,112)} | DM21: {=INDEX(AUM_Ladder,113)} | DN21: {=INDEX(AUM_Ladder,114)} | DO21: {=INDEX(AUM_Ladder,115)} | DP21: {=INDEX(AUM_Ladder,116)} | DQ21: {=INDEX(AUM_Ladder,117)} | DR21: {=INDEX(AUM_Ladder,118)} | DS21: {=INDEX(AUM_Ladder,119)} | DT21: {=INDEX(AUM_Ladder,120)} | DU21: {=INDEX(AUM_Ladder,121)} | DV21: {=INDEX(AUM_Ladder,122)} | DW21: {=INDEX(AUM_Ladder,123)} | DX21: {=INDEX(AUM_Ladder,124)} | DY21: {=INDEX(AUM_Ladder,125)} | DZ21: {=INDEX(AUM_Ladder,126)} | EA21: {=INDEX(AUM_Ladder,127)} | EB21: {=INDEX(AUM_Ladder,128)} | EC21: {=INDEX(AUM_Ladder,129)} | ED21: {=INDEX(AUM_Ladder,130)} | EE21: {=INDEX(AUM_Ladder,131)} | EF21: {=INDEX(AUM_Ladder,132)} | EG21: {=INDEX(AUM_Ladder,133)} | EH21: {=INDEX(AUM_Ladder,134)} | EI21: {=INDEX(AUM_Ladder,135)} | EJ21: {=INDEX(AUM_Ladder,136)} | EK21: {=INDEX(AUM_Ladder,137)} | EL21: {=INDEX(AUM_Ladder,138)} | EM21: {=INDEX(AUM_Ladder,139)} | EN21: {=INDEX(AUM_Ladder,140)} | EO21: {=INDEX(AUM_Ladder,141)} | EP21: {=INDEX(AUM_Ladder,142)} | EQ21: {=INDEX(AUM_Ladder,143)} | ER21: {=INDEX(AUM_Ladder,144)} | ES21: {=INDEX(AUM_Ladder,145)} | ET21: {=INDEX(AUM_Ladder,146)} | EU21: {=INDEX(AUM_Ladder,147)} | EV21: {=INDEX(AUM_Ladder,148)} | EW21: {=INDEX(AUM_Ladder,149)} | EX21: {=INDEX(AUM_Ladder,150)}
B22: — COMMISSION DÉPOSITAIRE (BFCM) —
B23: Taux appliqué (%) | E23: ='01_Input'!$M$57 -> 0.0003 | F23: ='01_Input'!$M$57 -> 0.0003 | G23: ='01_Input'!$M$57 -> 0.0003 | H23: ='01_Input'!$M$57 -> 0.0003 | I23: ='01_Input'!$M$57 -> 0.0003 | J23: ='01_Input'!$M$57 -> 0.0003 | K23: ='01_Input'!$M$57 -> 0.0003 | L23: ='01_Input'!$M$57 -> 0.0003 | ... EX23: ='01_Input'!$M$57 -> 0.0003
B24: Montant théorique = Taux x AUM (€) | E24: =E$21*E23 -> 1500 | F24: =F$21*F23 -> 3000 | G24: =G$21*G23 -> 4500 | H24: =H$21*H23 -> 6000 | I24: =I$21*I23 -> 7500 | J24: =J$21*J23 -> 9000 | K24: =K$21*K23 -> 10500 | L24: =L$21*L23 -> 12000 | ... EX24: =EX$21*EX23 -> 0
B25: Plancher annuel (€) | E25: ='01_Input'!$H$57 -> 12000 | F25: ='01_Input'!$H$57 -> 12000 | G25: ='01_Input'!$H$57 -> 12000 | H25: ='01_Input'!$H$57 -> 12000 | I25: ='01_Input'!$H$57 -> 12000 | J25: ='01_Input'!$H$57 -> 12000 | K25: ='01_Input'!$H$57 -> 12000 | L25: ='01_Input'!$H$57 -> 12000 | ... EX25: ='01_Input'!$H$57 -> 12000
B26: Plafond annuel (€) | E26: ='01_Input'!$I$57 -> 50000 | F26: ='01_Input'!$I$57 -> 50000 | G26: ='01_Input'!$I$57 -> 50000 | H26: ='01_Input'!$I$57 -> 50000 | I26: ='01_Input'!$I$57 -> 50000 | J26: ='01_Input'!$I$57 -> 50000 | K26: ='01_Input'!$I$57 -> 50000 | L26: ='01_Input'!$I$57 -> 50000 | ... EX26: ='01_Input'!$I$57 -> 50000
B27: Mécanisme retenu | E27: =IF(E24<E25,"Plancher (min.)",IF(E24>E26,"Plafond (max.)","Barème (plein)")) -> Plancher (min.) | F27: =IF(F24<F25,"Plancher (min.)",IF(F24>F26,"Plafond (max.)","Barème (plein)")) -> Plancher (min.) | G27: =IF(G24<G25,"Plancher (min.)",IF(G24>G26,"Plafond (max.)","Barème (plein)")) -> Plancher (min.) | H27: =IF(H24<H25,"Plancher (min.)",IF(H24>H26,"Plafond (max.)","Barème (plein)")) -> Plancher (min.) | I27: =IF(I24<I25,"Plancher (min.)",IF(I24>I26,"Plafond (max.)","Barème (plein)")) -> Plancher (min.) | J27: =IF(J24<J25,"Plancher (min.)",IF(J24>J26,"Plafond (max.)","Barème (plein)")) -> Plancher (min.) | K27: =IF(K24<K25,"Plancher (min.)",IF(K24>K26,"Plafond (max.)","Barème (plein)")) -> Plancher (min.) | L27: =IF(L24<L25,"Plancher (min.)",IF(L24>L26,"Plafond (max.)","Barème (plein)")) -> Barème (plein) | ... EX27: =IF(EX24<EX25,"Plancher (min.)",IF(EX24>EX26,"Plafond (max.)","Barème (plein)")) -> Plancher (min.)
B28: → Commission Dépositaire retenue (€) | E28: =MIN(E26,MAX(E25,E24)) -> 12000 | F28: =MIN(F26,MAX(F25,F24)) -> 12000 | G28: =MIN(G26,MAX(G25,G24)) -> 12000 | H28: =MIN(H26,MAX(H25,H24)) -> 12000 | I28: =MIN(I26,MAX(I25,I24)) -> 12000 | J28: =MIN(J26,MAX(J25,J24)) -> 12000 | K28: =MIN(K26,MAX(K25,K24)) -> 12000 | L28: =MIN(L26,MAX(L25,L24)) -> 12000 | ... EX28: =MIN(EX26,MAX(EX25,EX24)) -> 12000
B29: Écart vs 04_Recap (doit être 0) | E29: =ROUND(E28-'04_Recap'!E25,2) -> 0 | F29: =ROUND(F28-'04_Recap'!F25,2) -> 0 | G29: =ROUND(G28-'04_Recap'!G25,2) -> 0 | H29: =ROUND(H28-'04_Recap'!H25,2) -> 0 | I29: =ROUND(I28-'04_Recap'!I25,2) -> 0 | J29: =ROUND(J28-'04_Recap'!J25,2) -> 0 | K29: =ROUND(K28-'04_Recap'!K25,2) -> 0 | L29: =ROUND(L28-'04_Recap'!L25,2) -> 0 | ... EX29: =ROUND(EX28-'04_Recap'!EX25,2) -> -38000
B31: — VALORISATION (CIC) —
B32: Fréquence de VL retenue | E32: =Frequence_VL -> Mensuelle | F32: =Frequence_VL -> Mensuelle | G32: =Frequence_VL -> Mensuelle | H32: =Frequence_VL -> Mensuelle | I32: =Frequence_VL -> Mensuelle | J32: =Frequence_VL -> Mensuelle | K32: =Frequence_VL -> Mensuelle | L32: =Frequence_VL -> Mensuelle | ... EX32: =Frequence_VL -> Mensuelle
B33: Tranche d'actif atteinte | E33: =IF(E$21<'01_Input'!$K$61,"0 - "&TEXT('01_Input'!$K$61/1000000,"0")&"M€",IF(E$21<'01_Input'!$O$61,TEXT('01_Input'!$K$61/1000000,"0")&" - "&TEXT('01_Input'!$O$61/1000000,"0")&"M€",IF(E$21<'01_Input'!$S$61,TEXT('01_Input'!$O$61/1000000,"0")&" - "&TEXT('01_Input'!$S$61/1000000,"0")&"M€","> "&TEXT('01_Input'!$S$61/1000000,"0")&"M€"))) -> 0 - 40M€ | F33: =IF(F$21<'01_Input'!$K$61,"0 - "&TEXT('01_Input'!$K$61/1000000,"0")&"M€",IF(F$21<'01_Input'!$O$61,TEXT('01_Input'!$K$61/1000000,"0")&" - "&TEXT('01_Input'!$O$61/1000000,"0")&"M€",IF(F$21<'01_Input'!$S$61,TEXT('01_Input'!$O$61/1000000,"0")&" - "&TEXT('01_Input'!$S$61/1000000,"0")&"M€","> "&TEXT('01_Input'!$S$61/1000000,"0")&"M€"))) -> 0 - 40M€ | G33: =IF(G$21<'01_Input'!$K$61,"0 - "&TEXT('01_Input'!$K$61/1000000,"0")&"M€",IF(G$21<'01_Input'!$O$61,TEXT('01_Input'!$K$61/1000000,"0")&" - "&TEXT('01_Input'!$O$61/1000000,"0")&"M€",IF(G$21<'01_Input'!$S$61,TEXT('01_Input'!$O$61/1000000,"0")&" - "&TEXT('01_Input'!$S$61/1000000,"0")&"M€","> "&TEXT('01_Input'!$S$61/1000000,"0")&"M€"))) -> 0 - 40M€ | H33: =IF(H$21<'01_Input'!$K$61,"0 - "&TEXT('01_Input'!$K$61/1000000,"0")&"M€",IF(H$21<'01_Input'!$O$61,TEXT('01_Input'!$K$61/1000000,"0")&" - "&TEXT('01_Input'!$O$61/1000000,"0")&"M€",IF(H$21<'01_Input'!$S$61,TEXT('01_Input'!$O$61/1000000,"0")&" - "&TEXT('01_Input'!$S$61/1000000,"0")&"M€","> "&TEXT('01_Input'!$S$61/1000000,"0")&"M€"))) -> 0 - 40M€ | I33: =IF(I$21<'01_Input'!$K$61,"0 - "&TEXT('01_Input'!$K$61/1000000,"0")&"M€",IF(I$21<'01_Input'!$O$61,TEXT('01_Input'!$K$61/1000000,"0")&" - "&TEXT('01_Input'!$O$61/1000000,"0")&"M€",IF(I$21<'01_Input'!$S$61,TEXT('01_Input'!$O$61/1000000,"0")&" - "&TEXT('01_Input'!$S$61/1000000,"0")&"M€","> "&TEXT('01_Input'!$S$61/1000000,"0")&"M€"))) -> 0 - 40M€ | J33: =IF(J$21<'01_Input'!$K$61,"0 - "&TEXT('01_Input'!$K$61/1000000,"0")&"M€",IF(J$21<'01_Input'!$O$61,TEXT('01_Input'!$K$61/1000000,"0")&" - "&TEXT('01_Input'!$O$61/1000000,"0")&"M€",IF(J$21<'01_Input'!$S$61,TEXT('01_Input'!$O$61/1000000,"0")&" - "&TEXT('01_Input'!$S$61/1000000,"0")&"M€","> "&TEXT('01_Input'!$S$61/1000000,"0")&"M€"))) -> 0 - 40M€ | K33: =IF(K$21<'01_Input'!$K$61,"0 - "&TEXT('01_Input'!$K$61/1000000,"0")&"M€",IF(K$21<'01_Input'!$O$61,TEXT('01_Input'!$K$61/1000000,"0")&" - "&TEXT('01_Input'!$O$61/1000000,"0")&"M€",IF(K$21<'01_Input'!$S$61,TEXT('01_Input'!$O$61/1000000,"0")&" - "&TEXT('01_Input'!$S$61/1000000,"0")&"M€","> "&TEXT('01_Input'!$S$61/1000000,"0")&"M€"))) -> 0 - 40M€ | L33: =IF(L$21<'01_Input'!$K$61,"0 - "&TEXT('01_Input'!$K$61/1000000,"0")&"M€",IF(L$21<'01_Input'!$O$61,TEXT('01_Input'!$K$61/1000000,"0")&" - "&TEXT('01_Input'!$O$61/1000000,"0")&"M€",IF(L$21<'01_Input'!$S$61,TEXT('01_Input'!$O$61/1000000,"0")&" - "&TEXT('01_Input'!$S$61/1000000,"0")&"M€","> "&TEXT('01_Input'!$S$61/1000000,"0")&"M€"))) -> 40 - 80M€ | ... EX33: =IF(EX$21<'01_Input'!$K$61,"0 - "&TEXT('01_Input'!$K$61/1000000,"0")&"M€",IF(EX$21<'01_Input'!$O$61,TEXT('01_Input'!$K$61/1000000,"0")&" - "&TEXT('01_Input'!$O$61/1000000,"0")&"M€",IF(EX$21<'01_Input'!$S$61,TEXT('01_Input'!$O$61/1000000,"0")&" - "&TEXT('01_Input'!$S$61/1000000,"0")&"M€","> "&TEXT('01_Input'!$S$61/1000000,"0")&"M€"))) -> > 120M€
B34: Montant de la tranche (majoration incluse) (€) | E34: =IF(E$21<'01_Input'!$K$61,'01_Input'!$M$61,IF(E$21<'01_Input'!$O$61,'01_Input'!$Q$61,IF(E$21<'01_Input'!$S$61,'01_Input'!$U$61,'01_Input'!$Y$61))) -> 12000 | F34: =IF(F$21<'01_Input'!$K$61,'01_Input'!$M$61,IF(F$21<'01_Input'!$O$61,'01_Input'!$Q$61,IF(F$21<'01_Input'!$S$61,'01_Input'!$U$61,'01_Input'!$Y$61))) -> 12000 | G34: =IF(G$21<'01_Input'!$K$61,'01_Input'!$M$61,IF(G$21<'01_Input'!$O$61,'01_Input'!$Q$61,IF(G$21<'01_Input'!$S$61,'01_Input'!$U$61,'01_Input'!$Y$61))) -> 12000 | H34: =IF(H$21<'01_Input'!$K$61,'01_Input'!$M$61,IF(H$21<'01_Input'!$O$61,'01_Input'!$Q$61,IF(H$21<'01_Input'!$S$61,'01_Input'!$U$61,'01_Input'!$Y$61))) -> 12000 | I34: =IF(I$21<'01_Input'!$K$61,'01_Input'!$M$61,IF(I$21<'01_Input'!$O$61,'01_Input'!$Q$61,IF(I$21<'01_Input'!$S$61,'01_Input'!$U$61,'01_Input'!$Y$61))) -> 12000 | J34: =IF(J$21<'01_Input'!$K$61,'01_Input'!$M$61,IF(J$21<'01_Input'!$O$61,'01_Input'!$Q$61,IF(J$21<'01_Input'!$S$61,'01_Input'!$U$61,'01_Input'!$Y$61))) -> 12000 | K34: =IF(K$21<'01_Input'!$K$61,'01_Input'!$M$61,IF(K$21<'01_Input'!$O$61,'01_Input'!$Q$61,IF(K$21<'01_Input'!$S$61,'01_Input'!$U$61,'01_Input'!$Y$61))) -> 12000 | L34: =IF(L$21<'01_Input'!$K$61,'01_Input'!$M$61,IF(L$21<'01_Input'!$O$61,'01_Input'!$Q$61,IF(L$21<'01_Input'!$S$61,'01_Input'!$U$61,'01_Input'!$Y$61))) -> 14000 | ... EX34: =IF(EX$21<'01_Input'!$K$61,'01_Input'!$M$61,IF(EX$21<'01_Input'!$O$61,'01_Input'!$Q$61,IF(EX$21<'01_Input'!$S$61,'01_Input'!$U$61,'01_Input'!$Y$61))) -> 18000
B35: Majoration appliquée (%) | E35: =Majoration_Valorisation -> 0 | F35: =Majoration_Valorisation -> 0 | G35: =Majoration_Valorisation -> 0 | H35: =Majoration_Valorisation -> 0 | I35: =Majoration_Valorisation -> 0 | J35: =Majoration_Valorisation -> 0 | K35: =Majoration_Valorisation -> 0 | L35: =Majoration_Valorisation -> 0 | ... EX35: =Majoration_Valorisation -> 0
B36: Nombre de lignes du portefeuille | E36: =Nb_Lignes_Valorisation -> 2 | F36: =Nb_Lignes_Valorisation -> 2 | G36: =Nb_Lignes_Valorisation -> 2 | H36: =Nb_Lignes_Valorisation -> 2 | I36: =Nb_Lignes_Valorisation -> 2 | J36: =Nb_Lignes_Valorisation -> 2 | K36: =Nb_Lignes_Valorisation -> 2 | L36: =Nb_Lignes_Valorisation -> 2 | ... EX36: =Nb_Lignes_Valorisation -> 2
B37: Supplément lignes (€) | E37: ='01_Input'!$AC$61 -> 0 | F37: ='01_Input'!$AC$61 -> 0 | G37: ='01_Input'!$AC$61 -> 0 | H37: ='01_Input'!$AC$61 -> 0 | I37: ='01_Input'!$AC$61 -> 0 | J37: ='01_Input'!$AC$61 -> 0 | K37: ='01_Input'!$AC$61 -> 0 | L37: ='01_Input'!$AC$61 -> 0 | ... EX37: ='01_Input'!$AC$61 -> 0
B38: → Valorisation (CIC) retenue (€) | E38: =E34+E37 -> 12000 | F38: =F34+F37 -> 12000 | G38: =G34+G37 -> 12000 | H38: =H34+H37 -> 12000 | I38: =I34+I37 -> 12000 | J38: =J34+J37 -> 12000 | K38: =K34+K37 -> 12000 | L38: =L34+L37 -> 14000 | ... EX38: =EX34+EX37 -> 18000
B39: Écart vs 04_Recap (doit être 0) | E39: =ROUND(E38-'04_Recap'!E29,2) -> 0 | F39: =ROUND(F38-'04_Recap'!F29,2) -> 0 | G39: =ROUND(G38-'04_Recap'!G29,2) -> 0 | H39: =ROUND(H38-'04_Recap'!H29,2) -> 0 | I39: =ROUND(I38-'04_Recap'!I29,2) -> 0 | J39: =ROUND(J38-'04_Recap'!J29,2) -> 0 | K39: =ROUND(K38-'04_Recap'!K29,2) -> 0 | L39: =ROUND(L38-'04_Recap'!L29,2) -> 0 | ... EX39: =ROUND(EX38-'04_Recap'!EX29,2) -> 18000

Sheet 04_Recap
B1: 04_RÉCAP — Zéro saisie manuelle — tout provient de 01_Input (et 02_Classes_de_Parts si utilisé)
B2: Une ligne par frais/provision, une colonne par niveau d'Actif Net (repris de l'échelle définie en 01_Input) — pour lire d'un coup d'œil comment chaque poste évolue avec la taille du fonds. Les postes en mode "Résiduel vs Gestion" ou "Taux Classe sélectionnée" (01_Input) reflètent la classe de parts choisie en 01_Input §3B. Détail pas-à-pas des postes Dépositaire et Valorisation : voir 03_Detail_Depositaire_Valo.
B4: Fonds testé : | C4: =Nom_Fonds -> AF CVC
B5: Classe testée (si applicable) : | C5: =Classe_Selectionnee -> A
B20: Poste de frais | C20: Bénéficiaire | D20: Actif ? | E20: {=INDEX(AUM_Ladder,1)} -> 5000000 | F20: {=INDEX(AUM_Ladder,2)} -> 10000000 | G20: {=INDEX(AUM_Ladder,3)} -> 15000000 | H20: {=INDEX(AUM_Ladder,4)} -> 20000000 | I20: {=INDEX(AUM_Ladder,5)} -> 25000000 | J20: {=INDEX(AUM_Ladder,6)} -> 30000000 | K20: {=INDEX(AUM_Ladder,7)} -> 35000000 | L20: {=INDEX(AUM_Ladder,8)} -> 40000000 | M20: {=INDEX(AUM_Ladder,9)} -> 45000000 | N20: {=INDEX(AUM_Ladder,10)} -> 50000000 | O20: {=INDEX(AUM_Ladder,11)} | P20: {=INDEX(AUM_Ladder,12)} | Q20: {=INDEX(AUM_Ladder,13)} | R20: {=INDEX(AUM_Ladder,14)} | S20: {=INDEX(AUM_Ladder,15)} | T20: {=INDEX(AUM_Ladder,16)} | U20: {=INDEX(AUM_Ladder,17)} | V20: {=INDEX(AUM_Ladder,18)} | W20: {=INDEX(AUM_Ladder,19)} | X20: {=INDEX(AUM_Ladder,20)} | Y20: {=INDEX(AUM_Ladder,21)} | Z20: {=INDEX(AUM_Ladder,22)} | AA20: {=INDEX(AUM_Ladder,23)} | AB20: {=INDEX(AUM_Ladder,24)} | AC20: {=INDEX(AUM_Ladder,25)} | AD20: {=INDEX(AUM_Ladder,26)} | AE20: {=INDEX(AUM_Ladder,27)} | AF20: {=INDEX(AUM_Ladder,28)} | AG20: {=INDEX(AUM_Ladder,29)} | AH20: {=INDEX(AUM_Ladder,30)} | AI20: {=INDEX(AUM_Ladder,31)} | AJ20: {=INDEX(AUM_Ladder,32)} | AK20: {=INDEX(AUM_Ladder,33)} | AL20: {=INDEX(AUM_Ladder,34)} | AM20: {=INDEX(AUM_Ladder,35)} | AN20: {=INDEX(AUM_Ladder,36)} | AO20: {=INDEX(AUM_Ladder,37)} | AP20: {=INDEX(AUM_Ladder,38)} | AQ20: {=INDEX(AUM_Ladder,39)} | AR20: {=INDEX(AUM_Ladder,40)} | AS20: {=INDEX(AUM_Ladder,41)} | AT20: {=INDEX(AUM_Ladder,42)} | AU20: {=INDEX(AUM_Ladder,43)} | AV20: {=INDEX(AUM_Ladder,44)} | AW20: {=INDEX(AUM_Ladder,45)} | AX20: {=INDEX(AUM_Ladder,46)} | AY20: {=INDEX(AUM_Ladder,47)} | AZ20: {=INDEX(AUM_Ladder,48)} | BA20: {=INDEX(AUM_Ladder,49)} | BB20: {=INDEX(AUM_Ladder,50)} | BC20: {=INDEX(AUM_Ladder,51)} | BD20: {=INDEX(AUM_Ladder,52)} | BE20: {=INDEX(AUM_Ladder,53)} | BF20: {=INDEX(AUM_Ladder,54)} | BG20: {=INDEX(AUM_Ladder,55)} | BH20: {=INDEX(AUM_Ladder,56)} | BI20: {=INDEX(AUM_Ladder,57)} | BJ20: {=INDEX(AUM_Ladder,58)} | BK20: {=INDEX(AUM_Ladder,59)} | BL20: {=INDEX(AUM_Ladder,60)} | BM20: {=INDEX(AUM_Ladder,61)} | BN20: {=INDEX(AUM_Ladder,62)} | BO20: {=INDEX(AUM_Ladder,63)} | BP20: {=INDEX(AUM_Ladder,64)} | BQ20: {=INDEX(AUM_Ladder,65)} | BR20: {=INDEX(AUM_Ladder,66)} | BS20: {=INDEX(AUM_Ladder,67)} | BT20: {=INDEX(AUM_Ladder,68)} | BU20: {=INDEX(AUM_Ladder,69)} | BV20: {=INDEX(AUM_Ladder,70)} | BW20: {=INDEX(AUM_Ladder,71)} | BX20: {=INDEX(AUM_Ladder,72)} | BY20: {=INDEX(AUM_Ladder,73)} | BZ20: {=INDEX(AUM_Ladder,74)} | CA20: {=INDEX(AUM_Ladder,75)} | CB20: {=INDEX(AUM_Ladder,76)} | CC20: {=INDEX(AUM_Ladder,77)} | CD20: {=INDEX(AUM_Ladder,78)} | CE20: {=INDEX(AUM_Ladder,79)} | CF20: {=INDEX(AUM_Ladder,80)} | CG20: {=INDEX(AUM_Ladder,81)} | CH20: {=INDEX(AUM_Ladder,82)} | CI20: {=INDEX(AUM_Ladder,83)} | CJ20: {=INDEX(AUM_Ladder,84)} | CK20: {=INDEX(AUM_Ladder,85)} | CL20: {=INDEX(AUM_Ladder,86)} | CM20: {=INDEX(AUM_Ladder,87)} | CN20: {=INDEX(AUM_Ladder,88)} | CO20: {=INDEX(AUM_Ladder,89)} | CP20: {=INDEX(AUM_Ladder,90)} | CQ20: {=INDEX(AUM_Ladder,91)} | CR20: {=INDEX(AUM_Ladder,92)} | CS20: {=INDEX(AUM_Ladder,93)} | CT20: {=INDEX(AUM_Ladder,94)} | CU20: {=INDEX(AUM_Ladder,95)} | CV20: {=INDEX(AUM_Ladder,96)} | CW20: {=INDEX(AUM_Ladder,97)} | CX20: {=INDEX(AUM_Ladder,98)} | CY20: {=INDEX(AUM_Ladder,99)} | CZ20: {=INDEX(AUM_Ladder,100)} | DA20: {=INDEX(AUM_Ladder,101)} | DB20: {=INDEX(AUM_Ladder,102)} | DC20: {=INDEX(AUM_Ladder,103)} | DD20: {=INDEX(AUM_Ladder,104)} | DE20: {=INDEX(AUM_Ladder,105)} | DF20: {=INDEX(AUM_Ladder,106)} | DG20: {=INDEX(AUM_Ladder,107)} | DH20: {=INDEX(AUM_Ladder,108)} | DI20: {=INDEX(AUM_Ladder,109)} | DJ20: {=INDEX(AUM_Ladder,110)} | DK20: {=INDEX(AUM_Ladder,111)} | DL20: {=INDEX(AUM_Ladder,112)} | DM20: {=INDEX(AUM_Ladder,113)} | DN20: {=INDEX(AUM_Ladder,114)} | DO20: {=INDEX(AUM_Ladder,115)} | DP20: {=INDEX(AUM_Ladder,116)} | DQ20: {=INDEX(AUM_Ladder,117)} | DR20: {=INDEX(AUM_Ladder,118)} | DS20: {=INDEX(AUM_Ladder,119)} | DT20: {=INDEX(AUM_Ladder,120)} | DU20: {=INDEX(AUM_Ladder,121)} | DV20: {=INDEX(AUM_Ladder,122)} | DW20: {=INDEX(AUM_Ladder,123)} | DX20: {=INDEX(AUM_Ladder,124)} | DY20: {=INDEX(AUM_Ladder,125)} | DZ20: {=INDEX(AUM_Ladder,126)} | EA20: {=INDEX(AUM_Ladder,127)} | EB20: {=INDEX(AUM_Ladder,128)} | EC20: {=INDEX(AUM_Ladder,129)} | ED20: {=INDEX(AUM_Ladder,130)} | EE20: {=INDEX(AUM_Ladder,131)} | EF20: {=INDEX(AUM_Ladder,132)} | EG20: {=INDEX(AUM_Ladder,133)} | EH20: {=INDEX(AUM_Ladder,134)} | EI20: {=INDEX(AUM_Ladder,135)} | EJ20: {=INDEX(AUM_Ladder,136)} | EK20: {=INDEX(AUM_Ladder,137)} | EL20: {=INDEX(AUM_Ladder,138)} | EM20: {=INDEX(AUM_Ladder,139)} | EN20: {=INDEX(AUM_Ladder,140)} | EO20: {=INDEX(AUM_Ladder,141)} | EP20: {=INDEX(AUM_Ladder,142)} | EQ20: {=INDEX(AUM_Ladder,143)} | ER20: {=INDEX(AUM_Ladder,144)} | ES20: {=INDEX(AUM_Ladder,145)} | ET20: {=INDEX(AUM_Ladder,146)} | EU20: {=INDEX(AUM_Ladder,147)} | EV20: {=INDEX(AUM_Ladder,148)} | EW20: {=INDEX(AUM_Ladder,149)} | EX20: {=INDEX(AUM_Ladder,150)}
B21: =IF('01_Input'!D53="","(inactif)",'01_Input'!D53) -> Commission de Gestion | C21: =IF('01_Input'!E53="","",'01_Input'!E53) | D21: ='01_Input'!C53 -> Oui | E21: =IF('01_Input'!$C$53="Non",0,MIN('01_Input'!$I$53,MAX('01_Input'!$H$53,IF('01_Input'!$G$53="Résiduel vs Gestion",0,IF('01_Input'!$G$53="Taux Classe sélectionnée",Distrib_Global_Classe_Selectionnee*E$20,IF('01_Input'!$G$53="Frais KYC (paliers de 100M€)",MAX(0,Nb_Investisseurs-Nb_KYC_Gratuites_Par_Tranche*(FLOOR(E$20/Taille_Tranche_KYC,1)+1))*Cout_Par_KYC_Supplementaire,(IF('01_Input'!$L$53="Forfait",IF(E$20>='01_Input'!$J$53,'01_Input'!$M$53,0),IF('01_Input'!$L$53="Palier",IF(AND(E$20>='01_Input'!$J$53,E$20<'01_Input'!$K$53),'01_Input'!$M$53,0),MAX(MIN(E$20,'01_Input'!$K$53)-'01_Input'!$J$53,0)*'01_Input'!$M$53))+IF('01_Input'!$P$53="Forfait",IF(E$20>='01_Input'!$N$53,'01_Input'!$Q$53,0),IF('01_Input'!$P$53="Palier",IF(AND(E$20>='01_Input'!$N$53,E$20<'01_Input'!$O$53),'01_Input'!$Q$53,0),MAX(MIN(E$20,'01_Input'!$O$53)-'01_Input'!$N$53,0)*'01_Input'!$Q$53))+IF('01_Input'!$T$53="Forfait",IF(E$20>='01_Input'!$R$53,'01_Input'!$U$53,0),IF('01_Input'!$T$53="Palier",IF(AND(E$20>='01_Input'!$R$53,E$20<'01_Input'!$S$53),'01_Input'!$U$53,0),MAX(MIN(E$20,'01_Input'!$S$53)-'01_Input'!$R$53,0)*'01_Input'!$U$53))+IF('01_Input'!$X$53="Forfait",IF(E$20>='01_Input'!$V$53,'01_Input'!$Y$53,0),IF('01_Input'!$X$53="Palier",IF(AND(E$20>='01_Input'!$V$53,E$20<'01_Input'!$W$53),'01_Input'!$Y$53,0),MAX(MIN(E$20,'01_Input'!$W$53)-'01_Input'!$V$53,0)*'01_Input'!$Y$53))+IF('01_Input'!$AB$53="Forfait",IF(E$20>='01_Input'!$Z$53,'01_Input'!$AC$53,0),IF('01_Input'!$AB$53="Palier",IF(AND(E$20>='01_Input'!$Z$53,E$20<'01_Input'!$AA$53),'01_Input'!$AC$53,0),MAX(MIN(E$20,'01_Input'!$AA$53)-'01_Input'!$Z$53,0)*'01_Input'!$AC$53))))))))) -> 60000 | F21: =IF('01_Input'!$C$53="Non",0,MIN('01_Input'!$I$53,MAX('01_Input'!$H$53,IF('01_Input'!$G$53="Résiduel vs Gestion",0,IF('01_Input'!$G$53="Taux Classe sélectionnée",Distrib_Global_Classe_Selectionnee*F$20,IF('01_Input'!$G$53="Frais KYC (paliers de 100M€)",MAX(0,Nb_Investisseurs-Nb_KYC_Gratuites_Par_Tranche*(FLOOR(F$20/Taille_Tranche_KYC,1)+1))*Cout_Par_KYC_Supplementaire,(IF('01_Input'!$L$53="Forfait",IF(F$20>='01_Input'!$J$53,'01_Input'!$M$53,0),IF('01_Input'!$L$53="Palier",IF(AND(F$20>='01_Input'!$J$53,F$20<'01_Input'!$K$53),'01_Input'!$M$53,0),MAX(MIN(F$20,'01_Input'!$K$53)-'01_Input'!$J$53,0)*'01_Input'!$M$53))+IF('01_Input'!$P$53="Forfait",IF(F$20>='01_Input'!$N$53,'01_Input'!$Q$53,0),IF('01_Input'!$P$53="Palier",IF(AND(F$20>='01_Input'!$N$53,F$20<'01_Input'!$O$53),'01_Input'!$Q$53,0),MAX(MIN(F$20,'01_Input'!$O$53)-'01_Input'!$N$53,0)*'01_Input'!$Q$53))+IF('01_Input'!$T$53="Forfait",IF(F$20>='01_Input'!$R$53,'01_Input'!$U$53,0),IF('01_Input'!$T$53="Palier",IF(AND(F$20>='01_Input'!$R$53,F$20<'01_Input'!$S$53),'01_Input'!$U$53,0),MAX(MIN(F$20,'01_Input'!$S$53)-'01_Input'!$R$53,0)*'01_Input'!$U$53))+IF('01_Input'!$X$53="Forfait",IF(F$20>='01_Input'!$V$53,'01_Input'!$Y$53,0),IF('01_Input'!$X$53="Palier",IF(AND(F$20>='01_Input'!$V$53,F$20<'01_Input'!$W$53),'01_Input'!$Y$53,0),MAX(MIN(F$20,'01_Input'!$W$53)-'01_Input'!$V$53,0)*'01_Input'!$Y$53))+IF('01_Input'!$AB$53="Forfait",IF(F$20>='01_Input'!$Z$53,'01_Input'!$AC$53,0),IF('01_Input'!$AB$53="Palier",IF(AND(F$20>='01_Input'!$Z$53,F$20<'01_Input'!$AA$53),'01_Input'!$AC$53,0),MAX(MIN(F$20,'01_Input'!$AA$53)-'01_Input'!$Z$53,0)*'01_Input'!$AC$53))))))))) -> 60000 | G21: =IF('01_Input'!$C$53="Non",0,MIN('01_Input'!$I$53,MAX('01_Input'!$H$53,IF('01_Input'!$G$53="Résiduel vs Gestion",0,IF('01_Input'!$G$53="Taux Classe sélectionnée",Distrib_Global_Classe_Selectionnee*G$20,IF('01_Input'!$G$53="Frais KYC (paliers de 100M€)",MAX(0,Nb_Investisseurs-Nb_KYC_Gratuites_Par_Tranche*(FLOOR(G$20/Taille_Tranche_KYC,1)+1))*Cout_Par_KYC_Supplementaire,(IF('01_Input'!$L$53="Forfait",IF(G$20>='01_Input'!$J$53,'01_Input'!$M$53,0),IF('01_Input'!$L$53="Palier",IF(AND(G$20>='01_Input'!$J$53,G$20<'01_Input'!$K$53),'01_Input'!$M$53,0),MAX(MIN(G$20,'01_Input'!$K$53)-'01_Input'!$J$53,0)*'01_Input'!$M$53))+IF('01_Input'!$P$53="Forfait",IF(G$20>='01_Input'!$N$53,'01_Input'!$Q$53,0),IF('01_Input'!$P$53="Palier",IF(AND(G$20>='01_Input'!$N$53,G$20<'01_Input'!$O$53),'01_Input'!$Q$53,0),MAX(MIN(G$20,'01_Input'!$O$53)-'01_Input'!$N$53,0)*'01_Input'!$Q$53))+IF('01_Input'!$T$53="Forfait",IF(G$20>='01_Input'!$R$53,'01_Input'!$U$53,0),IF('01_Input'!$T$53="Palier",IF(AND(G$20>='01_Input'!$R$53,G$20<'01_Input'!$S$53),'01_Input'!$U$53,0),MAX(MIN(G$20,'01_Input'!$S$53)-'01_Input'!$R$53,0)*'01_Input'!$U$53))+IF('01_Input'!$X$53="Forfait",IF(G$20>='01_Input'!$V$53,'01_Input'!$Y$53,0),IF('01_Input'!$X$53="Palier",IF(AND(G$20>='01_Input'!$V$53,G$20<'01_Input'!$W$53),'01_Input'!$Y$53,0),MAX(MIN(G$20,'01_Input'!$W$53)-'01_Input'!$V$53,0)*'01_Input'!$Y$53))+IF('01_Input'!$AB$53="Forfait",IF(G$20>='01_Input'!$Z$53,'01_Input'!$AC$53,0),IF('01_Input'!$AB$53="Palier",IF(AND(G$20>='01_Input'!$Z$53,G$20<'01_Input'!$AA$53),'01_Input'!$AC$53,0),MAX(MIN(G$20,'01_Input'!$AA$53)-'01_Input'!$Z$53,0)*'01_Input'!$AC$53))))))))) -> 60000 | H21: =IF('01_Input'!$C$53="Non",0,MIN('01_Input'!$I$53,MAX('01_Input'!$H$53,IF('01_Input'!$G$53="Résiduel vs Gestion",0,IF('01_Input'!$G$53="Taux Classe sélectionnée",Distrib_Global_Classe_Selectionnee*H$20,IF('01_Input'!$G$53="Frais KYC (paliers de 100M€)",MAX(0,Nb_Investisseurs-Nb_KYC_Gratuites_Par_Tranche*(FLOOR(H$20/Taille_Tranche_KYC,1)+1))*Cout_Par_KYC_Supplementaire,(IF('01_Input'!$L$53="Forfait",IF(H$20>='01_Input'!$J$53,'01_Input'!$M$53,0),IF('01_Input'!$L$53="Palier",IF(AND(H$20>='01_Input'!$J$53,H$20<'01_Input'!$K$53),'01_Input'!$M$53,0),MAX(MIN(H$20,'01_Input'!$K$53)-'01_Input'!$J$53,0)*'01_Input'!$M$53))+IF('01_Input'!$P$53="Forfait",IF(H$20>='01_Input'!$N$53,'01_Input'!$Q$53,0),IF('01_Input'!$P$53="Palier",IF(AND(H$20>='01_Input'!$N$53,H$20<'01_Input'!$O$53),'01_Input'!$Q$53,0),MAX(MIN(H$20,'01_Input'!$O$53)-'01_Input'!$N$53,0)*'01_Input'!$Q$53))+IF('01_Input'!$T$53="Forfait",IF(H$20>='01_Input'!$R$53,'01_Input'!$U$53,0),IF('01_Input'!$T$53="Palier",IF(AND(H$20>='01_Input'!$R$53,H$20<'01_Input'!$S$53),'01_Input'!$U$53,0),MAX(MIN(H$20,'01_Input'!$S$53)-'01_Input'!$R$53,0)*'01_Input'!$U$53))+IF('01_Input'!$X$53="Forfait",IF(H$20>='01_Input'!$V$53,'01_Input'!$Y$53,0),IF('01_Input'!$X$53="Palier",IF(AND(H$20>='01_Input'!$V$53,H$20<'01_Input'!$W$53),'01_Input'!$Y$53,0),MAX(MIN(H$20,'01_Input'!$W$53)-'01_Input'!$V$53,0)*'01_Input'!$Y$53))+IF('01_Input'!$AB$53="Forfait",IF(H$20>='01_Input'!$Z$53,'01_Input'!$AC$53,0),IF('01_Input'!$AB$53="Palier",IF(AND(H$20>='01_Input'!$Z$53,H$20<'01_Input'!$AA$53),'01_Input'!$AC$53,0),MAX(MIN(H$20,'01_Input'!$AA$53)-'01_Input'!$Z$53,0)*'01_Input'!$AC$53))))))))) -> 60000 | I21: =IF('01_Input'!$C$53="Non",0,MIN('01_Input'!$I$53,MAX('01_Input'!$H$53,IF('01_Input'!$G$53="Résiduel vs Gestion",0,IF('01_Input'!$G$53="Taux Classe sélectionnée",Distrib_Global_Classe_Selectionnee*I$20,IF('01_Input'!$G$53="Frais KYC (paliers de 100M€)",MAX(0,Nb_Investisseurs-Nb_KYC_Gratuites_Par_Tranche*(FLOOR(I$20/Taille_Tranche_KYC,1)+1))*Cout_Par_KYC_Supplementaire,(IF('01_Input'!$L$53="Forfait",IF(I$20>='01_Input'!$J$53,'01_Input'!$M$53,0),IF('01_Input'!$L$53="Palier",IF(AND(I$20>='01_Input'!$J$53,I$20<'01_Input'!$K$53),'01_Input'!$M$53,0),MAX(MIN(I$20,'01_Input'!$K$53)-'01_Input'!$J$53,0)*'01_Input'!$M$53))+IF('01_Input'!$P$53="Forfait",IF(I$20>='01_Input'!$N$53,'01_Input'!$Q$53,0),IF('01_Input'!$P$53="Palier",IF(AND(I$20>='01_Input'!$N$53,I$20<'01_Input'!$O$53),'01_Input'!$Q$53,0),MAX(MIN(I$20,'01_Input'!$O$53)-'01_Input'!$N$53,0)*'01_Input'!$Q$53))+IF('01_Input'!$T$53="Forfait",IF(I$20>='01_Input'!$R$53,'01_Input'!$U$53,0),IF('01_Input'!$T$53="Palier",IF(AND(I$20>='01_Input'!$R$53,I$20<'01_Input'!$S$53),'01_Input'!$U$53,0),MAX(MIN(I$20,'01_Input'!$S$53)-'01_Input'!$R$53,0)*'01_Input'!$U$53))+IF('01_Input'!$X$53="Forfait",IF(I$20>='01_Input'!$V$53,'01_Input'!$Y$53,0),IF('01_Input'!$X$53="Palier",IF(AND(I$20>='01_Input'!$V$53,I$20<'01_Input'!$W$53),'01_Input'!$Y$53,0),MAX(MIN(I$20,'01_Input'!$W$53)-'01_Input'!$V$53,0)*'01_Input'!$Y$53))+IF('01_Input'!$AB$53="Forfait",IF(I$20>='01_Input'!$Z$53,'01_Input'!$AC$53,0),IF('01_Input'!$AB$53="Palier",IF(AND(I$20>='01_Input'!$Z$53,I$20<'01_Input'!$AA$53),'01_Input'!$AC$53,0),MAX(MIN(I$20,'01_Input'!$AA$53)-'01_Input'!$Z$53,0)*'01_Input'!$AC$53))))))))) -> 60000 | J21: =IF('01_Input'!$C$53="Non",0,MIN('01_Input'!$I$53,MAX('01_Input'!$H$53,IF('01_Input'!$G$53="Résiduel vs Gestion",0,IF('01_Input'!$G$53="Taux Classe sélectionnée",Distrib_Global_Classe_Selectionnee*J$20,IF('01_Input'!$G$53="Frais KYC (paliers de 100M€)",MAX(0,Nb_Investisseurs-Nb_KYC_Gratuites_Par_Tranche*(FLOOR(J$20/Taille_Tranche_KYC,1)+1))*Cout_Par_KYC_Supplementaire,(IF('01_Input'!$L$53="Forfait",IF(J$20>='01_Input'!$J$53,'01_Input'!$M$53,0),IF('01_Input'!$L$53="Palier",IF(AND(J$20>='01_Input'!$J$53,J$20<'01_Input'!$K$53),'01_Input'!$M$53,0),MAX(MIN(J$20,'01_Input'!$K$53)-'01_Input'!$J$53,0)*'01_Input'!$M$53))+IF('01_Input'!$P$53="Forfait",IF(J$20>='01_Input'!$N$53,'01_Input'!$Q$53,0),IF('01_Input'!$P$53="Palier",IF(AND(J$20>='01_Input'!$N$53,J$20<'01_Input'!$O$53),'01_Input'!$Q$53,0),MAX(MIN(J$20,'01_Input'!$O$53)-'01_Input'!$N$53,0)*'01_Input'!$Q$53))+IF('01_Input'!$T$53="Forfait",IF(J$20>='01_Input'!$R$53,'01_Input'!$U$53,0),IF('01_Input'!$T$53="Palier",IF(AND(J$20>='01_Input'!$R$53,J$20<'01_Input'!$S$53),'01_Input'!$U$53,0),MAX(MIN(J$20,'01_Input'!$S$53)-'01_Input'!$R$53,0)*'01_Input'!$U$53))+IF('01_Input'!$X$53="Forfait",IF(J$20>='01_Input'!$V$53,'01_Input'!$Y$53,0),IF('01_Input'!$X$53="Palier",IF(AND(J$20>='01_Input'!$V$53,J$20<'01_Input'!$W$53),'01_Input'!$Y$53,0),MAX(MIN(J$20,'01_Input'!$W$53)-'01_Input'!$V$53,0)*'01_Input'!$Y$53))+IF('01_Input'!$AB$53="Forfait",IF(J$20>='01_Input'!$Z$53,'01_Input'!$AC$53,0),IF('01_Input'!$AB$53="Palier",IF(AND(J$20>='01_Input'!$Z$53,J$20<'01_Input'!$AA$53),'01_Input'!$AC$53,0),MAX(MIN(J$20,'01_Input'!$AA$53)-'01_Input'!$Z$53,0)*'01_Input'!$AC$53))))))))) -> 60000 | K21: =IF('01_Input'!$C$53="Non",0,MIN('01_Input'!$I$53,MAX('01_Input'!$H$53,IF('01_Input'!$G$53="Résiduel vs Gestion",0,IF('01_Input'!$G$53="Taux Classe sélectionnée",Distrib_Global_Classe_Selectionnee*K$20,IF('01_Input'!$G$53="Frais KYC (paliers de 100M€)",MAX(0,Nb_Investisseurs-Nb_KYC_Gratuites_Par_Tranche*(FLOOR(K$20/Taille_Tranche_KYC,1)+1))*Cout_Par_KYC_Supplementaire,(IF('01_Input'!$L$53="Forfait",IF(K$20>='01_Input'!$J$53,'01_Input'!$M$53,0),IF('01_Input'!$L$53="Palier",IF(AND(K$20>='01_Input'!$J$53,K$20<'01_Input'!$K$53),'01_Input'!$M$53,0),MAX(MIN(K$20,'01_Input'!$K$53)-'01_Input'!$J$53,0)*'01_Input'!$M$53))+IF('01_Input'!$P$53="Forfait",IF(K$20>='01_Input'!$N$53,'01_Input'!$Q$53,0),IF('01_Input'!$P$53="Palier",IF(AND(K$20>='01_Input'!$N$53,K$20<'01_Input'!$O$53),'01_Input'!$Q$53,0),MAX(MIN(K$20,'01_Input'!$O$53)-'01_Input'!$N$53,0)*'01_Input'!$Q$53))+IF('01_Input'!$T$53="Forfait",IF(K$20>='01_Input'!$R$53,'01_Input'!$U$53,0),IF('01_Input'!$T$53="Palier",IF(AND(K$20>='01_Input'!$R$53,K$20<'01_Input'!$S$53),'01_Input'!$U$53,0),MAX(MIN(K$20,'01_Input'!$S$53)-'01_Input'!$R$53,0)*'01_Input'!$U$53))+IF('01_Input'!$X$53="Forfait",IF(K$20>='01_Input'!$V$53,'01_Input'!$Y$53,0),IF('01_Input'!$X$53="Palier",IF(AND(K$20>='01_Input'!$V$53,K$20<'01_Input'!$W$53),'01_Input'!$Y$53,0),MAX(MIN(K$20,'01_Input'!$W$53)-'01_Input'!$V$53,0)*'01_Input'!$Y$53))+IF('01_Input'!$AB$53="Forfait",IF(K$20>='01_Input'!$Z$53,'01_Input'!$AC$53,0),IF('01_Input'!$AB$53="Palier",IF(AND(K$20>='01_Input'!$Z$53,K$20<'01_Input'!$AA$53),'01_Input'!$AC$53,0),MAX(MIN(K$20,'01_Input'!$AA$53)-'01_Input'!$Z$53,0)*'01_Input'!$AC$53))))))))) -> 63000 | L21: =IF('01_Input'!$C$53="Non",0,MIN('01_Input'!$I$53,MAX('01_Input'!$H$53,IF('01_Input'!$G$53="Résiduel vs Gestion",0,IF('01_Input'!$G$53="Taux Classe sélectionnée",Distrib_Global_Classe_Selectionnee*L$20,IF('01_Input'!$G$53="Frais KYC (paliers de 100M€)",MAX(0,Nb_Investisseurs-Nb_KYC_Gratuites_Par_Tranche*(FLOOR(L$20/Taille_Tranche_KYC,1)+1))*Cout_Par_KYC_Supplementaire,(IF('01_Input'!$L$53="Forfait",IF(L$20>='01_Input'!$J$53,'01_Input'!$M$53,0),IF('01_Input'!$L$53="Palier",IF(AND(L$20>='01_Input'!$J$53,L$20<'01_Input'!$K$53),'01_Input'!$M$53,0),MAX(MIN(L$20,'01_Input'!$K$53)-'01_Input'!$J$53,0)*'01_Input'!$M$53))+IF('01_Input'!$P$53="Forfait",IF(L$20>='01_Input'!$N$53,'01_Input'!$Q$53,0),IF('01_Input'!$P$53="Palier",IF(AND(L$20>='01_Input'!$N$53,L$20<'01_Input'!$O$53),'01_Input'!$Q$53,0),MAX(MIN(L$20,'01_Input'!$O$53)-'01_Input'!$N$53,0)*'01_Input'!$Q$53))+IF('01_Input'!$T$53="Forfait",IF(L$20>='01_Input'!$R$53,'01_Input'!$U$53,0),IF('01_Input'!$T$53="Palier",IF(AND(L$20>='01_Input'!$R$53,L$20<'01_Input'!$S$53),'01_Input'!$U$53,0),MAX(MIN(L$20,'01_Input'!$S$53)-'01_Input'!$R$53,0)*'01_Input'!$U$53))+IF('01_Input'!$X$53="Forfait",IF(L$20>='01_Input'!$V$53,'01_Input'!$Y$53,0),IF('01_Input'!$X$53="Palier",IF(AND(L$20>='01_Input'!$V$53,L$20<'01_Input'!$W$53),'01_Input'!$Y$53,0),MAX(MIN(L$20,'01_Input'!$W$53)-'01_Input'!$V$53,0)*'01_Input'!$Y$53))+IF('01_Input'!$AB$53="Forfait",IF(L$20>='01_Input'!$Z$53,'01_Input'!$AC$53,0),IF('01_Input'!$AB$53="Palier",IF(AND(L$20>='01_Input'!$Z$53,L$20<'01_Input'!$AA$53),'01_Input'!$AC$53,0),MAX(MIN(L$20,'01_Input'!$AA$53)-'01_Input'!$Z$53,0)*'01_Input'!$AC$53))))))))) -> 72000 | ... EX21: =IF('01_Input'!$C$53="Non",0,MIN('01_Input'!$I$53,MAX('01_Input'!$H$53,IF('01_Input'!$G$53="Résiduel vs Gestion",0,IF('01_Input'!$G$53="Taux Classe sélectionnée",Distrib_Global_Classe_Selectionnee*EX$20,IF('01_Input'!$G$53="Frais KYC (paliers de 100M€)",MAX(0,Nb_Investisseurs-Nb_KYC_Gratuites_Par_Tranche*(FLOOR(EX$20/Taille_Tranche_KYC,1)+1))*Cout_Par_KYC_Supplementaire,(IF('01_Input'!$L$53="Forfait",IF(EX$20>='01_Input'!$J$53,'01_Input'!$M$53,0),IF('01_Input'!$L$53="Palier",IF(AND(EX$20>='01_Input'!$J$53,EX$20<'01_Input'!$K$53),'01_Input'!$M$53,0),MAX(MIN(EX$20,'01_Input'!$K$53)-'01_Input'!$J$53,0)*'01_Input'!$M$53))+IF('01_Input'!$P$53="Forfait",IF(EX$20>='01_Input'!$N$53,'01_Input'!$Q$53,0),IF('01_Input'!$P$53="Palier",IF(AND(EX$20>='01_Input'!$N$53,EX$20<'01_Input'!$O$53),'01_Input'!$Q$53,0),MAX(MIN(EX$20,'01_Input'!$O$53)-'01_Input'!$N$53,0)*'01_Input'!$Q$53))+IF('01_Input'!$T$53="Forfait",IF(EX$20>='01_Input'!$R$53,'01_Input'!$U$53,0),IF('01_Input'!$T$53="Palier",IF(AND(EX$20>='01_Input'!$R$53,EX$20<'01_Input'!$S$53),'01_Input'!$U$53,0),MAX(MIN(EX$20,'01_Input'!$S$53)-'01_Input'!$R$53,0)*'01_Input'!$U$53))+IF('01_Input'!$X$53="Forfait",IF(EX$20>='01_Input'!$V$53,'01_Input'!$Y$53,0),IF('01_Input'!$X$53="Palier",IF(AND(EX$20>='01_Input'!$V$53,EX$20<'01_Input'!$W$53),'01_Input'!$Y$53,0),MAX(MIN(EX$20,'01_Input'!$W$53)-'01_Input'!$V$53,0)*'01_Input'!$Y$53))+IF('01_Input'!$AB$53="Forfait",IF(EX$20>='01_Input'!$Z$53,'01_Input'!$AC$53,0),IF('01_Input'!$AB$53="Palier",IF(AND(EX$20>='01_Input'!$Z$53,EX$20<'01_Input'!$AA$53),'01_Input'!$AC$53,0),MAX(MIN(EX$20,'01_Input'!$AA$53)-'01_Input'!$Z$53,0)*'01_Input'!$AC$53))))))))) -> 900290000
